<?xml version="1.0" encoding="utf-8"?>
<!-- =================================================================================== -->
<!-- |    This document was autogenerated by xacro from full_reflex_model.urdf.xacro   | -->
<!-- |    EDITING THIS FILE BY HAND IS NOT RECOMMENDED                                 | -->
<!-- =================================================================================== -->
<robot name="rhr_flex_model">
  <!-- ################ ################ ################ ################ ################ ################ -->
  <!-- ################ XACRO PORTION OF THE URDF, FOR MAKING THE FLEXIBLE JOINTS ################ -->
  <!-- ################ ################ ################ ################ ################ ################ -->
<!--
  <link name="finger[1]/flex_link[1]">
    <inertial>
			<origin rpy="0.00000 -0.00000 0.00000" xyz="0.00000 0.00000 0.00000"/>
			<mass value="0.00000"/>
			<inertia ixx="0.00000" ixy="0" ixz="0" iyy="0.00000" iyz="0" izz="0.00000"/>
		</inertial>
    <visual>
      <origin rpy="1.57075 0 1.57075" xyz="0 -0.008 0.001"/>
      <geometry>
        <mesh filename="package://righthand/meshes/flex_block.stl"/>
      </geometry>
      <material name="">
        <color rgba="0.2 0.2 .2 1"/>
      </material>
    </visual>
  </link>

  <link name="finger[1]/flex_link[1]/virtual_link[1]"/>
    <inertial>
      <origin rpy="0.00000 -0.00000 0.00000" xyz="0.00000 0.00000 0.00000"/>
      <mass value="0.00000"/>
      <inertia ixx="0.00000" ixy="0" ixz="0" iyy="0.00000" iyz="0" izz="0.00000"/>
    </inertial>
  </link>


  <link name="finger[1]/flex_link[1]/virtual_link[2]"/>

  <link name="finger[1]/flex_link[2]">
    <inertial>
			<origin rpy="0.00000 -0.00000 0.00000" xyz="0.00000 0.00000 0.00000"/>
			<mass value="0.00000"/>
			<inertia ixx="0.00000" ixy="0" ixz="0" iyy="0.00000" iyz="0" izz="0.00000"/>
		</inertial>
    <visual>
      <origin rpy="1.57075 0 1.57075" xyz="0 -0.008 0.001"/>
      <geometry>
        <mesh filename="package://righthand/meshes/flex_block.stl"/>
      </geometry>
      <material name="">
        <color rgba="0.2 0.2 .2 1"/>
      </material>
    </visual>
  </link>

  <link name="finger[1]/flex_link[2]/virtual_link[1]"/>
  <link name="finger[1]/flex_link[2]/virtual_link[2]"/>

  <link name="finger[1]/flex_link[3]">
    <inertial>
			<origin rpy="0.00000 -0.00000 0.00000" xyz="0.00000 0.00000 0.00000"/>
			<mass value="0.00000"/>
			<inertia ixx="0.00000" ixy="0" ixz="0" iyy="0.00000" iyz="0" izz="0.00000"/>
		</inertial>
    <visual>
      <origin rpy="1.57075 0 1.57075" xyz="0 -0.008 0.001"/>
      <geometry>
        <mesh filename="package://righthand/meshes/flex_block.stl"/>
      </geometry>
      <material name="">
        <color rgba="0.2 0.2 .2 1"/>
      </material>
    </visual>
  </link>

  <link name="finger[1]/flex_link[3]/virtual_link[1]"/>
  <link name="finger[1]/flex_link[3]/virtual_link[2]"/>
  <link name="finger[1]/flex_link[4]">

    <visual>
      <inertial>
  			<origin rpy="0.00000 -0.00000 0.00000" xyz="0.00000 0.00000 0.00000"/>
  			<mass value="0.00000"/>
  			<inertia ixx="0.00000" ixy="0" ixz="0" iyy="0.00000" iyz="0" izz="0.00000"/>
  		</inertial>
      <origin rpy="1.57075 0 1.57075" xyz="0 -0.008 0.001"/>
      <geometry>
        <mesh filename="package://righthand/meshes/flex_block.stl"/>
      </geometry>
      <material name="">
        <color rgba="0.2 0.2 .2 1"/>
      </material>filename
    </visual>
  </link>

  <link name="finger[1]/flex_link[4]/virtual_link[1]"/>
  <link name="finger[1]/flex_link[4]/virtual_link[2]"/>

  <link name="finger[1]/flex_link[5]">
    <inertial>
			<origin rpy="0.00000 -0.00000 0.00000" xyz="0.00000 0.00000 0.00000"/>
			<mass value="0.00000"/>
			<inertia ixx="0.00000" ixy="0" ixz="0" iyy="0.00000" iyz="0" izz="0.00000"/>
		</inertial>
    <visual>
      <origin rpy="1.57075 0 1.57075" xyz="0 -0.008 0.001"/>
      <geometry>
        <mesh filename="package://righthand/meshes/flex_block.stl"/>
      </geometry>
      <material name="">
        <color rgba="0.2 0.2 .2 1"/>
      </material>
    </visual>
  </link>

  <link name="finger[1]/flex_link[5]/virtual_link[1]"/>
  <link name="finger[1]/flex_link[5]/virtual_link[2]"/>

  <link name="finger[1]/flex_link[6]">
    <inertial>
			<origin rpy="0.00000 -0.00000 0.00000" xyz="0.00000 0.00000 0.00000"/>
			<mass value="0.00000"/>
			<inertia ixx="0.00000" ixy="0" ixz="0" iyy="0.00000" iyz="0" izz="0.00000"/>
		</inertial>
    <visual>
      <origin rpy="1.57075 0 1.57075" xyz="0 -0.008 0.001"/>
      <geometry>
        <mesh filename="package://righthand/meshes/flex_block.stl"/>
      </geometry>
      <material name="">
        <color rgba="0.2 0.2 .2 1"/>
      </material>
    </visual>
  </link>

  <link name="finger[1]/flex_link[6]/virtual_link[1]"/>
  <link name="finger[1]/flex_link[6]/virtual_link[2]"/>

  <link name="finger[1]/flex_link[7]">
    <inertial>
			<origin rpy="0.00000 -0.00000 0.00000" xyz="0.00000 0.00000 0.00000"/>
			<mass value="0.00000"/>
			<inertia ixx="0.00000" ixy="0" ixz="0" iyy="0.00000" iyz="0" izz="0.00000"/>
		</inertial>
    <visual>
      <origin rpy="1.57075 0 1.57075" xyz="0 -0.008 0.001"/>
      <geometry>
        <mesh filename="package://righthand/meshes/flex_block.stl"/>
      </geometry>
      <material name="">
        <color rgba="0.2 0.2 .2 1"/>
      </material>
    </visual>
  </link>

  <link name="finger[1]/flex_link[7]/virtual_link[1]"/>
  <link name="finger[1]/flex_link[7]/virtual_link[2]"/>

  <link name="finger[1]/flex_link[8]">
    <inertial>
			<origin rpy="0.00000 -0.00000 0.00000" xyz="0.00000 0.00000 0.00000"/>
			<mass value="0.00000"/>
			<inertia ixx="0.00000" ixy="0" ixz="0" iyy="0.00000" iyz="0" izz="0.00000"/>
		</inertial>
    <visual>
      <origin rpy="1.57075 0 1.57075" xyz="0 -0.008 0.001"/>
      <geometry>
        <mesh filename="package://righthand/meshes/flex_block.stl"/>
      </geometry>
      <material name="">
        <color rgba="0.2 0.2 .2 1"/>
      </material>
    </visual>
  </link>

  <link name="finger[1]/flex_link[8]/virtual_link[1]"/>
  <link name="finger[1]/flex_link[8]/virtual_link[2]"/>

  <link name="finger[1]/flex_link[9]">
    <inertial>
			<origin rpy="0.00000 -0.00000 0.00000" xyz="0.00000 0.00000 0.00000"/>
			<mass value="0.00000"/>
			<inertia ixx="0.00000" ixy="0" ixz="0" iyy="0.00000" iyz="0" izz="0.00000"/>
		</inertial>
    <visual>
      <origin rpy="1.57075 0 1.57075" xyz="0 -0.008 0.001"/>
      <geometry>
        <mesh filename="package://righthand/meshes/flex_block.stl"/>
      </geometry>
      <material name="">
        <color rgba="0.2 0.2 .2 1"/>
      </material>
    </visual>
  </link>

  <link name="finger[1]/flex_link[9]/virtual_link[1]"/>
  <link name="finger[1]/flex_link[9]/virtual_link[2]"/>

  <joint name="finger[1]/flex_link[1]/flex_joint_from_flex_link[1]_to_virtual_link[1]" type="continuous">
    <parent link="finger[1]/flex_link[1]"/>
    <child link="finger[1]/flex_link[1]/virtual_link[1]"/>
    <origin xyz="0.00177777777778 0 0"/>
    <axis xyz="0 -1 0"/>
  </joint>
  <joint name="finger[1]/flex_link[1]/flex_joint_from_virtual_link[1]_to_virtual_link[2]" type="continuous">
    <parent link="finger[1]/flex_link[1]/virtual_link[1]"/>
    <child link="finger[1]/flex_link[1]/virtual_link[2]"/>
    <origin xyz="0 0 0"/>
    <axis xyz="-1 0 0"/>
  </joint>
  <joint name="finger[1]/flex_link[1]/flex_joint_from_virtual_link[2]_to_flex_link[2]" type="continuous">
    <parent link="finger[1]/flex_link[1]/virtual_link[2]"/>
    <child link="finger[1]/flex_link[2]"/>
    <origin xyz="0 0 0"/>
    <axis xyz="0 0 -1"/>
  </joint>
  <joint name="finger[1]/flex_link[2]/flex_joint_from_flex_link[2]_to_virtual_link[1]" type="continuous">
    <parent link="finger[1]/flex_link[2]"/>
    <child link="finger[1]/flex_link[2]/virtual_link[1]"/>
    <origin xyz="0.00177777777778 0 0"/>
    <axis xyz="0 -1 0"/>
  </joint>
  <joint name="finger[1]/flex_link[2]/flex_joint_from_virtual_link[1]_to_virtual_link[2]" type="continuous">
    <parent link="finger[1]/flex_link[2]/virtual_link[1]"/>
    <child link="finger[1]/flex_link[2]/virtual_link[2]"/>
    <origin xyz="0 0 0"/>
    <axis xyz="-1 0 0"/>
  </joint>
  <joint name="finger[1]/flex_link[2]/flex_joint_from_virtual_link[2]_to_flex_link[3]" type="continuous">
    <parent link="finger[1]/flex_link[2]/virtual_link[2]"/>
    <child link="finger[1]/flex_link[3]"/>
    <origin xyz="0 0 0"/>
    <axis xyz="0 0 -1"/>
  </joint>
  <joint name="finger[1]/flex_link[3]/flex_joint_from_flex_link[3]_to_virtual_link[1]" type="continuous">
    <parent link="finger[1]/flex_link[3]"/>
    <child link="finger[1]/flex_link[3]/virtual_link[1]"/>
    <origin xyz="0.00177777777778 0 0"/>
    <axis xyz="0 -1 0"/>
  </joint>
  <joint name="finger[1]/flex_link[3]/flex_joint_from_virtual_link[1]_to_virtual_link[2]" type="continuous">
    <parent link="finger[1]/flex_link[3]/virtual_link[1]"/>
    <child link="finger[1]/flex_link[3]/virtual_link[2]"/>
    <origin xyz="0 0 0"/>
    <axis xyz="-1 0 0"/>
  </joint>
  <joint name="finger[1]/flex_link[3]/flex_joint_from_virtual_link[2]_to_flex_link[4]" type="continuous">
    <parent link="finger[1]/flex_link[3]/virtual_link[2]"/>
    <child link="finger[1]/flex_link[4]"/>
    <origin xyz="0 0 0"/>
    <axis xyz="0 0 -1"/>
  </joint>
  <joint name="finger[1]/flex_link[4]/flex_joint_from_flex_link[4]_to_virtual_link[1]" type="continuous">
    <parent link="finger[1]/flex_link[4]"/>
    <child link="finger[1]/flex_link[4]/virtual_link[1]"/>
    <origin xyz="0.00177777777778 0 0"/>
    <axis xyz="0 -1 0"/>
  </joint>
  <joint name="finger[1]/flex_link[4]/flex_joint_from_virtual_link[1]_to_virtual_link[2]" type="continuous">
    <parent link="finger[1]/flex_link[4]/virtual_link[1]"/>
    <child link="finger[1]/flex_link[4]/virtual_link[2]"/>
    <origin xyz="0 0 0"/>
    <axis xyz="-1 0 0"/>
  </joint>
  <joint name="finger[1]/flex_link[4]/flex_joint_from_virtual_link[2]_to_flex_link[5]" type="continuous">
    <parent link="finger[1]/flex_link[4]/virtual_link[2]"/>
    <child link="finger[1]/flex_link[5]"/>
    <origin xyz="0 0 0"/>
    <axis xyz="0 0 -1"/>
  </joint>
  <joint name="finger[1]/flex_link[5]/flex_joint_from_flex_link[5]_to_virtual_link[1]" type="continuous">
    <parent link="finger[1]/flex_link[5]"/>
    <child link="finger[1]/flex_link[5]/virtual_link[1]"/>
    <origin xyz="0.00177777777778 0 0"/>
    <axis xyz="0 -1 0"/>
  </joint>
  <joint name="finger[1]/flex_link[5]/flex_joint_from_virtual_link[1]_to_virtual_link[2]" type="continuous">
    <parent link="finger[1]/flex_link[5]/virtual_link[1]"/>
    <child link="finger[1]/flex_link[5]/virtual_link[2]"/>
    <origin xyz="0 0 0"/>
    <axis xyz="-1 0 0"/>
  </joint>
  <joint name="finger[1]/flex_link[5]/flex_joint_from_virtual_link[2]_to_flex_link[6]" type="continuous">
    <parent link="finger[1]/flex_link[5]/virtual_link[2]"/>
    <child link="finger[1]/flex_link[6]"/>
    <origin xyz="0 0 0"/>
    <axis xyz="0 0 -1"/>
  </joint>
  <joint name="finger[1]/flex_link[6]/flex_joint_from_flex_link[6]_to_virtual_link[1]" type="continuous">
    <parent link="finger[1]/flex_link[6]"/>
    <child link="finger[1]/flex_link[6]/virtual_link[1]"/>
    <origin xyz="0.00177777777778 0 0"/>
    <axis xyz="0 -1 0"/>
  </joint>
  <joint name="finger[1]/flex_link[6]/flex_joint_from_virtual_link[1]_to_virtual_link[2]" type="continuous">
    <parent link="finger[1]/flex_link[6]/virtual_link[1]"/>
    <child link="finger[1]/flex_link[6]/virtual_link[2]"/>
    <origin xyz="0 0 0"/>
    <axis xyz="-1 0 0"/>
  </joint>
  <joint name="finger[1]/flex_link[6]/flex_joint_from_virtual_link[2]_to_flex_link[7]" type="continuous">
    <parent link="finger[1]/flex_link[6]/virtual_link[2]"/>
    <child link="finger[1]/flex_link[7]"/>
    <origin xyz="0 0 0"/>
    <axis xyz="0 0 -1"/>
  </joint>
  <joint name="finger[1]/flex_link[7]/flex_joint_from_flex_link[7]_to_virtual_link[1]" type="continuous">
    <parent link="finger[1]/flex_link[7]"/>
    <child link="finger[1]/flex_link[7]/virtual_link[1]"/>
    <origin xyz="0.00177777777778 0 0"/>
    <axis xyz="0 -1 0"/>
  </joint>
  <joint name="finger[1]/flex_link[7]/flex_joint_from_virtual_link[1]_to_virtual_link[2]" type="continuous">
    <parent link="finger[1]/flex_link[7]/virtual_link[1]"/>
    <child link="finger[1]/flex_link[7]/virtual_link[2]"/>
    <origin xyz="0 0 0"/>
    <axis xyz="-1 0 0"/>
  </joint>
  <joint name="finger[1]/flex_link[7]/flex_joint_from_virtual_link[2]_to_flex_link[8]" type="continuous">
    <parent link="finger[1]/flex_link[7]/virtual_link[2]"/>
    <child link="finger[1]/flex_link[8]"/>
    <origin xyz="0 0 0"/>
    <axis xyz="0 0 -1"/>
  </joint>
  <joint name="finger[1]/flex_link[8]/flex_joint_from_flex_link[8]_to_virtual_link[1]" type="continuous">
    <parent link="finger[1]/flex_link[8]"/>
    <child link="finger[1]/flex_link[8]/virtual_link[1]"/>
    <origin xyz="0.00177777777778 0 0"/>
    <axis xyz="0 -1 0"/>
  </joint>
  <joint name="finger[1]/flex_link[8]/flex_joint_from_virtual_link[1]_to_virtual_link[2]" type="continuous">
    <parent link="finger[1]/flex_link[8]/virtual_link[1]"/>
    <child link="finger[1]/flex_link[8]/virtual_link[2]"/>
    <origin xyz="0 0 0"/>
    <axis xyz="-1 0 0"/>
  </joint>
  <joint name="finger[1]/flex_link[8]/flex_joint_from_virtual_link[2]_to_flex_link[9]" type="continuous">
    <parent link="finger[1]/flex_link[8]/virtual_link[2]"/>
    <child link="finger[1]/flex_link[9]"/>
    <origin xyz="0 0 0"/>
    <axis xyz="0 0 -1"/>
  </joint>
  <link name="finger[1]/prox/virtual_link[1]"/>
  <link name="finger[1]/prox/virtual_link[2]"/>
  <joint name="finger[1]/prox/flex_joint_from_prox_to_virtual_link[1]" type="continuous">
    <parent link="proximal_1"/>
    <child link="finger[1]/prox/virtual_link[1]"/>
    <origin xyz="0.06 0 -0.004"/>
    <axis xyz="0 -1 0"/>
  </joint>
  <joint name="finger[1]/prox/flex_joint_from_virtual_link[1]_to_virtual_link[2]" type="continuous">
    <parent link="finger[1]/prox/virtual_link[1]"/>
    <child link="finger[1]/prox/virtual_link[2]"/>
    <origin xyz="0 0 0"/>
    <axis xyz="-1 0 0"/>
  </joint>
  <joint name="finger[1]/prox/flex_joint_from_virtual_link[2]_to_flex_link[1]" type="continuous">
    <parent link="finger[1]/prox/virtual_link[2]"/>
    <child link="finger[1]/flex_link[1]"/>
    <origin xyz="0 0 0"/>
    <axis xyz="0 0 -1"/>
  </joint>
  <joint name="finger[1]/flex_link[9]/flex_joint_from_flex_link[9]_to_virtual_link[1]" type="continuous">
    <parent link="finger[1]/flex_link[9]"/>
    <child link="finger[1]/flex_link[9]/virtual_link[1]"/>
    <origin xyz="-0.00822222222222 0 0.008"/>
    <axis xyz="0 -1 0"/>
  </joint>
  <joint name="finger[1]/flex_link[9]/flex_joint_from_virtual_link[1]_to_virtual_link[2]" type="continuous">
    <parent link="finger[1]/flex_link[9]/virtual_link[1]"/>
    <child link="finger[1]/flex_link[9]/virtual_link[2]"/>
    <origin xyz="0 0 0"/>
    <axis xyz="-1 0 0"/>
  </joint>
  <joint name="finger[1]/flex_link[9]/flex_joint_from_virtual_link[2]_to_dist" type="continuous">
    <parent link="finger[1]/flex_link[9]/virtual_link[2]"/>
    <child link="distal_1"/>
    <origin xyz="0 0 0"/>
    <axis xyz="0 0 -1"/>
  </joint>

  <link name="finger[2]/flex_link[1]">
    <inertial>
			<origin rpy="0.00000 -0.00000 0.00000" xyz="0.00000 0.00000 0.00000"/>
			<mass value="0.00000"/>
			<inertia ixx="0.00000" ixy="0" ixz="0" iyy="0.00000" iyz="0" izz="0.00000"/>
		</inertial>
    <visual>
      <origin rpy="1.57075 0 1.57075" xyz="0 -0.008 0.001"/>
      <geometry>
        <mesh filename="package://righthand/meshes/flex_block.stl"/>
      </geometry>
      <material name="">
        <color rgba="0.2 0.2 .2 1"/>
      </material>
    </visual>
  </link>

  <link name="finger[2]/flex_link[1]/virtual_link[1]"/>
  <link name="finger[2]/flex_link[1]/virtual_link[2]"/>

  <link name="finger[2]/flex_link[2]">
    <inertial>
			<origin rpy="0.00000 -0.00000 0.00000" xyz="0.00000 0.00000 0.00000"/>
			<mass value="0.00000"/>
			<inertia ixx="0.00000" ixy="0" ixz="0" iyy="0.00000" iyz="0" izz="0.00000"/>
		</inertial>
    <visual>
      <origin rpy="1.57075 0 1.57075" xyz="0 -0.008 0.001"/>
      <geometry>
        <mesh filename="package://righthand/meshes/flex_block.stl"/>
      </geometry>
      <material name="">
        <color rgba="0.2 0.2 .2 1"/>
      </material>
    </visual>
  </link>

  <link name="finger[2]/flex_link[2]/virtual_link[1]"/>
  <link name="finger[2]/flex_link[2]/virtual_link[2]"/>

  <link name="finger[2]/flex_link[3]">
    <inertial>
			<origin rpy="0.00000 -0.00000 0.00000" xyz="0.00000 0.00000 0.00000"/>
			<mass value="0.00000"/>
			<inertia ixx="0.00000" ixy="0" ixz="0" iyy="0.00000" iyz="0" izz="0.00000"/>
		</inertial>
    <visual>
      <origin rpy="1.57075 0 1.57075" xyz="0 -0.008 0.001"/>
      <geometry>
        <mesh filename="package://righthand/meshes/flex_block.stl"/>
      </geometry>
      <material name="">
        <color rgba="0.2 0.2 .2 1"/>
      </material>
    </visual>
  </link>

  <link name="finger[2]/flex_link[3]/virtual_link[1]"/>
  <link name="finger[2]/flex_link[3]/virtual_link[2]"/>

  <link name="finger[2]/flex_link[4]">
    <inertial>
			<origin rpy="0.00000 -0.00000 0.00000" xyz="0.00000 0.00000 0.00000"/>
			<mass value="0.00000"/>
			<inertia ixx="0.00000" ixy="0" ixz="0" iyy="0.00000" iyz="0" izz="0.00000"/>
		</inertial>
    <visual>
      <origin rpy="1.57075 0 1.57075" xyz="0 -0.008 0.001"/>
      <geometry>
        <mesh filename="package://righthand/meshes/flex_block.stl"/>
      </geometry>
      <material name="">
        <color rgba="0.2 0.2 .2 1"/>
      </material>
    </visual>
  </link>

  <link name="finger[2]/flex_link[4]/virtual_link[1]"/>
  <link name="finger[2]/flex_link[4]/virtual_link[2]"/>

  <link name="finger[2]/flex_link[5]">
    <inertial>
			<origin rpy="0.00000 -0.00000 0.00000" xyz="0.00000 0.00000 0.00000"/>
			<mass value="0.00000"/>
			<inertia ixx="0.00000" ixy="0" ixz="0" iyy="0.00000" iyz="0" izz="0.00000"/>
		</inertial>
    <visual>
      <origin rpy="1.57075 0 1.57075" xyz="0 -0.008 0.001"/>
      <geometry>
        <mesh filename="package://righthand/meshes/flex_block.stl"/>
      </geometry>
      <material name="">
        <color rgba="0.2 0.2 .2 1"/>
      </material>
    </visual>
  </link>

  <link name="finger[2]/flex_link[5]/virtual_link[1]"/>
  <link name="finger[2]/flex_link[5]/virtual_link[2]"/>

  <link name="finger[2]/flex_link[6]">
    <inertial>
			<origin rpy="0.00000 -0.00000 0.00000" xyz="0.00000 0.00000 0.00000"/>
			<mass value="0.00000"/>
			<inertia ixx="0.00000" ixy="0" ixz="0" iyy="0.00000" iyz="0" izz="0.00000"/>
		</inertial>
    <visual>
      <origin rpy="1.57075 0 1.57075" xyz="0 -0.008 0.001"/>
      <geometry>
        <mesh filename="package://righthand/meshes/flex_block.stl"/>
      </geometry>
      <material name="">
        <color rgba="0.2 0.2 .2 1"/>
      </material>
    </visual>
  </link>

  <link name="finger[2]/flex_link[6]/virtual_link[1]"/>
  <link name="finger[2]/flex_link[6]/virtual_link[2]"/>

  <link name="finger[2]/flex_link[7]">
    <visual>
      <origin rpy="1.57075 0 1.57075" xyz="0 -0.008 0.001"/>
      <geometry>
        <mesh filename="package://righthand/meshes/flex_block.stl"/>
      </geometry>
      <material name="">
        <color rgba="0.2 0.2 .2 1"/>
      </material>
    </visual>
  </link>

  <link name="finger[2]/flex_link[7]/virtual_link[1]"/>
  <link name="finger[2]/flex_link[7]/virtual_link[2]"/>

  <link name="finger[2]/flex_link[8]">
    <inertial>
			<origin rpy="0.00000 -0.00000 0.00000" xyz="0.00000 0.00000 0.00000"/>
			<mass value="0.00000"/>
			<inertia ixx="0.00000" ixy="0" ixz="0" iyy="0.00000" iyz="0" izz="0.00000"/>
		</inertial>
    <visual>
      <origin rpy="1.57075 0 1.57075" xyz="0 -0.008 0.001"/>
      <geometry>
        <mesh filename="package://righthand/meshes/flex_block.stl"/>
      </geometry>
      <material name="">
        <color rgba="0.2 0.2 .2 1"/>
      </material>
    </visual>
  </link>

  <link name="finger[2]/flex_link[8]/virtual_link[1]"/>
  <link name="finger[2]/flex_link[8]/virtual_link[2]"/>

  <link name="finger[2]/flex_link[9]">
    <inertial>
			<origin rpy="0.00000 -0.00000 0.00000" xyz="0.00000 0.00000 0.00000"/>
			<mass value="0.00000"/>
			<inertia ixx="0.00000" ixy="0" ixz="0" iyy="0.00000" iyz="0" izz="0.00000"/>
		</inertial>
    <visual>
      <origin rpy="1.57075 0 1.57075" xyz="0 -0.008 0.001"/>
      <geometry>
        <mesh filename="package://righthand/meshes/flex_block.stl"/>
      </geometry>
      <material name="">
        <color rgba="0.2 0.2 .2 1"/>
      </material>
    </visual>
  </link>

  <link name="finger[2]/flex_link[9]/virtual_link[1]"/>
  <link name="finger[2]/flex_link[9]/virtual_link[2]"/>
  <joint name="finger[2]/flex_link[1]/flex_joint_from_flex_link[1]_to_virtual_link[1]" type="continuous">
    <parent link="finger[2]/flex_link[1]"/>
    <child link="finger[2]/flex_link[1]/virtual_link[1]"/>
    <origin xyz="0.00177777777778 0 0"/>
    <axis xyz="0 -1 0"/>
  </joint>
  <joint name="finger[2]/flex_link[1]/flex_joint_from_virtual_link[1]_to_virtual_link[2]" type="continuous">
    <parent link="finger[2]/flex_link[1]/virtual_link[1]"/>
    <child link="finger[2]/flex_link[1]/virtual_link[2]"/>
    <origin xyz="0 0 0"/>
    <axis xyz="-1 0 0"/>
  </joint>
  <joint name="finger[2]/flex_link[1]/flex_joint_from_virtual_link[2]_to_flex_link[2]" type="continuous">
    <parent link="finger[2]/flex_link[1]/virtual_link[2]"/>
    <child link="finger[2]/flex_link[2]"/>
    <origin xyz="0 0 0"/>
    <axis xyz="0 0 -1"/>
  </joint>
  <joint name="finger[2]/flex_link[2]/flex_joint_from_flex_link[2]_to_virtual_link[1]" type="continuous">
    <parent link="finger[2]/flex_link[2]"/>
    <child link="finger[2]/flex_link[2]/virtual_link[1]"/>
    <origin xyz="0.00177777777778 0 0"/>
    <axis xyz="0 -1 0"/>
  </joint>
  <joint name="finger[2]/flex_link[2]/flex_joint_from_virtual_link[1]_to_virtual_link[2]" type="continuous">
    <parent link="finger[2]/flex_link[2]/virtual_link[1]"/>
    <child link="finger[2]/flex_link[2]/virtual_link[2]"/>
    <origin xyz="0 0 0"/>
    <axis xyz="-1 0 0"/>
  </joint>
  <joint name="finger[2]/flex_link[2]/flex_joint_from_virtual_link[2]_to_flex_link[3]" type="continuous">
    <parent link="finger[2]/flex_link[2]/virtual_link[2]"/>
    <child link="finger[2]/flex_link[3]"/>
    <origin xyz="0 0 0"/>
    <axis xyz="0 0 -1"/>
  </joint>
  <joint name="finger[2]/flex_link[3]/flex_joint_from_flex_link[3]_to_virtual_link[1]" type="continuous">
    <parent link="finger[2]/flex_link[3]"/>
    <child link="finger[2]/flex_link[3]/virtual_link[1]"/>
    <origin xyz="0.00177777777778 0 0"/>
    <axis xyz="0 -1 0"/>
  </joint>
  <joint name="finger[2]/flex_link[3]/flex_joint_from_virtual_link[1]_to_virtual_link[2]" type="continuous">
    <parent link="finger[2]/flex_link[3]/virtual_link[1]"/>
    <child link="finger[2]/flex_link[3]/virtual_link[2]"/>
    <origin xyz="0 0 0"/>
    <axis xyz="-1 0 0"/>
  </joint>
  <joint name="finger[2]/flex_link[3]/flex_joint_from_virtual_link[2]_to_flex_link[4]" type="continuous">
    <parent link="finger[2]/flex_link[3]/virtual_link[2]"/>
    <child link="finger[2]/flex_link[4]"/>
    <origin xyz="0 0 0"/>
    <axis xyz="0 0 -1"/>
  </joint>
  <joint name="finger[2]/flex_link[4]/flex_joint_from_flex_link[4]_to_virtual_link[1]" type="continuous">
    <parent link="finger[2]/flex_link[4]"/>
    <child link="finger[2]/flex_link[4]/virtual_link[1]"/>
    <origin xyz="0.00177777777778 0 0"/>
    <axis xyz="0 -1 0"/>
  </joint>
  <joint name="finger[2]/flex_link[4]/flex_joint_from_virtual_link[1]_to_virtual_link[2]" type="continuous">
    <parent link="finger[2]/flex_link[4]/virtual_link[1]"/>
    <child link="finger[2]/flex_link[4]/virtual_link[2]"/>
    <origin xyz="0 0 0"/>
    <axis xyz="-1 0 0"/>
  </joint>
  <joint name="finger[2]/flex_link[4]/flex_joint_from_virtual_link[2]_to_flex_link[5]" type="continuous">
    <parent link="finger[2]/flex_link[4]/virtual_link[2]"/>
    <child link="finger[2]/flex_link[5]"/>
    <origin xyz="0 0 0"/>
    <axis xyz="0 0 -1"/>
  </joint>
  <joint name="finger[2]/flex_link[5]/flex_joint_from_flex_link[5]_to_virtual_link[1]" type="continuous">
    <parent link="finger[2]/flex_link[5]"/>
    <child link="finger[2]/flex_link[5]/virtual_link[1]"/>
    <origin xyz="0.00177777777778 0 0"/>
    <axis xyz="0 -1 0"/>
  </joint>
  <joint name="finger[2]/flex_link[5]/flex_joint_from_virtual_link[1]_to_virtual_link[2]" type="continuous">
    <parent link="finger[2]/flex_link[5]/virtual_link[1]"/>
    <child link="finger[2]/flex_link[5]/virtual_link[2]"/>
    <origin xyz="0 0 0"/>
    <axis xyz="-1 0 0"/>
  </joint>
  <joint name="finger[2]/flex_link[5]/flex_joint_from_virtual_link[2]_to_flex_link[6]" type="continuous">
    <parent link="finger[2]/flex_link[5]/virtual_link[2]"/>
    <child link="finger[2]/flex_link[6]"/>
    <origin xyz="0 0 0"/>
    <axis xyz="0 0 -1"/>
  </joint>
  <joint name="finger[2]/flex_link[6]/flex_joint_from_flex_link[6]_to_virtual_link[1]" type="continuous">
    <parent link="finger[2]/flex_link[6]"/>
    <child link="finger[2]/flex_link[6]/virtual_link[1]"/>
    <origin xyz="0.00177777777778 0 0"/>
    <axis xyz="0 -1 0"/>
  </joint>
  <joint name="finger[2]/flex_link[6]/flex_joint_from_virtual_link[1]_to_virtual_link[2]" type="continuous">
    <parent link="finger[2]/flex_link[6]/virtual_link[1]"/>
    <child link="finger[2]/flex_link[6]/virtual_link[2]"/>
    <origin xyz="0 0 0"/>
    <axis xyz="-1 0 0"/>
  </joint>
  <joint name="finger[2]/flex_link[6]/flex_joint_from_virtual_link[2]_to_flex_link[7]" type="continuous">
    <parent link="finger[2]/flex_link[6]/virtual_link[2]"/>
    <child link="finger[2]/flex_link[7]"/>
    <origin xyz="0 0 0"/>
    <axis xyz="0 0 -1"/>
  </joint>
  <joint name="finger[2]/flex_link[7]/flex_joint_from_flex_link[7]_to_virtual_link[1]" type="continuous">
    <parent link="finger[2]/flex_link[7]"/>
    <child link="finger[2]/flex_link[7]/virtual_link[1]"/>
    <origin xyz="0.00177777777778 0 0"/>
    <axis xyz="0 -1 0"/>
  </joint>
  <joint name="finger[2]/flex_link[7]/flex_joint_from_virtual_link[1]_to_virtual_link[2]" type="continuous">
    <parent link="finger[2]/flex_link[7]/virtual_link[1]"/>
    <child link="finger[2]/flex_link[7]/virtual_link[2]"/>
    <origin xyz="0 0 0"/>
    <axis xyz="-1 0 0"/>
  </joint>
  <joint name="finger[2]/flex_link[7]/flex_joint_from_virtual_link[2]_to_flex_link[8]" type="continuous">
    <parent link="finger[2]/flex_link[7]/virtual_link[2]"/>
    <child link="finger[2]/flex_link[8]"/>
    <origin xyz="0 0 0"/>
    <axis xyz="0 0 -1"/>
  </joint>
  <joint name="finger[2]/flex_link[8]/flex_joint_from_flex_link[8]_to_virtual_link[1]" type="continuous">
    <parent link="finger[2]/flex_link[8]"/>
    <child link="finger[2]/flex_link[8]/virtual_link[1]"/>
    <origin xyz="0.00177777777778 0 0"/>
    <axis xyz="0 -1 0"/>
  </joint>
  <joint name="finger[2]/flex_link[8]/flex_joint_from_virtual_link[1]_to_virtual_link[2]" type="continuous">
    <parent link="finger[2]/flex_link[8]/virtual_link[1]"/>
    <child link="finger[2]/flex_link[8]/virtual_link[2]"/>
    <origin xyz="0 0 0"/>
    <axis xyz="-1 0 0"/>
  </joint>
  <joint name="finger[2]/flex_link[8]/flex_joint_from_virtual_link[2]_to_flex_link[9]" type="continuous">
    <parent link="finger[2]/flex_link[8]/virtual_link[2]"/>
    <child link="finger[2]/flex_link[9]"/>
    <origin xyz="0 0 0"/>
    <axis xyz="0 0 -1"/>
  </joint>
  <link name="finger[2]/prox/virtual_link[1]"/>
  <link name="finger[2]/prox/virtual_link[2]"/>
  <joint name="finger[2]/prox/flex_joint_from_prox_to_virtual_link[1]" type="continuous">
    <parent link="proximal_2"/>
    <child link="finger[2]/prox/virtual_link[1]"/>
    <origin xyz="0.06 0 -0.004"/>
    <axis xyz="0 -1 0"/>
  </joint>
  <joint name="finger[2]/prox/flex_joint_from_virtual_link[1]_to_virtual_link[2]" type="continuous">
    <parent link="finger[2]/prox/virtual_link[1]"/>
    <child link="finger[2]/prox/virtual_link[2]"/>
    <origin xyz="0 0 0"/>
    <axis xyz="-1 0 0"/>
  </joint>
  <joint name="finger[2]/prox/flex_joint_from_virtual_link[2]_to_flex_link[1]" type="continuous">
    <parent link="finger[2]/prox/virtual_link[2]"/>
    <child link="finger[2]/flex_link[1]"/>
    <origin xyz="0 0 0"/>
    <axis xyz="0 0 -1"/>
  </joint>
  <joint name="finger[2]/flex_link[9]/flex_joint_from_flex_link[9]_to_virtual_link[1]" type="continuous">
    <parent link="finger[2]/flex_link[9]"/>
    <child link="finger[2]/flex_link[9]/virtual_link[1]"/>
    <origin xyz="-0.00822222222222 0 0.008"/>
    <axis xyz="0 -1 0"/>
  </joint>
  <joint name="finger[2]/flex_link[9]/flex_joint_from_virtual_link[1]_to_virtual_link[2]" type="continuous">
    <parent link="finger[2]/flex_link[9]/virtual_link[1]"/>
    <child link="finger[2]/flex_link[9]/virtual_link[2]"/>
    <origin xyz="0 0 0"/>
    <axis xyz="-1 0 0"/>
  </joint>
  <joint name="finger[2]/flex_link[9]/flex_joint_from_virtual_link[2]_to_dist" type="continuous">
    <parent link="finger[2]/flex_link[9]/virtual_link[2]"/>
    <child link="distal_2"/>
    <origin xyz="0 0 0"/>
    <axis xyz="0 0 -1"/>
  </joint>

  <link name="finger[3]/flex_link[1]">
    <inertial>
			<origin rpy="0.00000 -0.00000 0.00000" xyz="0.00000 0.00000 0.00000"/>
			<mass value="0.00000"/>
			<inertia ixx="0.00000" ixy="0" ixz="0" iyy="0.00000" iyz="0" izz="0.00000"/>
		</inertial>
    <visual>
      <origin rpy="1.57075 0 1.57075" xyz="0 -0.008 0.001"/>
      <geometry>
        <mesh filename="package://righthand/meshes/flex_block.stl"/>
      </geometry>
      <material name="">
        <color rgba="0.2 0.2 .2 1"/>
      </material>
    </visual>
  </link>

  <link name="finger[3]/flex_link[1]/virtual_link[1]"/>
  <link name="finger[3]/flex_link[1]/virtual_link[2]"/>

  <link name="finger[3]/flex_link[2]">
    <inertial>
			<origin rpy="0.00000 -0.00000 0.00000" xyz="0.00000 0.00000 0.00000"/>
			<mass value="0.00000"/>
			<inertia ixx="0.00000" ixy="0" ixz="0" iyy="0.00000" iyz="0" izz="0.00000"/>
		</inertial>
    <visual>
      <origin rpy="1.57075 0 1.57075" xyz="0 -0.008 0.001"/>
      <geometry>
        <mesh filename="package://righthand/meshes/flex_block.stl"/>
      </geometry>
      <material name="">
        <color rgba="0.2 0.2 .2 1"/>
      </material>
    </visual>
  </link>

  <link name="finger[3]/flex_link[2]/virtual_link[1]"/>
  <link name="finger[3]/flex_link[2]/virtual_link[2]"/>

  <link name="finger[3]/flex_link[3]">
    <inertial>
			<origin rpy="0.00000 -0.00000 0.00000" xyz="0.00000 0.00000 0.00000"/>
			<mass value="0.00000"/>
			<inertia ixx="0.00000" ixy="0" ixz="0" iyy="0.00000" iyz="0" izz="0.00000"/>
		</inertial>
    <visual>
      <origin rpy="1.57075 0 1.57075" xyz="0 -0.008 0.001"/>
      <geometry>
        <mesh filename="package://righthand/meshes/flex_block.stl"/>
      </geometry>
      <material name="">
        <color rgba="0.2 0.2 .2 1"/>
      </material>
    </visual>
  </link>

  <link name="finger[3]/flex_link[3]/virtual_link[1]"/>
  <link name="finger[3]/flex_link[3]/virtual_link[2]"/>

  <link name="finger[3]/flex_link[4]">
    <inertial>
			<origin rpy="0.00000 -0.00000 0.00000" xyz="0.00000 0.00000 0.00000"/>
			<mass value="0.00000"/>
			<inertia ixx="0.00000" ixy="0" ixz="0" iyy="0.00000" iyz="0" izz="0.00000"/>
		</inertial>
    <visual>
      <origin rpy="1.57075 0 1.57075" xyz="0 -0.008 0.001"/>
      <geometry>
        <mesh filename="package://righthand/meshes/flex_block.stl"/>
      </geometry>
      <material name="">
        <color rgba="0.2 0.2 .2 1"/>
      </material>
    </visual>
  </link>

  <link name="finger[3]/flex_link[4]/virtual_link[1]"/>
  <link name="finger[3]/flex_link[4]/virtual_link[2]"/>

  <link name="finger[3]/flex_link[5]">
    <inertial>
			<origin rpy="0.00000 -0.00000 0.00000" xyz="0.00000 0.00000 0.00000"/>
			<mass value="0.00000"/>
			<inertia ixx="0.00000" ixy="0" ixz="0" iyy="0.00000" iyz="0" izz="0.00000"/>
		</inertial>
    <visual>
      <origin rpy="1.57075 0 1.57075" xyz="0 -0.008 0.001"/>
      <geometry>
        <mesh filename="package://righthand/meshes/flex_block.stl"/>
      </geometry>
      <material name="">
        <color rgba="0.2 0.2 .2 1"/>
      </material>
    </visual>
  </link>

  <link name="finger[3]/flex_link[5]/virtual_link[1]"/>
  <link name="finger[3]/flex_link[5]/virtual_link[2]"/>

  <link name="finger[3]/flex_link[6]">
    <inertial>
			<origin rpy="0.00000 -0.00000 0.00000" xyz="0.00000 0.00000 0.00000"/>
			<mass value="0.00000"/>
			<inertia ixx="0.00000" ixy="0" ixz="0" iyy="0.00000" iyz="0" izz="0.00000"/>
		</inertial>
    <visual>
      <origin rpy="1.57075 0 1.57075" xyz="0 -0.008 0.001"/>
      <geometry>
        <mesh filename="package://righthand/meshes/flex_block.stl"/>
      </geometry>
      <material name="">
        <color rgba="0.2 0.2 .2 1"/>
      </material>
    </visual>
  </link>

  <link name="finger[3]/flex_link[6]/virtual_link[1]"/>
  <link name="finger[3]/flex_link[6]/virtual_link[2]"/>

  <link name="finger[3]/flex_link[7]">
    <inertial>
			<origin rpy="0.00000 -0.00000 0.00000" xyz="0.00000 0.00000 0.00000"/>
			<mass value="0.00000"/>
			<inertia ixx="0.00000" ixy="0" ixz="0" iyy="0.00000" iyz="0" izz="0.00000"/>
		</inertial>
    <visual>
      <origin rpy="1.57075 0 1.57075" xyz="0 -0.008 0.001"/>
      <geometry>
        <mesh filename="package://righthand/meshes/flex_block.stl"/>
      </geometry>
      <material name="">
        <color rgba="0.2 0.2 .2 1"/>
      </material>
    </visual>
  </link>

  <link name="finger[3]/flex_link[7]/virtual_link[1]"/>
  <link name="finger[3]/flex_link[7]/virtual_link[2]"/>

  <link name="finger[3]/flex_link[8]">
    <inertial>
			<origin rpy="0.00000 -0.00000 0.00000" xyz="0.00000 0.00000 0.00000"/>
			<mass value="0.00000"/>
			<inertia ixx="0.00000" ixy="0" ixz="0" iyy="0.00000" iyz="0" izz="0.00000"/>
		</inertial>
    <visual>
      <origin rpy="1.57075 0 1.57075" xyz="0 -0.008 0.001"/>
      <geometry>
        <mesh filename="package://righthand/meshes/flex_block.stl"/>
      </geometry>
      <material name="">
        <color rgba="0.2 0.2 .2 1"/>
      </material>
    </visual>
  </link>

  <link name="finger[3]/flex_link[8]/virtual_link[1]"/>
  <link name="finger[3]/flex_link[8]/virtual_link[2]"/>

  <link name="finger[3]/flex_link[9]">
    <inertial>
			<origin rpy="0.00000 -0.00000 0.00000" xyz="0.00000 0.00000 0.00000"/>
			<mass value="0.00000"/>
			<inertia ixx="0.00000" ixy="0" ixz="0" iyy="0.00000" iyz="0" izz="0.00000"/>
		</inertial>
    <visual>
      <origin rpy="1.57075 0 1.57075" xyz="0 -0.008 0.001"/>
      <geometry>
        <mesh filename="package://righthand/meshes/flex_block.stl"/>
      </geometry>
      <material name="">
        <color rgba="0.2 0.2 .2 1"/>
      </material>
    </visual>
  </link>

  <link name="finger[3]/flex_link[9]/virtual_link[1]"/>
  <link name="finger[3]/flex_link[9]/virtual_link[2]"/>
  <joint name="finger[3]/flex_link[1]/flex_joint_from_flex_link[1]_to_virtual_link[1]" type="continuous">
    <parent link="finger[3]/flex_link[1]"/>
    <child link="finger[3]/flex_link[1]/virtual_link[1]"/>
    <origin xyz="0.00177777777778 0 0"/>
    <axis xyz="0 -1 0"/>
  </joint>
  <joint name="finger[3]/flex_link[1]/flex_joint_from_virtual_link[1]_to_virtual_link[2]" type="continuous">
    <parent link="finger[3]/flex_link[1]/virtual_link[1]"/>
    <child link="finger[3]/flex_link[1]/virtual_link[2]"/>
    <origin xyz="0 0 0"/>
    <axis xyz="-1 0 0"/>
  </joint>
  <joint name="finger[3]/flex_link[1]/flex_joint_from_virtual_link[2]_to_flex_link[2]" type="continuous">
    <parent link="finger[3]/flex_link[1]/virtual_link[2]"/>
    <child link="finger[3]/flex_link[2]"/>
    <origin xyz="0 0 0"/>
    <axis xyz="0 0 -1"/>
  </joint>
  <joint name="finger[3]/flex_link[2]/flex_joint_from_flex_link[2]_to_virtual_link[1]" type="continuous">
    <parent link="finger[3]/flex_link[2]"/>
    <child link="finger[3]/flex_link[2]/virtual_link[1]"/>
    <origin xyz="0.00177777777778 0 0"/>
    <axis xyz="0 -1 0"/>
  </joint>
  <joint name="finger[3]/flex_link[2]/flex_joint_from_virtual_link[1]_to_virtual_link[2]" type="continuous">
    <parent link="finger[3]/flex_link[2]/virtual_link[1]"/>
    <child link="finger[3]/flex_link[2]/virtual_link[2]"/>
    <origin xyz="0 0 0"/>
    <axis xyz="-1 0 0"/>
  </joint>
  <joint name="finger[3]/flex_link[2]/flex_joint_from_virtual_link[2]_to_flex_link[3]" type="continuous">
    <parent link="finger[3]/flex_link[2]/virtual_link[2]"/>
    <child link="finger[3]/flex_link[3]"/>
    <origin xyz="0 0 0"/>
    <axis xyz="0 0 -1"/>
  </joint>
  <joint name="finger[3]/flex_link[3]/flex_joint_from_flex_link[3]_to_virtual_link[1]" type="continuous">
    <parent link="finger[3]/flex_link[3]"/>
    <child link="finger[3]/flex_link[3]/virtual_link[1]"/>
    <origin xyz="0.00177777777778 0 0"/>
    <axis xyz="0 -1 0"/>
  </joint>
  <joint name="finger[3]/flex_link[3]/flex_joint_from_virtual_link[1]_to_virtual_link[2]" type="continuous">
    <parent link="finger[3]/flex_link[3]/virtual_link[1]"/>
    <child link="finger[3]/flex_link[3]/virtual_link[2]"/>
    <origin xyz="0 0 0"/>
    <axis xyz="-1 0 0"/>
  </joint>
  <joint name="finger[3]/flex_link[3]/flex_joint_from_virtual_link[2]_to_flex_link[4]" type="continuous">
    <parent link="finger[3]/flex_link[3]/virtual_link[2]"/>
    <child link="finger[3]/flex_link[4]"/>
    <origin xyz="0 0 0"/>
    <axis xyz="0 0 -1"/>
  </joint>
  <joint name="finger[3]/flex_link[4]/flex_joint_from_flex_link[4]_to_virtual_link[1]" type="continuous">
    <parent link="finger[3]/flex_link[4]"/>
    <child link="finger[3]/flex_link[4]/virtual_link[1]"/>
    <origin xyz="0.00177777777778 0 0"/>
    <axis xyz="0 -1 0"/>
  </joint>
  <joint name="finger[3]/flex_link[4]/flex_joint_from_virtual_link[1]_to_virtual_link[2]" type="continuous">
    <parent link="finger[3]/flex_link[4]/virtual_link[1]"/>
    <child link="finger[3]/flex_link[4]/virtual_link[2]"/>
    <origin xyz="0 0 0"/>
    <axis xyz="-1 0 0"/>
  </joint>
  <joint name="finger[3]/flex_link[4]/flex_joint_from_virtual_link[2]_to_flex_link[5]" type="continuous">
    <parent link="finger[3]/flex_link[4]/virtual_link[2]"/>
    <child link="finger[3]/flex_link[5]"/>
    <origin xyz="0 0 0"/>
    <axis xyz="0 0 -1"/>
  </joint>
  <joint name="finger[3]/flex_link[5]/flex_joint_from_flex_link[5]_to_virtual_link[1]" type="continuous">
    <parent link="finger[3]/flex_link[5]"/>
    <child link="finger[3]/flex_link[5]/virtual_link[1]"/>
    <origin xyz="0.00177777777778 0 0"/>
    <axis xyz="0 -1 0"/>
  </joint>
  <joint name="finger[3]/flex_link[5]/flex_joint_from_virtual_link[1]_to_virtual_link[2]" type="continuous">
    <parent link="finger[3]/flex_link[5]/virtual_link[1]"/>
    <child link="finger[3]/flex_link[5]/virtual_link[2]"/>
    <origin xyz="0 0 0"/>
    <axis xyz="-1 0 0"/>
  </joint>
  <joint name="finger[3]/flex_link[5]/flex_joint_from_virtual_link[2]_to_flex_link[6]" type="continuous">
    <parent link="finger[3]/flex_link[5]/virtual_link[2]"/>
    <child link="finger[3]/flex_link[6]"/>
    <origin xyz="0 0 0"/>
    <axis xyz="0 0 -1"/>
  </joint>
  <joint name="finger[3]/flex_link[6]/flex_joint_from_flex_link[6]_to_virtual_link[1]" type="continuous">
    <parent link="finger[3]/flex_link[6]"/>
    <child link="finger[3]/flex_link[6]/virtual_link[1]"/>
    <origin xyz="0.00177777777778 0 0"/>
    <axis xyz="0 -1 0"/>
  </joint>
  <joint name="finger[3]/flex_link[6]/flex_joint_from_virtual_link[1]_to_virtual_link[2]" type="continuous">
    <parent link="finger[3]/flex_link[6]/virtual_link[1]"/>
    <child link="finger[3]/flex_link[6]/virtual_link[2]"/>
    <origin xyz="0 0 0"/>
    <axis xyz="-1 0 0"/>
  </joint>
  <joint name="finger[3]/flex_link[6]/flex_joint_from_virtual_link[2]_to_flex_link[7]" type="continuous">
    <parent link="finger[3]/flex_link[6]/virtual_link[2]"/>
    <child link="finger[3]/flex_link[7]"/>
    <origin xyz="0 0 0"/>
    <axis xyz="0 0 -1"/>
  </joint>
  <joint name="finger[3]/flex_link[7]/flex_joint_from_flex_link[7]_to_virtual_link[1]" type="continuous">
    <parent link="finger[3]/flex_link[7]"/>
    <child link="finger[3]/flex_link[7]/virtual_link[1]"/>
    <origin xyz="0.00177777777778 0 0"/>
    <axis xyz="0 -1 0"/>
  </joint>
  <joint name="finger[3]/flex_link[7]/flex_joint_from_virtual_link[1]_to_virtual_link[2]" type="continuous">
    <parent link="finger[3]/flex_link[7]/virtual_link[1]"/>
    <child link="finger[3]/flex_link[7]/virtual_link[2]"/>
    <origin xyz="0 0 0"/>
    <axis xyz="-1 0 0"/>
  </joint>
  <joint name="finger[3]/flex_link[7]/flex_joint_from_virtual_link[2]_to_flex_link[8]" type="continuous">
    <parent link="finger[3]/flex_link[7]/virtual_link[2]"/>
    <child link="finger[3]/flex_link[8]"/>
    <origin xyz="0 0 0"/>
    <axis xyz="0 0 -1"/>
  </joint>
  <joint name="finger[3]/flex_link[8]/flex_joint_from_flex_link[8]_to_virtual_link[1]" type="continuous">
    <parent link="finger[3]/flex_link[8]"/>
    <child link="finger[3]/flex_link[8]/virtual_link[1]"/>
    <origin xyz="0.00177777777778 0 0"/>
    <axis xyz="0 -1 0"/>
  </joint>
  <joint name="finger[3]/flex_link[8]/flex_joint_from_virtual_link[1]_to_virtual_link[2]" type="continuous">
    <parent link="finger[3]/flex_link[8]/virtual_link[1]"/>
    <child link="finger[3]/flex_link[8]/virtual_link[2]"/>
    <origin xyz="0 0 0"/>
    <axis xyz="-1 0 0"/>
  </joint>
  <joint name="finger[3]/flex_link[8]/flex_joint_from_virtual_link[2]_to_flex_link[9]" type="continuous">
    <parent link="finger[3]/flex_link[8]/virtual_link[2]"/>
    <child link="finger[3]/flex_link[9]"/>
    <origin xyz="0 0 0"/>
    <axis xyz="0 0 -1"/>
  </joint>
  <link name="finger[3]/prox/virtual_link[1]"/>
  <link name="finger[3]/prox/virtual_link[2]"/>
  <joint name="finger[3]/prox/flex_joint_from_prox_to_virtual_link[1]" type="continuous">
    <parent link="proximal_3"/>
    <child link="finger[3]/prox/virtual_link[1]"/>
    <origin xyz="0.06 0 -0.004"/>
    <axis xyz="0 -1 0"/>
  </joint>
  <joint name="finger[3]/prox/flex_joint_from_virtual_link[1]_to_virtual_link[2]" type="continuous">
    <parent link="finger[3]/prox/virtual_link[1]"/>
    <child link="finger[3]/prox/virtual_link[2]"/>
    <origin xyz="0 0 0"/>
    <axis xyz="-1 0 0"/>
  </joint>
  <joint name="finger[3]/prox/flex_joint_from_virtual_link[2]_to_flex_link[1]" type="continuous">
    <parent link="finger[3]/prox/virtual_link[2]"/>
    <child link="finger[3]/flex_link[1]"/>
    <origin xyz="0 0 0"/>
    <axis xyz="0 0 -1"/>
  </joint>
  <joint name="finger[3]/flex_link[9]/flex_joint_from_flex_link[9]_to_virtual_link[1]" type="continuous">
    <parent link="finger[3]/flex_link[9]"/>
    <child link="finger[3]/flex_link[9]/virtual_link[1]"/>
    <origin xyz="-0.00822222222222 0 0.008"/>
    <axis xyz="0 -1 0"/>
  </joint>
  <joint name="finger[3]/flex_link[9]/flex_joint_from_virtual_link[1]_to_virtual_link[2]" type="continuous">
    <parent link="finger[3]/flex_link[9]/virtual_link[1]"/>
    <child link="finger[3]/flex_link[9]/virtual_link[2]"/>
    <origin xyz="0 0 0"/>
    <axis xyz="-1 0 0"/>
  </joint>
  <joint name="finger[3]/flex_link[9]/flex_joint_from_virtual_link[2]_to_dist" type="continuous">
    <parent link="finger[3]/flex_link[9]/virtual_link[2]"/>
    <child link="distal_3"/>
    <origin xyz="0 0 0"/>
    <axis xyz="0 0 -1"/>
  </joint>
-->

  <!-- ################ ################ ################ ################ ################ ################ -->
  <!-- ################ THE SECTION CREATED BY SOLIDWORKS EXPORTER, CUT AND PASTE THIS IN HERE ################ -->
  <!-- ################ YOU CAN ALTER THE COLORS FROM HERE ################ -->
  <!-- ################ COMMENT OUT ALL dist*_joint PIECES OF THIS URDF SO THE FLEX JOINTS CAN LINK UP ################ -->
  <!-- ################ ################ ################ ################ ################ ################ -->
  <link name="base_link">
    <inertial>
			<origin rpy="0.00000 -0.00000 0.00000" xyz="0.00000 0.00000 0.00000"/>
			<mass value="0.00000"/>
			<inertia ixx="0.00000" ixy="0" ixz="0" iyy="0.00000" iyz="0" izz="0.00000"/>
		</inertial>
    <visual>
      <origin rpy="0 0 0" xyz="0 0 0"/>
      <geometry>
        <mesh filename="package://righthand/meshes/base_link.stl"/>
      </geometry>
      <material name="">
        <color rgba="0.1 0.1 0.1 1"/>
      </material>
    </visual>
  </link>

  <link name="pad">
    <inertial>
			<origin rpy="0.00000 -0.00000 0.00000" xyz="0.00000 0.00000 0.00000"/>
			<mass value="0.00000"/>
			<inertia ixx="0.00000" ixy="0" ixz="0" iyy="0.00000" iyz="0" izz="0.00000"/>
		</inertial>
    <visual>
      <origin rpy="0 0 0" xyz="0 0 0"/>
      <geometry>
        <mesh filename="package://righthand/meshes/pad.stl"/>
      </geometry>
      <material name="">
        <color rgba="0.2 0.8 0.75 1"/>
      </material>
    </visual>
  </link>

  <joint name="pad_joint" type="fixed">
    <origin rpy="1.5707963267949 5.55111512312578E-17 -1.5707963267949" xyz="0.02 0 0.063"/>
    <parent link="base_link"/>
    <child link="pad"/>
    <axis xyz="0 0 0"/>
  </joint>

  <link name="swivel_1">
    <inertial>
		<origin rpy="0.00000 -0.00000 0.00000" xyz="0.00000 0.00000 0.00000"/>
		<mass value="0.00000"/>
		<inertia ixx="0.00000" ixy="0" ixz="0" iyy="0.00000" iyz="0" izz="0.00000"/>
	</inertial>
    <visual>
      <origin rpy="0.00000 -0.00000 0.00000" xyz="0 0 0"/>
      <geometry>
        <mesh filename="package://righthand/meshes/swivel_1.stl"/>
      </geometry>
      <material name="">
        <color rgba="0.1 0.1 0.1 1"/>
      </material>
    </visual>
  </link>

  <joint name="preshape_1" type="continuous">
    <origin rpy="6.75550818663469E-16 1.97993848419069E-16 -2.77555756156289E-16" xyz="0.0503973683071414 -0.026 0.063"/>
    <parent link="base_link"/>
    <child link="swivel_1"/>
    <axis xyz="0 0 -1"/>
  </joint>

  <link name="proximal_1">
    <inertial>
		<origin rpy="3.1459 0.00000 0.00000" xyz="-0.011 0.007 0.011"/>
		<mass value="0.00000"/>
        <inertia ixx="0.00000" ixy="0" ixz="0" iyy="0.00000" iyz="0" izz="0.00000"/>
	</inertial>
    <visual>
      <origin rpy="3.1459 0.00000 0.00000" xyz="-0.011 0.007 0.011"/>
      <geometry>
        <mesh filename="package://righthand/meshes/proximal_1.stl"/>
      </geometry>
      <material name="">
        <color rgba="0.16 0.16 0.16 1"/>
      </material>
    </visual>
  </link>

  <joint name="proximal_joint_1" type="revolute">
    <origin rpy="-6.20039667432211E-16 0.05 2.22044604925031E-16" xyz="0.01 0 0.0186"/>
    <parent link="swivel_1"/>
    <child link="proximal_1"/>
	<limit lower="-1.0" upper="1.0" effort="0" velocity="1.0"/>
    <axis xyz="0 -1 0"/>
  </joint>
  


  <link name="distal_pad_1">
    <inertial>
		<origin rpy="1.5708 1.5708 0" xyz="-0.00825 0.009 0.057"/> 
		<mass value="0.00000"/>
        <inertia ixx="0.00000" ixy="0" ixz="0" iyy="0.00000" iyz="0" izz="0.00000"/>
	</inertial>
    <visual>
      <origin rpy="1.5708 1.5708 0" xyz="-0.00825 0.009 0.057"/>
      <geometry>
        <mesh filename="package://righthand/meshes/distal_pad_1.stl"/>
      </geometry>
      <material name="">
        <color rgba="0.2 0.8 0.75 1"/>
      </material>
    </visual>
  </link>


  <joint name="dist1_pad_joint" type="fixed">
    <origin rpy="1.5707963267949 0 -1.5707963267949" xyz="-0.01 0 0.001"/> 
    <parent link="distal_1"/>
    <child link="distal_pad_1"/>
    <axis xyz="0 0 0"/>
  </joint>



  	<link name="flex_block_1">
		<inertial>
			<origin rpy="0.00000 -0.00000 0.00000" xyz="0.00000 0.00000 0.00000"/>
			<mass value="0.00000"/>
			<inertia ixx="0.00000" ixy="0" ixz="0" iyy="0.00000" iyz="0" izz="0.00000"/>
		</inertial>
		<visual>
			<origin rpy="0.00000 -0.00000 0.00000" xyz="0.00000 0.00000 0.00000"/>
			<geometry>
				<mesh filename="righthand/meshes/flex_block.stl" scale = "1.30000 1.30000 1.30000"/>
			</geometry>
		</visual>
		<collision>
			<origin rpy="0.00000 -0.00000 0.00000" xyz="0.00000 0.00000 0.00000"/>
			<geometry>
				<mesh filename="righthand/meshes/flex_block.stl" scale = "1.30000 1.30000 1.30000"/>
			</geometry>
		</collision>
	</link>
    
	<joint name="flex_block_1" type="revolute">
		<parent link="proximal_1"/>
		<child link="flex_block_1"/>
		<dynamics damping="1.0" friction="0.0001"/>
		<origin rpy="0.00000 -0.00000 0.00000" xyz="0.05900 -0.00350 -0.00300"/>
		<limit lower="-1.0" upper="1.0" effort="0" velocity="1.0"/>
		<axis xyz="0.00000 1.00000 0.00000"/>
    </joint>

    <link name="proximal_pad_1">
    <inertial>
		<origin rpy="1.5708 1.5708 0" xyz="-0.008 0.014 -0.002"/> 
		<mass value="0.00000"/>
    <inertia ixx="0.00000" ixy="0" ixz="0" iyy="0.00000" iyz="0" izz="0.00000"/>
	</inertial>
    <visual>
      <origin rpy="1.5708 1.5708 0" xyz="-0.008 0.014 -0.002"/>
      <geometry>
        <mesh filename="package://righthand/meshes/proximal_pad_1.stl"/>
      </geometry>
      <material name="">
        <color rgba="0.2 0.8 0.75 1"/>
      </material>
    </visual>
  </link>
  <joint name="prox1_pad_joint" type="fixed">
    <origin rpy="1.5707963267949 0 -1.5707963267949" xyz="0 0 0"/>
    <parent link="proximal_1"/>
    <child link="proximal_pad_1"/>
    <axis xyz="0 0 0"/>
  </joint>

   
  <link name="distal_1">
    <inertial>
		<origin rpy="3.1459 0 0" xyz="-0.077 0.007 0.007"/> 
		<mass value="0.00000"/>
        <inertia ixx="0.00000" ixy="0" ixz="0" iyy="0.00000" iyz="0" izz="0.00000"/>
	</inertial>
    <visual>
      <origin rpy="3.1459 0 0" xyz="-0.077 0.007 0.007"/>
      <geometry>
        <mesh filename="package://righthand/meshes/distal_1.stl"/>
      </geometry>
      <material name="">
        <color rgba="0.16 0.16 0.16 1"/>
      </material>
    </visual>
   </link>
  
    <joint name="distal_joint_1" type="continuous">
        <origin rpy="0 0 0" xyz="0.00670000000000001 0.00350 0.00550000000000002"/> 
        <parent link="flex_block_1"/>
        <child link="distal_1"/>
        <axis xyz="0 -1 0"/>
    </joint>
  





  
  

  <link name="swivel_2">
    <inertial>
			<origin rpy="0.00000 -0.00000 0.00000" xyz="0.00000 0.00000 0.00000"/>
			<mass value="0.00000"/>
			<inertia ixx="0.00000" ixy="0" ixz="0" iyy="0.00000" iyz="0" izz="0.00000"/>
		</inertial>
    <visual>
      <origin rpy="0 0 0" xyz="0 0 0"/>
      <geometry>
        <mesh filename="package://righthand/meshes/swivel_2.stl"/>
      </geometry>
      <material name="">
        <color rgba="0.1 0.1 0.1 1"/>
      </material>
    </visual>
  </link>

  <joint name="preshape_2" type="continuous">
    <origin rpy="1.22459340959228E-15 -7.33448407631817E-16 -1.66533453693773E-16" xyz="0.0503973683071413 0.0259999999999999 0.063"/>
    <parent link="base_link"/>
    <child link="swivel_2"/>
    <axis xyz="0 0 -1"/>
  </joint>

  <link name="proximal_2">
    <inertial>
			<origin rpy="0.00000 -0.00000 0.00000" xyz="0.00000 0.00000 0.00000"/>
			<mass value="0.00000"/>
			<inertia ixx="0.00000" ixy="0" ixz="0" iyy="0.00000" iyz="0" izz="0.00000"/>
		</inertial>
    <visual>
      <origin rpy="3.1459 0 0" xyz="-0.011 0.007 0.011"/>
      <geometry>
        <mesh filename="package://righthand/meshes/proximal_1.stl"/>
      </geometry>
      <material name="">
        <color rgba="0.16 0.16 0.16 1"/>
      </material>
    </visual>
  </link>


  <joint name="proximal_joint_2" type="revolute">
    <origin rpy="-1.16908225836102E-15 0.05 1.11022302462515E-16" xyz="0.01 0 0.0186"/>
    <parent link="swivel_2"/>
    <child link="proximal_2"/>
    <limit lower="-1.0" upper="1.0" effort="0" velocity="1.0"/>
    <axis xyz="0 -1 0"/>
  </joint>


  <link name="proximal_pad_2">
    <inertial>
			<origin rpy="0.00000 -0.00000 0.00000" xyz="0.00000 0.00000 0.00000"/>
			<mass value="0.00000"/>
			<inertia ixx="0.00000" ixy="0" ixz="0" iyy="0.00000" iyz="0" izz="0.00000"/>
		</inertial>
    <visual>
      <origin rpy="1.5708 1.5708 0" xyz="-0.008 0.014 -0.002"/>
      <geometry>
        <mesh filename="package://righthand/meshes/proximal_pad_1.stl"/>
      </geometry>
      <material name="">
        <color rgba="0.2 0.8 0.75 1"/>
      </material>
    </visual>
  </link>

  <joint name="prox2_pad_joint" type="fixed">
    <origin rpy="1.5707963267949 0 -1.5707963267949" xyz="0 0 0"/>
    <parent link="proximal_2"/>
    <child link="proximal_pad_2"/>
    <axis xyz="0 0 0"/>
  </joint>


  <link name="distal_pad_2">
    <inertial>
			<origin rpy="1.5708 1.5708 0" xyz="-0.00825 0.009 0.057"/>
			<mass value="0.00000"/>
			<inertia ixx="0.00000" ixy="0" ixz="0" iyy="0.00000" iyz="0" izz="0.00000"/>
		</inertial>
    <visual>
      <origin rpy="1.5708 1.5708 0" xyz="-0.00825 0.009 0.057"/>
      <geometry>
        <mesh filename="package://righthand/meshes/distal_pad_1.stl"/>
      </geometry>
      <material name="">
        <color rgba="0.2 0.8 0.75 1"/>
      </material>
    </visual>
  </link>

  <joint name="dist2_pad_joint" type="fixed">
    <origin rpy="1.5707963267949 0 -1.5707963267949" xyz="-0.01 0 0.001"/>
    <parent link="distal_2"/>
    <child link="distal_pad_2"/>
    <axis xyz="0 0 0"/>
  </joint>


  	<link name="flex_block_2">
		<inertial>
			<origin rpy="0.00000 -0.00000 0.00000" xyz="0.00000 0.00000 0.00000"/>
			<mass value="0.00000"/>
			<inertia ixx="0.00000" ixy="0" ixz="0" iyy="0.00000" iyz="0" izz="0.00000"/>
		</inertial>
		<visual>
			<origin rpy="0.00000 -0.00000 0.00000" xyz="0.00000 0.00000 0.00000"/>
			<geometry>
				<mesh filename="righthand/meshes/flex_block.stl" scale = "1.30000 1.30000 1.30000"/>
			</geometry>
		</visual>
		<collision>
			<origin rpy="0.00000 -0.00000 0.00000" xyz="0.00000 0.00000 0.00000"/>
			<geometry>
				<mesh filename="righthand/meshes/flex_block.stl" scale = "1.30000 1.30000 1.30000"/>
			</geometry>
		</collision>
	</link>
    
	<joint name="flex_block_2" type="revolute">
		<parent link="proximal_2"/>
		<child link="flex_block_2"/>
		<dynamics damping="1.0" friction="0.0001"/>
		<origin rpy="0.00000 -0.00000 0.00000" xyz="0.05900 -0.00350 -0.00300"/>  
		<limit lower="-1.0" upper="1.0" effort="0" velocity="1.0"/>
		<axis xyz="0.00000 1.00000 0.00000"/>
    </joint>
    
    
    
    
  <link name="distal_2">
    <inertial>
			<origin rpy="0.00000 -0.00000 0.00000" xyz="0.00000 0.00000 0.00000"/>
			<mass value="0.00000"/>
			<inertia ixx="0.00000" ixy="0" ixz="0" iyy="0.00000" iyz="0" izz="0.00000"/>
		</inertial>
    <visual>
      <origin rpy="3.1459 0 0" xyz="-0.077 0.007 0.006"/>
      <geometry>
        <mesh filename="package://righthand/meshes/distal_1.stl"/>
      </geometry>
      <material name="">
        <color rgba="0.16 0.16 0.16 1"/>
      </material>
    </visual>
  </link>

  <joint name="distal_joint_2" type="revolute">
    <origin rpy="0 0 0" xyz="0.00670000000000001 0.00350 0.00550000000000002"/>  
    <parent link="flex_block_2"/>
    <child link="distal_2"/>
    <limit lower="-1.0" upper="1.0" effort="0" velocity="1.0"/>
    <axis xyz="0 -1 0"/>
  </joint>
















  <link name="proximal_3">
    <inertial>
			<origin rpy="0.00000 -0.00000 0.00000" xyz="0.00000 0.00000 0.00000"/>
			<mass value="0.00000"/>
			<inertia ixx="0.00000" ixy="0" ixz="0" iyy="0.00000" iyz="0" izz="0.00000"/>
		</inertial>
    <visual>
      <origin rpy="3.1459 0 0" xyz="-0.011 0.007 0.011"/>
      <geometry>
        <mesh filename="package://righthand/meshes/proximal_1.stl"/>
      </geometry>
      <material name="">
        <color rgba="0.16 0.16 0.16 1"/>
      </material>
    </visual>
  </link>

  <joint name="proximal_joint_3" type="continuous">
    <origin rpy="-5.55111512312578E-17 0.05 3.14159265358979" xyz="-0.0299999999999996 0 0.0816000000000002"/>
    <parent link="base_link"/>
    <child link="proximal_3"/>
    <axis xyz="0 -1 0"/>
  </joint>
  
  
  	<link name="flex_block_3">
		<inertial>
			<origin rpy="0.00000 -0.00000 0.00000" xyz="0.00000 0.00000 0.00000"/>
			<mass value="0.00000"/>
			<inertia ixx="0.00000" ixy="0" ixz="0" iyy="0.00000" iyz="0" izz="0.00000"/>
		</inertial>
		<visual>
			<origin rpy="0.00000 -0.00000 0.00000" xyz="0.00000 0.00000 0.00000"/>
			<geometry>
				<mesh filename="righthand/meshes/flex_block.stl" scale = "1.30000 1.30000 1.30000"/>
			</geometry>
		</visual>
		<collision>
			<origin rpy="0.00000 -0.00000 0.00000" xyz="0.00000 0.00000 0.00000"/>
			<geometry>
				<mesh filename="righthand/meshes/flex_block.stl" scale = "1.30000 1.30000 1.30000"/>
			</geometry>
		</collision>
	</link>
    
	<joint name="flex_block_3" type="revolute">
		<parent link="proximal_3"/>
		<child link="flex_block_3"/>
		<dynamics damping="1.0" friction="0.0001"/>
		<origin rpy="0.00000 -0.00000 0.00000" xyz="0.05900 -0.00350 -0.00300"/>  
		<limit lower="-1.0" upper="1.0" effort="0" velocity="1.0"/>
		<axis xyz="0.00000 1.00000 0.00000"/>
    </joint>
    
    

  <link name="proximal_pad_3">
    <inertial>
			<origin rpy="0.00000 -0.00000 0.00000" xyz="0.00000 0.00000 0.00000"/>
			<mass value="0.00000"/>
			<inertia ixx="0.00000" ixy="0" ixz="0" iyy="0.00000" iyz="0" izz="0.00000"/>
		</inertial>
    <visual>
      <origin rpy="1.5708 1.5708 0" xyz="-0.008 0.014 -0.002"/>
      <geometry>
        <mesh filename="package://righthand/meshes/proximal_pad_1.stl"/>
      </geometry>
      <material name="">
        <color rgba="0.2 0.8 0.75 1"/>
      </material>
    </visual>
  </link>

  <joint name="prox3_pad_joint" type="fixed">
    <origin rpy="1.5707963267949 1.22460635382238E-16 -1.5707963267949" xyz="0 0 0"/>
    <parent link="proximal_3"/>
    <child link="proximal_pad_3"/>
    <axis xyz="0 0 0"/>
  </joint>

  <link name="distal_3">
    <inertial>
			<origin rpy="0.00000 -0.00000 0.00000" xyz="0.00000 0.00000 0.00000"/>
			<mass value="0.00000"/>
			<inertia ixx="0.00000" ixy="0" ixz="0" iyy="0.00000" iyz="0" izz="0.00000"/>
		</inertial>
    <visual>
      <origin rpy="3.1459 0 0" xyz="-0.077 0.007 0.006"/>
      <geometry>
        <mesh filename="package://righthand/meshes/distal_1.stl"/>
      </geometry>
      <material name="">
        <color rgba="0.16 0.16 0.16 1"/>
      </material>
    </visual>
  </link>
  <joint name="distal_joint_3" type="continuous">
    <origin rpy="-1.48887961834512E-45 -1.0995850059156E-76 -7.38531841236285E-32" xyz="0.00670000000000001 0.00350 0.00550000000000002"/>
    <parent link="flex_block_3"/>
    <child link="distal_3"/>
    <axis xyz="0 -1 0"/>
  </joint>

  <link name="distal_pad_3">
    <inertial>
			<origin rpy="0.00000 -0.00000 0.00000" xyz="0.00000 0.00000 0.00000"/>
			<mass value="0.00000"/>
			<inertia ixx="0.00000" ixy="0" ixz="0" iyy="0.00000" iyz="0" izz="0.00000"/>
		</inertial>
    <visual>
      <origin rpy="1.5708 1.5708 0" xyz="-0.00825 0.009 0.057"/>
      <geometry>
        <mesh filename="package://righthand/meshes/distal_pad_1.stl"/>
      </geometry>
      <material name="">
        <color rgba="0.2 0.8 0.75 1"/>
      </material>
    </visual>
  </link>

  <joint name="dist3_pad_joint" type="fixed">
    <origin rpy="1.5707963267949 0 -1.5707963267949" xyz="-0.01 0 0.001"/>
    <parent link="distal_3"/>
    <child link="distal_pad_3"/>
    <axis xyz="0 0 0"/>
  </joint>

  
  
  
  <!-- ################ ################ ################ ################ ################ ################ -->
  <!-- ################ THIS SECTION LINKS THE MARKERS (TACTILE DATA) TO THE CAD MESH ################ -->
  <!-- ################ COPY AND PASTE THIS FROM urdf/homemade_marker_portion_urdf  ################ -->
  <!-- ################ ################ ################ ################ ################ ################ -->

<!--
  <joint name="base_tactile_joint" type="fixed">
    <origin rpy="0 0 0" xyz="0 0 0"/>
    <parent link="base_link"/>
    <child link="base_tactile"/>
  </joint>
  <link name="base_tactile"/>
  <link name="proximal_1_tactile"/>
  <joint name="proximal_1_tactile_joint" type="fixed">
    <origin rpy="0 0 0" xyz="0 0 0"/>
    <parent link="proximal_1"/>
    <child link="proximal_1_tactile"/>
  </joint>
  <joint name="proximal_2_tactile_joint" type="fixed">
    <origin rpy="0 0 0" xyz="0 0 0"/>
    <parent link="proximal_2"/>
    <child link="proximal_2_tactile"/>
  </joint>
  <link name="proximal_2_tactile"/>
  <joint name="proximal_3_tactile_joint" type="fixed">
    <origin rpy="0 0 0" xyz="0 0 0"/>
    <parent link="proximal_3"/>
    <child link="proximal_3_tactile"/>
  </joint>
  <link name="proximal_3_tactile"/>0 0 0
  <joint name="distal_1_tactile_joint" type="fixed">
    <origin rpy="0 0 0" xyz="-0.0062 0 0"/>
    <parent link="distal_1"/>
    <child link="distal_1_tactile"/>
  </joint>
  <link name="distal_1_tactile"/>
  <joint name="distal_2_tactile_joint" type="fixed">
    <origin rpy="0 0 0" xyz="-0.0062 0 0"/>
    <parent link="distal_2"/>
    <child link="distal_2_tactile"/>
  </joint>
  <link name="distal_2_tactile"/>
  <joint name="distal_3_tactile_joint" type="fixed">
    <origin rpy="0 0 0" xyz="-0.0062 0 0"/>
    <parent link="distal_3"/>
    <child link="distal_3_tactile"/>
  </joint>
  <link name="distal_3_tactile"/>
-->
</robot>
