<?xml version="0.0" ?>
<robot name="">

	<link name="base_link">
		<inertial>
			<origin rpy="0.00000 -0.00000 0.00000" xyz="0.00000 0.00000 0.00000"/>
			<mass value="0.00000"/>
			<inertia ixx="0.00000" ixy="0" ixz="0" iyy="0.00000" iyz="0" izz="0.00000"/>
		</inertial>
		<visual>
			<origin rpy="0.00000 -0.00000 0.00000" xyz="0.00000 0.00000 0.00000"/>
			<geometry>
				<mesh filename="righthand/meshes/base_link.stl" scale="1.00000 1.00000 1.00000"/>
			</geometry>
		</visual>
		<collision>
			<origin rpy="0.00000 -0.00000 0.00000" xyz="0.00000 0.00000 0.00000"/>
			<geometry>
				<mesh filename="righthand/meshes/base_link.stl" scale="1.00000 1.00000 1.00000"/>
			</geometry>
		</collision>
	</link>


	<link name="pad">
		<inertial>
			<origin rpy="1.55000 0.00000 -1.58000" xyz="0.00000 0.00000 0.00000"/>
			<mass value="0.00000"/>
			<inertia ixx="0.00000" ixy="0" ixz="0" iyy="0.00000" iyz="0" izz="0.00000"/>
		</inertial>
		<visual>
			<origin rpy="1.55000 0.00000 -1.58000" xyz="0.00000 0.00000 0.00000"/>
			<geometry>
				<mesh filename="righthand/meshes/pad.stl" scale="1.00000 1.00000 1.00000"/>
			</geometry>
		</visual>
		<collision>
			<origin rpy="1.55000 0.00000 -1.58000" xyz="0.00000 0.00000 0.00000"/>
			<geometry>
				<mesh filename="righthand/meshes/pad.stl" scale="1.00000 1.00000 1.00000"/>
			</geometry>
		</collision>
	</link>
	<link name="link0_3">
		<inertial>
			<origin rpy="0.00000 -0.00000 0.00000" xyz="0.00000 0.00000 0.00000"/>
			<mass value="0.00000"/>
			<inertia ixx="0.00000" ixy="0" ixz="0" iyy="0.00000" iyz="0" izz="0.00000"/>
		</inertial>
	</link>
	<link name="swivel_1">
		<inertial>
			<origin rpy="0.00000 -0.00000 -0.50000" xyz="0.00000 0.00000 0.00000"/>
			<mass value="0.00000"/>
			<inertia ixx="0.00000" ixy="0" ixz="0" iyy="0.00000" iyz="0" izz="0.00000"/>
		</inertial>
		<visual>
			<origin rpy="0.00000 -0.00000 -0.50000" xyz="0.00000 0.00000 0.00000"/>
			<geometry>
				<mesh filename="righthand/meshes/swivel_1.stl" scale="1.00000 1.00000 1.00000"/>
			</geometry>
		</visual>
		<collision>
			<origin rpy="0.00000 -0.00000 -0.50000" xyz="0.00000 0.00000 0.00000"/>
			<geometry>
				<mesh filename="righthand/meshes/swivel_1.stl" scale="1.00000 1.00000 1.00000"/>
			</geometry>
		</collision>
	</link>
 <link name="link0_5">
		<inertial>
			<origin rpy="0.00000 -0.00000 -0.00000" xyz="0.00000 0.00000 0.00000"/>
			<mass value="0.00000"/>
			<inertia ixx="0.00000" ixy="0" ixz="0" iyy="0.00000" iyz="0" izz="0.00000"/>
		</inertial>
	</link>
	<link name="proximal_1">
		<inertial>
			<origin rpy="0.00000 -0.15000 -0.50000" xyz="0.00000 0.00000 0.00000"/>
			<mass value="0.00000"/>
			<inertia ixx="0.00000" ixy="0" ixz="0" iyy="0.00000" iyz="0" izz="0.00000"/>
		</inertial>
		<visual>
			<origin rpy="0.00000 -0.15000 -0.50000" xyz="0.00000 0.00000 0.00000"/>
			<geometry>
				<mesh filename="righthand/meshes/proximal_1.stl" scale="1.00000 1.00000 1.00000"/>
			</geometry>
		</visual>
		<collision>
			<origin rpy="0.00000 -0.15000 -0.50000" xyz="0.00000 0.00000 0.00000"/>
			<geometry>
				<mesh filename="righthand/meshes/proximal_1.stl" scale="1.00000 1.00000 1.00000"/>
			</geometry>
		</collision>
	</link>
	<link name="link0_7">
		<inertial>
			<origin rpy="0.00000 -0.00000 0.00000" xyz="0.00000 0.00000 0.00000"/>
			<mass value="0.00000"/>
			<inertia ixx="0.00000" ixy="0" ixz="0" iyy="0.00000" iyz="0" izz="0.00000"/>
		</inertial>
	</link>
	<link name="flex_block_1">
		<inertial>
			<origin rpy="0.00000 -0.00000 -0.50000" xyz="0.00000 0.00000 0.00000"/>
			<mass value="0.00000"/>
			<inertia ixx="0.00000" ixy="0" ixz="0" iyy="0.00000" iyz="0" izz="0.00000"/>
		</inertial>
		<visual>
			<origin rpy="0.00000 -0.00000 -0.50000" xyz="0.00000 0.00000 0.00000"/>
			<geometry>
				<mesh filename="righthand/meshes/flex_block.stl" scale="1.30000 1.30000 1.30000"/>
			</geometry>
		</visual>
		<collision>
			<origin rpy="0.00000 -0.00000 -0.50000" xyz="0.00000 0.00000 0.00000"/>
			<geometry>
				<mesh filename="righthand/meshes/flex_block.stl" scale="1.30000 1.30000 1.30000"/>
			</geometry>
		</collision>
	</link>



	<link name="distal_pad_1">
		<inertial>
			<origin rpy="0.00000 -0.00000 0.50000" xyz="0.00000 0.00000 0.00000"/>
			<mass value="0.00000"/>
			<inertia ixx="0.00000" ixy="0" ixz="0" iyy="0.00000" iyz="0" izz="0.00000"/>
		</inertial>
		<visual>
			<origin rpy="0.00000 -0.00000 0.50000" xyz="0.00000 0.00000 0.00000"/>
			<geometry>
				<mesh filename="righthand/meshes/distal_pad_1.stl" scale="1.00000 1.00000 1.00000"/>
			</geometry>
		</visual>
		<collision>
			<origin rpy="0.00000 -0.00000 0.50000" xyz="0.00000 0.00000 0.00000"/>
			<geometry>
				<mesh filename="righthand/meshes/distal_pad_1.stl" scale="1.00000 1.00000 1.00000"/>
			</geometry>
		</collision>
	</link>





	<link name="link0_10">
		<inertial>
			<origin rpy="0.00000 -0.00000 0.00000" xyz="0.00000 0.00000 0.00000"/>
			<mass value="0.00000"/>
			<inertia ixx="0.00000" ixy="0" ixz="0" iyy="0.00000" iyz="0" izz="0.00000"/>
		</inertial>
	</link>

	<link name="swivel_2">
		<inertial>
			<origin rpy="0.00000 -0.00000 0.50000" xyz="0.00000 0.00000 0.00000"/>
			<mass value="0.00000"/>
			<inertia ixx="0.00000" ixy="0" ixz="0" iyy="0.00000" iyz="0" izz="0.00000"/>
		</inertial>
		<visual>
			<origin rpy="0.00000 -0.00000 0.50000" xyz="0.00000 0.00000 0.00000"/>
			<geometry>
				<mesh filename="righthand/meshes/swivel_2.stl" scale="1.00000 1.00000 1.00000"/>
			</geometry>
		</visual>
		<collision>
			<origin rpy="0.00000 -0.00000 0.50000" xyz="0.00000 0.00000 0.00000"/>
			<geometry>
				<mesh filename="righthand/meshes/swivel_2.stl" scale="1.00000 1.00000 1.00000"/>
			</geometry>
		</collision>
	</link>
	<link name="link0_12">
		<inertial>
			<origin rpy="0.00000 -0.00000 0.00000" xyz="0.00000 0.00000 0.00000"/>
			<mass value="0.00000"/>
			<inertia ixx="0.00000" ixy="0" ixz="0" iyy="0.00000" iyz="0" izz="0.00000"/>
		</inertial>
	</link>
	<link name="proximal_2">
		<inertial>
			<origin rpy="0.00000 -0.15000 0.50000" xyz="0.00000 0.00000 0.00000"/>
			<mass value="0.00000"/>
			<inertia ixx="0.00000" ixy="0" ixz="0" iyy="0.00000" iyz="0" izz="0.00000"/>
		</inertial>
		<visual>
			<origin rpy="0.00000 -0.15000 0.50000" xyz="0.00000 0.00000 0.00000"/>
			<geometry>
				<mesh filename="righthand/meshes/proximal_1.stl" scale="1.00000 1.00000 1.00000"/>
			</geometry>
		</visual>
		<collision>
			<origin rpy="0.00000 -0.15000 0.50000" xyz="0.00000 0.00000 0.00000"/>
			<geometry>
				<mesh filename="righthand/meshes/proximal_1.stl" scale="1.00000 1.00000 1.00000"/>
			</geometry>
		</collision>
	</link>


	<link name="link0_14">
		<inertial>
			<origin rpy="0.00000 -0.00000 0.00000" xyz="0.00000 0.00000 0.00000"/>
			<mass value="0.00000"/>
			<inertia ixx="0.00000" ixy="0" ixz="0" iyy="0.00000" iyz="0" izz="0.00000"/>
		</inertial>
	</link>
	<link name="flex_block_2">
		<inertial>
			<origin rpy="0.00000 -0.00000 0.50000" xyz="0.00000 0.00000 0.00000"/>
			<mass value="0.00000"/>
			<inertia ixx="0.00000" ixy="0" ixz="0" iyy="0.00000" iyz="0" izz="0.00000"/>
		</inertial>
		<visual>
			<origin rpy="0.00000 -0.00000 0.50000" xyz="0.00000 0.00000 0.00000"/>
			<geometry>
				<mesh filename="righthand/meshes/flex_block.stl" scale="1.30000 1.30000 1.30000"/>
			</geometry>
		</visual>
		<collision>
			<origin rpy="0.00000 -0.00000 0.50000" xyz="0.00000 0.00000 0.00000"/>
			<geometry>
				<mesh filename="righthand/meshes/flex_block.stl" scale="1.30000 1.30000 1.30000"/>
			</geometry>
		</collision>
	</link>



	<link name="distal_pad_2">
		<inertial>
			<origin rpy="0.00000 -0.00000 -0.50000" xyz="0.00000 0.00000 0.00000"/>
			<mass value="0.00000"/>
			<inertia ixx="0.00000" ixy="0" ixz="0" iyy="0.00000" iyz="0" izz="0.00000"/>
		</inertial>
		<visual>
			<origin rpy="0.00000 -0.00000 -0.50000" xyz="0.00000 0.00000 0.00000"/>
			<geometry>
				<mesh filename="righthand/meshes/distal_pad_1.stl" scale="1.00000 1.00000 1.00000"/>
			</geometry>
		</visual>
		<collision>
			<origin rpy="0.00000 -0.00000 -0.50000" xyz="0.00000 0.00000 0.00000"/>
			<geometry>
				<mesh filename="righthand/meshes/distal_pad_1.stl" scale="1.00000 1.00000 1.00000"/>
			</geometry>
		</collision>
	</link>




	<link name="link0_17">
		<inertial>
			<origin rpy="0.00000 -0.00000 0.00000" xyz="0.00000 0.00000 0.00000"/>
			<mass value="0.00000"/>
			<inertia ixx="0.00000" ixy="0" ixz="0" iyy="0.00000" iyz="0" izz="0.00000"/>
		</inertial>
	</link>
	<link name="proximal_3">
		<inertial>
			<origin rpy="0.00000 -0.60000 0.00000" xyz="0.00000 0.00000 0.00000"/>
			<mass value="0.00000"/>
			<inertia ixx="0.00000" ixy="0" ixz="0" iyy="0.00000" iyz="0" izz="0.00000"/>
		</inertial>
		<visual>
			<origin rpy="0.00000 -0.60000 0.00000" xyz="0.00000 0.00000 0.00000"/>
			<geometry>
				<mesh filename="righthand/meshes/proximal_1.stl" scale="1.00000 1.00000 1.00000"/>
			</geometry>
		</visual>
		<collision>
			<origin rpy="0.00000 -0.60000 0.00000" xyz="0.00000 0.00000 0.00000"/>
			<geometry>
				<mesh filename="righthand/meshes/proximal_1.stl" scale="1.00000 1.00000 1.00000"/>
			</geometry>
		</collision>
	</link>
	<link name="link0_19">
		<inertial>
			<origin rpy="0.00000 -0.00000 0.00000" xyz="0.00000 0.00000 0.00000"/>
			<mass value="0.00000"/>
			<inertia ixx="0.00000" ixy="0" ixz="0" iyy="0.00000" iyz="0" izz="0.00000"/>
		</inertial>
	</link>
	<link name="flex_block_3">
		<inertial>
			<origin rpy="0.00000 -2.30000 0.00000" xyz="0.00000 0.00000 0.00000"/>
			<mass value="0.00000"/>
			<inertia ixx="0.00000" ixy="0" ixz="0" iyy="0.00000" iyz="0" izz="0.00000"/>
		</inertial>
		<visual>
			<origin rpy="0.00000 -2.30000 0.00000" xyz="0.00000 0.00000 0.00000"/>
			<geometry>
				<mesh filename="righthand/meshes/flex_block.stl" scale="1.30000 1.30000 1.30000"/>
			</geometry>
		</visual>
		<collision>
			<origin rpy="0.00000 -2.30000 0.00000" xyz="0.00000 0.00000 0.00000"/>
			<geometry>
				<mesh filename="righthand/meshes/flex_block.stl" scale="1.30000 1.30000 1.30000"/>
			</geometry>
		</collision>
	</link>
	<link name="distal_pad_3">
		<inertial>
			<origin rpy="0.00000 2.30000 0.00000" xyz="0.00000 0.00000 0.00000"/>
			<mass value="0.00000"/>
			<inertia ixx="0.00000" ixy="0" ixz="0" iyy="0.00000" iyz="0" izz="0.00000"/>
		</inertial>
		<visual>
			<origin rpy="0.00000 2.30000 0.00000" xyz="0.00000 0.00000 0.00000"/>
			<geometry>
				<mesh filename="righthand/meshes/distal_pad_1.stl" scale="1.00000 1.00000 1.00000"/>
			</geometry>
		</visual>
		<collision>
			<origin rpy="0.00000 2.00000 0.00000" xyz="0.00000 0.00000 0.00000"/>
			<geometry>
				<mesh filename="righthand/meshes/distal_pad_1.stl" scale="1.00000 1.00000 1.00000"/>
			</geometry>
		</collision>
	</link>
	<joint name="jointfix_11_0" type="fixed">
		<parent link="base_link"/>
		<child link="pad"/>
		<dynamics damping="1.0" friction="0.0001"/>
		<origin rpy="0.00000 -0.00000 0.00000" xyz="0.02100 0.00000 0.06500"/>
		<axis xyz="0.00000 0.00000 0.00000"/>
	</joint>
	<joint name="swivel_1" type="continuous">
		<parent link="pad"/>
		<child link="link0_3"/>
		<dynamics damping="1.0" friction="0.0001"/>
		<origin rpy="0.00000 -0.00000 0.00000" xyz="0.01590 -0.05520 0.00000"/>
		<axis xyz="0.00000 0.00000 1.00000"/>
	</joint>
	<joint name="jointfix_3_3" type="fixed">
		<parent link="link0_3"/>
		<child link="swivel_1"/>
		<dynamics damping="1.0" friction="0.0001"/>
		<origin rpy="0.00000 -0.00000 0.00000" xyz="0.01400 0.02900 0.00000"/>
		<axis xyz="0.00000 0.00000 0.00000"/>
	</joint>
	<joint name="proximal_1" type="continuous">
		<parent link="swivel_1"/>
		<child link="link0_5"/>
		<dynamics damping="1.0" friction="0.0001"/>
		<origin rpy="0.00000 -0.00000 0.00000" xyz="0.00210 -0.00140 0.00370"/>
		<axis xyz="0.00000 1.00000 0.00000"/>
	</joint>
	<joint name="jointfix_2_5" type="fixed">
		<parent link="link0_5"/>
		<child link="proximal_1"/>
		<dynamics damping="1.0" friction="0.0001"/>
		<origin rpy="0.00000 -0.00000 0.00000" xyz="-0.00480 -0.00600 0.00200"/>
		<axis xyz="0.00000 0.00000 0.00000"/>
	</joint>
	<joint name="flex_block_1" type="revolute">
		<parent link="proximal_1"/>
		<child link="link0_7"/>
		<dynamics damping="1.0" friction="0.0001"/>
		<origin rpy="0.00000 -0.00000 0.00000" xyz="0.01450 0.00020 0.00000"/>
		<limit lower="-3.1416" upper="3.1416" effort="10" velocity="3"/>
		<axis xyz="0.00000 1.00000 0.00000"/>
	</joint>
	<joint name="jointfix_1_7" type="fixed">
		<parent link="link0_7"/>
		<child link="flex_block_1"/>
		<dynamics damping="1.0" friction="0.0001"/>
		<origin rpy="0.00000 -0.00000 0.00000" xyz="0.04800 -0.03000 0.01300"/>
		<axis xyz="0.00000 0.00000 0.00000"/>
	</joint>



	<joint name="jointfix_0_6" type="fixed">
		<parent link="flex_block_1"/>
		<child link="distal_pad_1"/>
		<dynamics damping="1.0" friction="0.0001"/>
		<origin rpy="3.14159 -0.00000 0.00000" xyz="-0.04500 0.03880 0.01480"/>
		<axis xyz="0.00000 0.00000 0.00000"/>
	</joint>



	<joint name="swivel_2" type="continuous">
		<parent link="pad"/>
		<child link="link0_10"/>
		<dynamics damping="1.0" friction="0.0001"/>
		<origin rpy="0.00000 -0.00000 0.00000" xyz="0.01590 0.05520 0.00000"/>
		<axis xyz="0.00000 0.00000 1.00000"/>
	</joint>
	<joint name="jointfix_7_10" type="fixed">
		<parent link="link0_10"/>
		<child link="swivel_2"/>
		<dynamics damping="1.0" friction="0.0001"/>
		<origin rpy="0.00000 -0.00000 0.00000" xyz="0.01400 -0.02900 0.00000"/>
		<axis xyz="0.00000 0.00000 0.00000"/>
	</joint>


	<joint name="proximal_2" type="continuous">
		<parent link="swivel_2"/>
		<child link="link0_12"/>
		<dynamics damping="1.0" friction="0.0001"/>
		<origin rpy="0.00000 -0.00000 0.00000" xyz="0.00210 -0.00140 0.00400"/>
		<axis xyz="0.00000 1.00000 0.00000"/>
	</joint>
	<joint name="jointfix_6_12" type="fixed">
		<parent link="link0_12"/>
		<child link="proximal_2"/>
		<dynamics damping="1.0" friction="0.0001"/>
		<origin rpy="0.00000 -0.00000 0.00000" xyz="0.00200 -0.00600 0.00300"/>
		<axis xyz="0.00000 0.00000 0.00000"/>
	</joint>


	<joint name="flex_block_2" type="revolute">
		<parent link="proximal_2"/>
		<child link="link0_14"/>
		<dynamics damping="1.0" friction="0.0001"/>
		<origin rpy="0.00000 -0.00000 0.00000" xyz="0.01450 0.00020 0.00000"/>
		<limit lower="-3.1416" upper="3.1416" effort="10" velocity="3"/>
		<axis xyz="0.00000 1.00000 0.00000"/>
	</joint>


	<joint name="jointfix_5_14" type="fixed">
		<parent link="link0_14"/>
		<child link="flex_block_2"/>
		<dynamics damping="1.0" friction="0.0001"/>
		<origin rpy="0.00000 -0.00000 0.00000" xyz="0.04500 0.03500 0.01300"/>
		<axis xyz="0.00000 0.00000 0.00000"/>
	</joint>



	<joint name="jointfix_4_13" type="fixed">
		<parent link="flex_block_2"/>
		<child link="distal_pad_2"/>
		<dynamics damping="1.0" friction="0.0001"/>
		<origin rpy="3.14159 -0.00000 0.00000" xyz="-0.05800 -0.01720 0.01480"/> <!-- -0.04500 0.03880 0.01480 -->
		<axis xyz="0.00000 0.00000 0.00000"/>
	</joint>






	<joint name="proximal_3" type="continuous">
		<parent link="pad"/>
		<child link="link0_17"/>
		<dynamics damping="1.0" friction="0.0001"/>
		<origin rpy="0.00000 -0.00000 3.14159" xyz="-0.00990 0.00140 0.00400"/>
		<axis xyz="0.00000 1.00000 0.00000"/>
	</joint>
	<joint name="jointfix_10_17" type="fixed">
		<parent link="link0_17"/>
		<child link="proximal_3"/>
		<dynamics damping="1.0" friction="0.0001"/>
		<origin rpy="0.00000 -0.00000 0.00000" xyz="0.04001 -0.00600 -0.00220"/>
		<axis xyz="0.00000 0.00000 0.00000"/>
	</joint>
	<joint name="flex_block_3" type="revolute">
		<parent link="proximal_3"/>
		<child link="link0_19"/>
		<dynamics damping="1.0" friction="0.0001"/>
		<origin rpy="0.00000 -0.00000 0.00000" xyz="0.01000 0.00020 0.00000"/>
		<limit lower="-3.1416" upper="3.1416" effort="10" velocity="3"/>
		<axis xyz="0.00000 1.00000 0.00000"/>
	</joint>
	<joint name="jointfix_9_19" type="fixed">
		<parent link="link0_19"/>
		<child link="flex_block_3"/>
		<dynamics damping="1.0" friction="0.0001"/>
		<origin rpy="0.00000 -0.00000 0.00000" xyz="0.05100 0.00300 0.04300"/>
		<axis xyz="0.00000 0.00000 0.00000"/>
	</joint>
	<joint name="jointfix_8_18" type="fixed">
		<parent link="flex_block_3"/>
		<child link="distal_pad_3"/>
		<dynamics damping="1.0" friction="0.0001"/>
		<origin rpy="3.14159 -0.00000 0.00000" xyz="0.03100 0.01200 -0.05300"/>
		<axis xyz="0.00000 0.00000 0.00000"/>
	</joint>


</robot>
