<?xml version="1.0" ?>
<!-- =================================================================================== -->
<!-- |    This document was autogenerated by xacro from /home/adam/research/16hlpr/kinova-ros/kinova_description/urdf/j2s7s300_standalone.xacro | -->
<!-- |    EDITING THIS FILE BY HAND IS NOT RECOMMENDED                                 | -->
<!-- =================================================================================== -->
<!-- j2s7s300 refers to jaco v2 7DOF spherical 3fingers -->
<robot name="j2s7s300" xmlns:xacro="http://www.ros.org/wiki/xacro">
  <material name="Black">
    <color rgba="0.3 0.3 0.3 1.0"/>
  </material>
  <material name="Gray">
    <color rgba="0.5 0.5 0.5 1.0"/>
  </material>

  <link name="j2s7s300_link_base">
    <visual>
      <geometry>
        <mesh filename="jaco/base.obj"/>
      </geometry>
      <material name="Black"/>
    </visual>
    <collision>
      <geometry>
        <mesh filename="jaco/base.obj"/>
      </geometry>
    </collision>
    <inertial>
      <mass value="0.0"/>
      <origin rpy="0 0 0" xyz="0 0 0"/>
      <inertia ixx="0.000951270861568" ixy="0" ixz="0" iyy="0.000951270861568" iyz="0" izz="0.000374272"/>
    </inertial>
  </link>
  <link name="j2s7s300_link_1">
    <visual>
      <geometry>
        <mesh filename="jaco/shoulder.obj"/>
      </geometry>
      <material name="Black"/>
    </visual>
    <visual>
      <geometry>
        <mesh filename="jaco/ring_big.obj"/>
      </geometry>
      <material name="Black"/>
    </visual>
    <collision>
      <geometry>
        <mesh filename="jaco/shoulder.obj"/>
      </geometry>
    </collision>
    <inertial>
      <mass value="0.7477"/>
      <origin xyz="0 -0.002 -0.0605"/>
      <inertia ixx="0.00152031725204" ixy="0" ixz="0" iyy="0.00152031725204" iyz="0" izz="0.00059816"/>
    </inertial>
  </link>
  <joint name="j2s7s300_joint_1" type="continuous">
    <parent link="j2s7s300_link_base"/>
    <child link="j2s7s300_link_1"/>
    <axis xyz="0 0 1"/>
    <limit effort="2000" lower="-6.28318530718" upper="6.28318530718" velocity="10.0"/>
    <origin rpy="0 3.14159265359 0" xyz="0 0 0.15675"/>
    <dynamics damping="0.5"/>
  </joint>
  <link name="j2s7s300_link_2">
    <visual>
      <geometry>
        <mesh filename="jaco/arm_half_1.obj"/>
      </geometry>
      <material name="Black"/>
    </visual>
    <visual>
      <geometry>
        <mesh filename="jaco/ring_big.obj"/>
      </geometry>
      <material name="Black"/>
    </visual>
    <collision>
      <geometry>
        <mesh filename="jaco/arm_half_1.obj"/>
      </geometry>
    </collision>
    <inertial>
      <mass value="0.8447"/>
      <origin xyz="0 -0.103563213 0"/>
      <inertia ixx="0.00247073761701" ixy="0" ixz="0" iyy="0.000380115" iyz="0" izz="0.00247073761701"/>
    </inertial>
  </link>
  <joint name="j2s7s300_joint_2" type="revolute">
    <parent link="j2s7s300_link_1"/>
    <child link="j2s7s300_link_2"/>
    <axis xyz="0 0 1"/>
    <limit effort="2000" lower="0.523598775598" upper="5.75958653158" velocity="1"/>
    <origin rpy="-1.57079632679 0 3.14159265359" xyz="0 0.0016 -0.11875"/>
    <dynamics damping="0.5"/>
  </joint>
  <link name="j2s7s300_link_3">
    <visual>
      <geometry>
        <mesh filename="jaco/arm_half_2.obj"/>
      </geometry>
      <material name="Black"/>
    </visual>
    <visual>
      <geometry>
        <mesh filename="jaco/ring_big.obj"/>
      </geometry>
      <material name="Black"/>
    </visual>
    <collision>
      <geometry>
        <mesh filename="jaco/arm_half_2.obj"/>
      </geometry>
    </collision>
    <inertial>
      <mass value="0.8447"/>
      <origin xyz="0 0 -0.1022447445"/>
      <inertia ixx="0.00247073761701" ixy="0" ixz="0" iyy="0.00247073761701" iyz="0" izz="0.000380115"/>
    </inertial>
  </link>
  <joint name="j2s7s300_joint_3" type="continuous">
    <parent link="j2s7s300_link_2"/>
    <child link="j2s7s300_link_3"/>
    <axis xyz="0 0 1"/>
    <limit effort="2000" lower="-6.28318530718" upper="6.28318530718" velocity="1"/>
    <origin rpy="-1.57079632679 0 0" xyz="0 -0.205 0"/>
    <dynamics damping="0.5"/>
  </joint>
  <link name="j2s7s300_link_4">
    <visual>
      <geometry>
        <mesh filename="jaco/forearm.obj"/>
      </geometry>
      <material name="Black"/>
    </visual>
    <visual>
      <geometry>
        <mesh filename="jaco/ring_small.obj"/>
      </geometry>
      <material name="Black"/>
    </visual>
    <collision>
      <geometry>
        <mesh filename="jaco/forearm.obj"/>
      </geometry>
    </collision>
    <inertial>
      <mass value="0.6763"/>
      <origin xyz="0 0.081 -0.0086"/>
      <inertia ixx="0.00142022431908" ixy="0" ixz="0" iyy="0.000304335" iyz="0" izz="0.00142022431908"/>
    </inertial>
  </link>
  <joint name="j2s7s300_joint_4" type="revolute">
    <parent link="j2s7s300_link_3"/>
    <child link="j2s7s300_link_4"/>
    <axis xyz="0 0 1"/>
    <limit effort="2000" lower="0.523598775598" upper="5.75958653158" velocity="1"/>
    <origin rpy="1.57079632679 0 3.14159265359" xyz="0 0 -0.205"/>
    <dynamics damping="0.5"/>
  </joint>
  <link name="j2s7s300_link_5">
    <visual>
      <geometry>
        <mesh filename="jaco/wrist_spherical_1.obj"/>
      </geometry>
      <material name="Black"/>
    </visual>
    <visual>
      <geometry>
        <mesh filename="jaco/ring_small.obj"/>
      </geometry>
      <material name="Black"/>
    </visual>
    <collision>
      <geometry>
        <mesh filename="jaco/wrist_spherical_1.obj"/>
      </geometry>
    </collision>
    <inertial>
      <mass value="0.463"/>
      <origin xyz="0 0.0028848942 -0.0541932613"/>
      <inertia ixx="0.0004321316048" ixy="0" ixz="0" iyy="0.0004321316048" iyz="0" izz="9.26e-05"/>
    </inertial>
  </link>
  <joint name="j2s7s300_joint_5" type="continuous">
    <parent link="j2s7s300_link_4"/>
    <child link="j2s7s300_link_5"/>
    <axis xyz="0 0 1"/>
    <limit effort="2000" lower="-6.28318530718" upper="6.28318530718" velocity="1"/>
    <origin rpy="-1.57079632679 0 3.14159265359" xyz="0 0.2073 -0.0114"/>
    <dynamics damping="0.5"/>
  </joint>
  <link name="j2s7s300_link_6">
    <visual>
      <geometry>
        <mesh filename="jaco/wrist_spherical_2.obj"/>
      </geometry>
      <material name="Black"/>
    </visual>
    <visual>
      <geometry>
        <mesh filename="jaco/ring_small.obj"/>
      </geometry>
      <material name="Black"/>
    </visual>
    <collision>
      <geometry>
        <mesh filename="jaco/wrist_spherical_2.obj"/>
      </geometry>
    </collision>
    <inertial>
      <mass value="0.463"/>
      <origin xyz="0 0.0497208855 -0.0028562765"/>
      <inertia ixx="0.0004321316048" ixy="0" ixz="0" iyy="9.26e-05" iyz="0" izz="0.0004321316048"/>
    </inertial>
  </link>
  <joint name="j2s7s300_joint_6" type="revolute">
    <parent link="j2s7s300_link_5"/>
    <child link="j2s7s300_link_6"/>
    <axis xyz="0 0 1"/>
    <limit effort="2000" lower="0.523598775598" upper="5.75958653158" velocity="1"/>
    <origin rpy="1.57079632679 0 3.14159265359" xyz="0 0 -0.10375"/>
    <dynamics damping="0.5"/>
  </joint>
  <!--
        <xacro:kinova_armlink link_name="${prefix}_link_7" link_mesh="${link_7_mesh}" use_ring_mesh="true" ring_mesh="ring_small" mesh_no="${link_7_mesh_no}"/>
        <xacro:kinova_armjoint joint_name="${prefix}_joint_7" type="${joint_7_type}" parent="${prefix}_link_6" child="${prefix}_link_7" joint_axis_xyz="${joint_7_axis_xyz}" joint_origin_xyz="${joint_7_origin_xyz}" joint_origin_rpy="${joint_7_origin_rpy}" joint_lower_limit="${joint_7_lower_limit}" joint_upper_limit="${joint_7_upper_limit}"/>

        <xacro:kinova_virtual_link link_name="${prefix}_end_effector"/>
        <xacro:kinova_virtual_joint joint_name="${prefix}_joint_end_effector" type="${joint_end_effector_type}" parent="${prefix}_link_7" child="${prefix}_end_effector" joint_axis_xyz="${joint_end_effector_axis_xyz}" joint_origin_xyz="${joint_end_effector_origin_xyz}" joint_origin_rpy="${joint_end_effector_origin_rpy}" joint_lower_limit="0" joint_upper_limit="0"/>

        <xacro:kinova_3fingers link_hand="${prefix}_link_7" prefix="${prefix}_"/>
        -->
  <!-- RAIL end-effector additions/modifications -->
  <joint name="j2s7s300_joint_7" type="continuous">
    <parent link="j2s7s300_link_6"/>
    <child link="j2s7s300_link_7"/>
    <origin rpy="1.5707 0 0" xyz="0 0.06075 0"/>
    <axis xyz="0 0 1"/>
    <limit effort="600.8" velocity="0.785"/>
    <dynamics damping="0.5"/>
  </joint>
  <link name="j2s7s300_link_7">
    <visual>
      <geometry>
        <mesh filename="jaco/wrist_3.obj"/>
      </geometry>
      <material name="Gray"/>
    </visual>
    <collision>
      <geometry>
        <mesh filename="jaco/wrist_3.obj"/>
      </geometry>
    </collision>
    <inertial>
      <mass value="0.463"/>
      <origin xyz="0 0.0497208855 -0.0028562765"/>
      <inertia ixx="0.0004321316048" ixy="0" ixz="0" iyy="9.26e-05" iyz="0" izz="0.0004321316048"/>
    </inertial>
  </link>


  <joint name="j2s7s300_ee_fixed_joint" type="fixed">
    <parent link="j2s7s300_link_7"/>
    <child link="j2s7s300_ee_base"/>
    <origin rpy="0 1.57079632679 0" xyz="0 0 -0.09380704"/>
  </joint>

  <link name="j2s7s300_ee_base">
    <inertial>
      <mass value="0.001"/>
      <origin xyz="0 0 0"/>
      <inertia ixx="0" ixy="0" ixz="0" iyy="0" iyz="0" izz="0"/>
    </inertial>
  </link>

  <joint name="j2s7s300_ee_gripper" type="fixed">
    <parent link="j2s7s300_ee_base"/>
    <child link="j2s7s300_ee_link"/>
    <origin xyz="0.13 0 0" rpy="1.57079632679 0 0"/>
  </joint>

  <link name="j2s7s300_ee_link">
    <inertial>
      <mass value="0.001"/>
      <origin xyz="0 0 0"/>
      <inertia ixx="0" ixy="0" ixz="0" iyy="0" iyz="0" izz="0"/>
    </inertial>
  </link>


  <joint name="robotiq_85_base_joint" type="fixed">
    <parent link="j2s7s300_ee_base"/>
    <child link="robotiq_85_base_link"/>
    <origin rpy="0 0 0" xyz="0 0 0"/>
  </joint>
  <link name="robotiq_85_base_link">
    <visual>
      <geometry>
        <mesh filename="robotiq/visual/robotiq_85_base_link.obj"/>
      </geometry>
      <material name="Black"/>
    </visual>
    <collision>
      <geometry>
        <mesh filename="robotiq/collision/robotiq_85_base_link.obj"/>
      </geometry>
    </collision>
    <inertial>
      <mass value="0.636951"/>
      <origin xyz="0.0 0.0 0.0"/>
      <inertia ixx="0.000380" ixy="0.000000" ixz="0.000000" iyx="0.000000" iyy="0.001110" iyz="0.000000" izx="0.000000" izy="0.000000" izz="0.001171"/>
    </inertial>
  </link>
  <joint name="robotiq_85_left_knuckle_joint" type="revolute">
    <parent link="robotiq_85_base_link"/>
    <child link="robotiq_85_left_knuckle_link"/>
    <axis xyz="0 0 1"/>
    <origin rpy="3.14159 0.0 0.0" xyz="0.05490451627 0.03060114443 0.0"/>
    <limit lower="-0.7" upper="0.9" velocity="100.0"/>
  </joint>
  <joint name="robotiq_85_right_knuckle_joint" type="revolute">
    <parent link="robotiq_85_base_link"/>
    <child link="robotiq_85_right_knuckle_link"/>
    <axis xyz="0 0 1"/>
    <origin rpy="0.0 0.0 0.0" xyz="0.05490451627 -0.03060114443 0.0"/>
    <limit lower="-0.7" upper="0.9" velocity="100.0"/>
  </joint>
  <link name="robotiq_85_left_knuckle_link">
    <visual>
      <geometry>
        <mesh filename="robotiq/visual/robotiq_85_knuckle_link.obj"/>
      </geometry>
      <material name="Black"/>
    </visual>
    <collision>
      <geometry>
        <mesh filename="robotiq/collision/robotiq_85_knuckle_link.obj"/>
      </geometry>
    </collision>
    <inertial>
      <mass value="0.018491"/>
      <origin xyz="0.0 0.0 0.0"/>
      <inertia ixx="0.000009" ixy="-0.000001" ixz="0.000000" iyx="-0.000001" iyy="0.000001" iyz="0.000000" izx="0.000000" izy="0.000000" izz="0.000010"/>
    </inertial>
  </link>
  <link name="robotiq_85_right_knuckle_link">
    <visual>
      <geometry>
        <mesh filename="robotiq/visual/robotiq_85_knuckle_link.obj"/>
      </geometry>
      <material name="Black"/>
    </visual>
    <collision>
      <geometry>
        <mesh filename="robotiq/collision/robotiq_85_knuckle_link.obj"/>
      </geometry>
    </collision>
    <inertial>
      <mass value="0.018491"/>
      <origin xyz="0.0 0.0 0.0"/>
      <inertia ixx="0.000009" ixy="-0.000001" ixz="0.000000" iyx="-0.000001" iyy="0.000001" iyz="0.000000" izx="0.000000" izy="0.000000" izz="0.000010"/>
    </inertial>
  </link>
  <joint name="robotiq_85_left_finger_joint" type="fixed">
    <parent link="robotiq_85_left_knuckle_link"/>
    <child link="robotiq_85_left_finger_link"/>
    <origin rpy="0 0 0" xyz="-0.00408552455 -0.03148604435 0.0"/>
    <limit lower="-3.14" upper="3.14" velocity="100.0"/>
  </joint>
  <joint name="robotiq_85_right_finger_joint" type="fixed">
    <parent link="robotiq_85_right_knuckle_link"/>
    <child link="robotiq_85_right_finger_link"/>
    <origin rpy="0 0 0" xyz="-0.00408552455 -0.03148604435 0.0"/>
    <limit lower="-3.14" upper="3.14" velocity="100.0"/>
  </joint>
  <link name="robotiq_85_left_finger_link">
    <visual>
      <geometry>
        <mesh filename="robotiq/visual/robotiq_85_finger_link.obj"/>
      </geometry>
      <material name="Black"/>
    </visual>
    <collision>
      <geometry>
        <mesh filename="robotiq/collision/robotiq_85_finger_link.obj"/>
      </geometry>
    </collision>
    <inertial>
      <mass value="0.027309"/>
      <origin xyz="0.0 0.0 0.0"/>
      <inertia ixx="0.000003" ixy="-0.000002" ixz="0.000000" iyx="-0.000002" iyy="0.000021" iyz="0.000000" izx="0.000000" izy="0.000000" izz="0.000020"/>
    </inertial>
  </link>
  <link name="robotiq_85_right_finger_link">
    <visual>
      <geometry>
        <mesh filename="robotiq/visual/robotiq_85_finger_link.obj"/>
      </geometry>
      <material name="Black"/>
    </visual>
    <collision>
      <geometry>
        <mesh filename="robotiq/collision/robotiq_85_finger_link.obj"/>
      </geometry>
    </collision>
    <inertial>
      <mass value="0.027309"/>
      <origin xyz="0.0 0.0 0.0"/>
      <inertia ixx="0.000003" ixy="-0.000002" ixz="0.000000" iyx="-0.000002" iyy="0.000021" iyz="0.000000" izx="0.000000" izy="0.000000" izz="0.000020"/>
    </inertial>
  </link>
  <joint name="robotiq_85_left_inner_knuckle_joint" type="revolute">
    <parent link="robotiq_85_base_link"/>
    <child link="robotiq_85_left_inner_knuckle_link"/>
    <axis xyz="0 0 1"/>
    <origin rpy="3.14159 0.0 0.0" xyz="0.06142 0.0127 0"/>
    <limit lower="-3.14" upper="3.14" velocity="100.0"/>
  </joint>
  <joint name="robotiq_85_right_inner_knuckle_joint" type="revolute">
    <parent link="robotiq_85_base_link"/>
    <child link="robotiq_85_right_inner_knuckle_link"/>
    <axis xyz="0 0 1"/>
    <origin rpy="0 0 0" xyz="0.06142 -0.0127 0"/>
    <limit lower="-3.14" upper="3.14" velocity="100.0"/>
  </joint>
  <link name="robotiq_85_left_inner_knuckle_link">
    <visual>
      <geometry>
        <mesh filename="robotiq/visual/robotiq_85_inner_knuckle_link.obj"/>
      </geometry>
      <material name="Black"/>
    </visual>
    <collision>
      <geometry>
        <mesh filename="robotiq/collision/robotiq_85_inner_knuckle_link.obj"/>
      </geometry>
    </collision>
    <inertial>
      <mass value="0.029951"/>
      <origin xyz="0.0 0.0 0.0"/>
      <inertia ixx="0.000039" ixy="0.000000" ixz="0.000000" iyx="0.000000" iyy="0.000005" iyz="0.000000" izx="0.000000" izy="0.000000" izz="0.000035"/>
    </inertial>
  </link>
  <link name="robotiq_85_right_inner_knuckle_link">
    <visual>
      <geometry>
        <mesh filename="robotiq/visual/robotiq_85_inner_knuckle_link.obj"/>
      </geometry>
      <material name="Black"/>
    </visual>
    <collision>
      <geometry>
        <mesh filename="robotiq/collision/robotiq_85_inner_knuckle_link.obj"/>
      </geometry>
    </collision>
    <inertial>
      <mass value="0.029951"/>
      <origin xyz="0.0 0.0 0.0"/>
      <inertia ixx="0.000039" ixy="0.000000" ixz="0.000000" iyx="0.000000" iyy="0.000005" iyz="0.000000" izx="0.000000" izy="0.000000" izz="0.000035"/>
    </inertial>
  </link>
  <joint name="robotiq_85_left_finger_tip_joint" type="revolute">
    <parent link="robotiq_85_left_inner_knuckle_link"/>
    <child link="robotiq_85_left_finger_tip_link"/>
    <axis xyz="0 0 1"/>
    <origin rpy="0.0 0.0 0.0" xyz="0.04303959807 -0.03759940821 0.0"/>
    <limit lower="-0.8" upper="0.1" velocity="100.0"/>
  </joint>
  <joint name="robotiq_85_right_finger_tip_joint" type="revolute">
    <parent link="robotiq_85_right_inner_knuckle_link"/>
    <child link="robotiq_85_right_finger_tip_link"/>
    <axis xyz="0 0 1"/>
    <origin rpy="0.0 0.0 0.0" xyz="0.04303959807 -0.03759940821  0.0"/>
    <limit lower="-0.8" upper="0.1" velocity="100.0"/>
  </joint>
  <link name="robotiq_85_left_finger_tip_link">
    <contact>
      <lateral_friction value="2.0"/>
      <spinning_friction value="0.1"/>
    </contact>
    <visual>
      <geometry>
        <mesh filename="robotiq/visual/robotiq_85_finger_tip_link.obj"/>
      </geometry>
      <material name="Gray"/>
    </visual>
    <collision>
      <geometry>
        <mesh filename="robotiq/collision/robotiq_85_finger_tip_link.obj"/>
      </geometry>
    </collision>
    <inertial>
      <mass value="0.019555"/>
      <origin xyz="0.0 0.0 0.0"/>
      <inertia ixx="0.000002" ixy="0.000000" ixz="0.000000" iyx="0.000000" iyy="0.000005" iyz="0.000000" izx="0.000000" izy="0.000000" izz="0.000006"/>
    </inertial>
  </link>
  <link name="robotiq_85_right_finger_tip_link">
    <contact>
      <lateral_friction value="2.0"/>
      <spinning_friction value="0.1"/>
    </contact>
    <visual>
      <geometry>
        <mesh filename="robotiq/visual/robotiq_85_finger_tip_link.obj"/>
      </geometry>
      <material name="Gray"/>
    </visual>
    <collision>
      <geometry>
        <mesh filename="robotiq/collision/robotiq_85_finger_tip_link.obj"/>
      </geometry>
    </collision>
    <inertial>
      <mass value="0.019555"/>
      <origin xyz="0.0 0.0 0.0"/>
      <inertia ixx="0.000002" ixy="0.000000" ixz="0.000000" iyx="0.000000" iyy="0.000005" iyz="0.000000" izx="0.000000" izy="0.000000" izz="0.000006"/>
    </inertial>
  </link>

  <link name="weight">
    <inertial>
      <origin rpy="0 0 0" xyz="0 0 0"/>
       <mass value="1"/>
       <inertia ixx="1" ixy="0" ixz="0" iyy="1" iyz="0" izz="1"/>
    </inertial>
    <visual>
      <origin rpy="0 0 0" xyz="0 0 0"/>
      <geometry>
        <box size="0.05 0.05 0.05" />
      </geometry>
       <material name="red">
        <color rgba="1 0 0 1"/>
      </material>
    </visual>
  </link>
  <joint name="weight_joint" type="fixed">
    <parent link="robotiq_85_base_link"/>
    <child link="weight"/>
    <axis xyz="0 0 1"/>
    <origin rpy="0.0 0.0 0.0" xyz="0.15 0.0 0.0"/>
  </joint>
</robot>

