<?xml version="1.0" ?>
<!-- =================================================================================== -->
<!-- |    This document was autogenerated by xacro from jaco_standalone.urdf.xacro     | -->
<!-- |    EDITING THIS FILE BY HAND IS NOT RECOMMENDED                                 | -->
<!-- =================================================================================== -->
<!--
Software License Agreement (BSD)
\file      vector.urdf.xacro
\authors   Patrick Hussey
\copyright Copyright (c) 2015, Stanley Innovation, Inc., All rights reserved.
Redistribution and use in source and binary forms, with or without modification, are permitted provided that
the following conditions are met:
 * Redistributions of source code must retain the above copyright notice, this list of conditions and the
   following disclaimer.
 * Redistributions in binary form must reproduce the above copyright notice, this list of conditions and the
   following disclaimer in the documentation and/or other materials provided with the distribution.
 * Neither the name of Stanley Innovation nor the names of its contributors may be used to endorse or promote
   products derived from this software without specific prior written permission.
THIS SOFTWARE IS PROVIDED BY THE COPYRIGHT HOLDERS AND CONTRIBUTORS "AS IS" AND ANY EXPRESS OR IMPLIED WAR-
RANTIES, INCLUDING, BUT NOT LIMITED TO, THE IMPLIED WARRANTIES OF MERCHANTABILITY AND FITNESS FOR A PARTICULAR
PURPOSE ARE DISCLAIMED. IN NO EVENT SHALL THE COPYRIGHT HOLDER OR CONTRIBUTORS BE LIABLE FOR ANY DIRECT, IN-
DIRECT, INCIDENTAL, SPECIAL, EXEMPLARY, OR CONSEQUENTIAL DAMAGES (INCLUDING, BUT NOT LIMITED TO, PROCUREMENT
OF SUBSTITUTE GOODS OR SERVICES; LOSS OF USE, DATA, OR PROFITS; OR BUSINESS INTERRUPTION) HOWEVER CAUSED AND
ON ANY THEORY OF LIABILITY, WHETHER IN CONTRACT, STRICT LIABILITY, OR TORT (INCLUDING NEGLIGENCE OR OTHERWISE)
ARISING IN ANY WAY OUT OF THE USE OF THIS SOFTWARE, EVEN IF ADVISED OF THE POSSIBILITY OF SUCH DAMAGE.
-->
<robot name="jaco" xmlns:xacro="http://ros.org/wiki/xacro">
<!--   <link name="world"/>
  <joint name="world_joint" type="fixed">
    <origin rpy="0 0 0" xyz="0 0 0"/>
    <parent link="world"/>
    <child link="right_base_link"/>
  </joint> -->
  <link name="right_base_link">
<!--     <visual>
      <geometry>
        <mesh filename="jaco/visual/base.dae"/>
      </geometry>
    </visual> -->
    <collision>
      <geometry>
        <mesh filename="jaco/base.STL"/>
      </geometry>
    </collision>
    <inertial>
      <mass value="0.752103"/>
      <origin xyz="0 0 0"/>
      <inertia ixx="0.009025" ixy="-0.000002" ixz="-0.000005" iyx="-0.000002" iyy="0.009007" iyz="0.000000" izx="-0.000005" izy="0.000000" izz="0.000704"/>
    </inertial>
  </link>
  <joint name="right_shoulder_pan_joint" type="continuous">
    <parent link="right_base_link"/>
    <child link="right_shoulder_link"/>
    <origin rpy="3.14159 0 3.14159" xyz="0 0 0.15675"/>
    <axis xyz="0 0 1"/>
    <limit effort="1800.0" velocity="0.314"/>
    <dynamics damping="0.0" friction="0.0"/>
  </joint>
  <link name="right_shoulder_link">
<!--     <visual>
      <geometry>
        <mesh filename="jaco/visual/shoulder.dae"/>
      </geometry>
    </visual> -->
    <collision>
      <geometry>
        <mesh filename="jaco/shoulder.STL"/>
      </geometry>
    </collision>
    <inertial>
      <mass value="0.839784"/>
      <origin xyz="0 0 0"/>
      <inertia ixx="0.005735" ixy="0.000000" ixz="0.000000" iyx="0.000000" iyy="0.005801" iyz="0.000496" izx="0.000000" izy="0.000496" izz="0.000570"/>
    </inertial>
  </link>
  <joint name="right_shoulder_lift_joint" type="revolute">
    <parent link="right_shoulder_link"/>
    <child link="right_upper_arm_link"/>
    <!--ZERO CONFIG:<origin xyz="0 0 -0.11875" rpy="${M_PI/2} ${M_PI/2} 0" />-->
    <origin rpy="1.570795 -1.570795 0" xyz="0 0 -0.11875"/>
    <axis xyz="0 0 1"/>
    <!--ZERO CONFIG:<limit lower="-2.238" upper="2.238" effort="3000.5" velocity="0.314"/>-->
    <limit effort="3000.5" lower="0.90359" upper="5.37959" velocity="0.314"/>
    <dynamics damping="0.0" friction="0.0"/>
  </joint>
  <link name="right_upper_arm_link">
<!--     <visual>
      <geometry>
        <mesh filename="jaco/visual/upper_arm.dae"/>
      </geometry>
    </visual> -->
    <collision>
      <geometry>
        <mesh filename="jaco/collision/upper_arm.stl"/>
      </geometry>
    </collision>
    <inertial>
      <mass value="0.968862"/>
      <origin xyz="0 0 0"/>
      <inertia ixx="0.000789" ixy="0.000008" ixz="-0.002914" iyx="0.000008" iyy="0.069034" iyz="-0.000001" izx="-0.002914" izy="-0.000001" izz="0.069005"/>
    </inertial>
  </link>
  <joint name="right_elbow_joint" type="revolute">
    <parent link="right_upper_arm_link"/>
    <child link="right_forearm_link"/>
    <!--ZERO CONFIG:<origin xyz="0.41 0 0.00975" rpy=" 0 ${M_PI} ${M_PI}" />-->
    <origin rpy="0 3.14159 0" xyz="0.41 0 0.00975"/>
    <axis xyz="0 0 1"/>
    <!--ZERO CONFIG:<limit lower="-2.809" upper="2.809" effort="1800.0" velocity="0.314"/>-->
    <limit effort="1800.0" lower="0.33259" upper="5.95059" velocity="0.314"/>
    <dynamics damping="0.0" friction="0.0"/>
  </joint>
  <link name="right_forearm_link">
<!--     <visual>
      <geometry>
        <mesh filename="jaco/visual/forearm.dae"/>
      </geometry>
    </visual> -->
    <collision>
      <geometry>
        <mesh filename="jaco/collision/forearm.stl"/>
      </geometry>
    </collision>
    <inertial>
      <mass value="0.70996"/>
      <origin xyz="0 0 0"/>
      <inertia ixx="0.000341" ixy="0.000003" ixz="-0.000034" iyx="0.000003" iyy="0.008491" iyz="-0.000000" izx="-0.000034" izy="0.000000" izz="0.008612"/>
    </inertial>
  </link>
  <joint name="right_wrist_1_joint" type="continuous">
    <parent link="right_forearm_link"/>
    <child link="right_wrist_1_link"/>
    <origin rpy="0 -1.570795 0" xyz="0.20725 0 0 "/>
    <axis xyz="0 0 1"/>
    <limit effort="600.8" velocity="0.785"/>
    <dynamics damping="0.0" friction="0.0"/>
  </joint>
  <link name="right_wrist_1_link">
<!--     <visual>
      <geometry>
        <mesh filename="jaco/visual/wrist_1.dae"/>
      </geometry>
    </visual> -->
    <collision>
      <geometry>
        <mesh filename="jaco/collision/wrist_1.stl"/>
      </geometry>
    </collision>
    <inertial>
      <mass value="0.441232"/>
      <origin xyz="0 0 0"/>
      <inertia ixx="0.000924" ixy="0.000000" ixz="-0.000294" iyx="0.000000" iyy="0.001034" iyz="0.000000" izx="-0.000294" izy="0.000000" izz="0.000312"/>
    </inertial>
  </link>
  <joint name="right_wrist_2_joint" type="continuous">
    <parent link="right_wrist_1_link"/>
    <child link="right_wrist_2_link"/>
    <origin rpy="0 1.04719666667 3.14159" xyz="0 0 -0.04275704"/>
    <axis xyz="0 0 1"/>
    <limit effort="600.8" velocity="0.785"/>
    <dynamics damping="0.0" friction="0.0"/>
  </joint>
  <link name="right_wrist_2_link">
<!--     <visual>
      <geometry>
        <mesh filename="jaco/visual/wrist_2.dae"/>
      </geometry>
    </visual> -->
    <collision>
      <geometry>
        <mesh filename="jaco/collision/wrist_2.stl"/>
      </geometry>
    </collision>
    <inertial>
      <mass value="0.441232"/>
      <origin xyz="0 0 0"/>
      <inertia ixx="0.003063" ixy="0.000000" ixz="-0.000522" iyx="0.000000" iyy="0.003174" iyz="-0.000001" izx="-0.000522" izy="-0.000001" izz="0.000312"/>
    </inertial>
  </link>
  <joint name="right_wrist_3_joint" type="continuous">
    <parent link="right_wrist_2_link"/>
    <child link="right_wrist_3_link"/>
    <origin rpy="0 -1.04719666667 0" xyz="0 0 -0.08551408"/>
    <axis xyz="0 0 1"/>
    <limit effort="600.8" velocity="0.785"/>
    <dynamics damping="0.0" friction="0.0"/>
  </joint>
  <link name="right_wrist_3_link">
<!--     <visual>
      <geometry>
        <mesh filename="jaco/visual/wrist_3.dae"/>
      </geometry>
    </visual> -->
    <collision>
      <geometry>
        <mesh filename="jaco/collision/wrist_3.stl"/>
      </geometry>
    </collision>
    <inertial>
      <mass value="0.36329"/>
      <origin xyz="0 0 0"/>
      <inertia ixx="0.001908" ixy="0.000000" ixz="0.000000" iyx="0.000000" iyy="0.001907" iyz="0.000000" izx="0.000000" izy="0.000001" izz="0.000209"/>
    </inertial>
  </link>
  <joint name="right_ee_fixed_joint" type="fixed">
    <parent link="right_wrist_3_link"/>
    <child link="right_ee_base"/>
    <origin rpy="3.14159 1.570795 0" xyz="0 0 -0.09380704"/>
    <!--0.09380704156-->
  </joint>
  <link name="right_ee_base"/>
  <!-- Add in an EEF link for the center of the gripper -->
<!--   <joint name="right_ee_gripper" type="fixed">
    <parent link="right_ee_base"/>
    <child link="right_ee_link"/>
    <origin xyz="0.13 0 0"/>
  </joint> -->
  <!-- <link name="right_ee_link"/> -->
  <transmission name="right_shoulder_pan_trans">
    <type>transmission_interface/SimpleTransmission</type>
    <joint name="right_shoulder_pan_joint">
      <hardwareInterface>hardware_interface/PositionJointInterface</hardwareInterface>
    </joint>
    <actuator name="right_shoulder_pan_motor">
      <mechanicalReduction>1</mechanicalReduction>
    </actuator>
  </transmission>
  <transmission name="right_shoulder_lift_trans">
    <type>transmission_interface/SimpleTransmission</type>
    <joint name="right_shoulder_lift_joint">
      <hardwareInterface>hardware_interface/PositionJointInterface</hardwareInterface>
    </joint>
    <actuator name="right_shoulder_lift_motor">
      <mechanicalReduction>1</mechanicalReduction>
    </actuator>
  </transmission>
  <transmission name="right_elbow_trans">
    <type>transmission_interface/SimpleTransmission</type>
    <joint name="right_elbow_joint">
      <hardwareInterface>hardware_interface/PositionJointInterface</hardwareInterface>
    </joint>
    <actuator name="right_elbow_motor">
      <mechanicalReduction>1</mechanicalReduction>
    </actuator>
  </transmission>
  <transmission name="right_wrist_1_trans">
    <type>transmission_interface/SimpleTransmission</type>
    <joint name="right_wrist_1_joint">
      <hardwareInterface>hardware_interface/PositionJointInterface</hardwareInterface>
    </joint>
    <actuator name="right_wrist_1_motor">
      <mechanicalReduction>1</mechanicalReduction>
    </actuator>
  </transmission>
  <transmission name="right_wrist_2_trans">
    <type>transmission_interface/SimpleTransmission</type>
    <joint name="right_wrist_2_joint">
      <hardwareInterface>hardware_interface/PositionJointInterface</hardwareInterface>
    </joint>
    <actuator name="right_wrist_2_motor">
      <mechanicalReduction>1</mechanicalReduction>
    </actuator>
  </transmission>
  <transmission name="right_wrist_3_trans">
    <type>transmission_interface/SimpleTransmission</type>
    <joint name="right_wrist_3_joint">
      <hardwareInterface>hardware_interface/PositionJointInterface</hardwareInterface>
    </joint>
    <actuator name="right_wrist_3_motor">
      <mechanicalReduction>1</mechanicalReduction>
    </actuator>
  </transmission>
</robot>

