<?xml version="1.0" ?>
<robot name="drawer">
  <!-- Cabinet -->
  <link name="cabinet_link">
    <contact>
      <friction_anchor/>
      <lateral_friction value="10.0"/> <!--  lateral friction for stability -->
      <rolling_friction value="10.01"/> <!--  rolling friction for stability -->
    </contact>
    <inertial>
       <origin rpy="0 0 0" xyz="0 0 0"/>
       <mass value="10.1"/>
            <inertia ixx="0.0" ixy="0.0" ixz="0.0" iyy="0.0" iyz="0.0" izz="0.0" />
    </inertial>
    <visual>
      <geometry>
        <mesh filename="./cabinet/cabinet.obj" scale="1.3 1.3 1.3"/>
      </geometry>
    </visual>
    <collision>
      <geometry>
    	 	<mesh filename="./cabinet/cabinet.obj" scale="1.3 1.3 1.3"/>
      </geometry>
    </collision>
  </link>


  <!-- Drawer  -->
  <link name="drawer_link">
    <contact>
      <friction_anchor/>
      <lateral_friction value="2.5"/> <!--  lateral friction for stability -->
      <rolling_friction value="2.5"/> <!--  rolling friction for stability -->
    </contact>
    <inertial>
       <origin rpy="0 0 0" xyz="0 0 0"/>
       <mass value="1.1"/>
            <inertia ixx="0.0" ixy="0.0" ixz="0.0" iyy="0.0" iyz="0.0" izz="0.0" />
    </inertial>
    <visual>
      <geometry>
        <mesh filename="./drawer/drawerhandle.obj" scale="1 0.95 1"/>
      </geometry>
    </visual>
    <collision>
      <geometry>
    	 	<mesh filename="./drawer/drawerhandle.obj" scale="1 0.95 1"/>
      </geometry>
    </collision>
  </link>
 
  <joint name="drawer_joint" type="prismatic">
    <parent link="cabinet_link"/>
    <child link="drawer_link"/>
    <origin xyz="0 0 0" rpy="0 0 0"/>
    <axis xyz="1 0 0"/>
        <dynamics damping="0" friction="0" />
        <limit lower="-0.4" upper="0.4" effort="0" velocity="2.16"/>
  </joint>


    <joint name="handle_joint" type="fixed">
    <parent link="drawer_link"/>
    <child link="handle"/>
    <origin rpy="0 0 0" xyz="-0.18 0.0 0"/>
  </joint>
  <link name="handle">
    <visual>
      <origin rpy="0 0 0" xyz="0 0.0 0"/>
      <geometry>
        <sphere radius="0.01"/>
      </geometry>
    <material name="green">
        <color rgba="0.0 1 0.0 1.0"/>
    </material>
    </visual>
  </link>
  
</robot>


