<?xml version="1.0" ?>
<robot name="nico_upper_rh6d">
	<link name="world" />
	<link name="torso">
		<visual>
			<geometry>
				<mesh filename="mesh/torso.stl"/>
			</geometry>
			<origin rpy="0 0 0" xyz="0.0 0.0 0.0"/>
			<material name="torso_color">
				<color rgba="0.270588 0.270588 0.270588 1"/>
			</material>
		</visual>
	</link>
	<joint name="world_to_base_link" type="fixed">
    	<parent link="world"/>
    	<child link="torso"/>
  	</joint>
    <link name="neck">
		<visual>
			<geometry>
				<mesh filename="mesh/neck.stl"/>
			</geometry>
			<origin rpy="0 0 0" xyz="0.0 0.0 0.0"/>
			<material name="neck_color">
				<color rgba="0.74902 0.74902 0.74902 1"/>
			</material>
		</visual>
		<collision>
			<geometry>
				<mesh filename="mesh/neck.stl"/>
			</geometry>
			<origin rpy="0 0 0" xyz="0.0 0.0 0.0"/>
		</collision>
		<inertial>
			<mass value="0.090439"/>
			<inertia ixx="0.00006" ixy="-0" ixz="-0" iyy="0.000056" iyz="-0.000001" izz="0.000019"/>
			<origin rpy="0 0 0" xyz="0 0.000266 0.050352"/>
		</inertial>
	</link>
	<joint name="head_z_rjoint" type="revolute">
		<parent link="torso"/>
		<child link="neck"/>
		<origin rpy="0 0 0" xyz="-0.02 0.0 0.23"/>
		<axis xyz="0 0 1"/>
		<limit effort="30" lower="-3.124" upper="3.142" velocity="1"/>
	</joint>
	<link name="head">
		<visual>
			<geometry>
				<mesh filename="mesh/head.stl"/>
			</geometry>
			<origin rpy="0 0 0" xyz="0 0 0"/>
			<material name="head_color">
				<color rgba="0.74902 0.74902 0.74902 1"/>
			</material>
		</visual>
		<collision>
			<geometry>
				<mesh filename="mesh/head.stl"/>
			</geometry>
			<origin rpy="0 0 0" xyz="0 0 0"/>
		</collision>
		<inertial>
			<mass value="0.294137"/>
			<inertia ixx="0.001424" ixy="-0" ixz="0.000083" iyy="0.00159" iyz="-0.000002" izz="0.001485"/>
			<origin rpy="0 0 0" xyz="0.01525 -0.023771 0.09423"/>
		</inertial>
	</link>
	<joint name="head_y_rjoint" type="revolute">
		<parent link="neck"/>
		<child link="head"/>
		<origin rpy="0 0 0" xyz="0 0.0 0.10"/>
		<axis xyz="0 1 0"/>
		<limit effort="30" lower="-1.553" upper="1.379" velocity="1"/>
	</joint>
	<link name="right_shoulder">
		<visual>
			<geometry>
				<mesh filename="mesh/right_shoulder.stl"/>
			</geometry>
			<origin rpy="0 0 0" xyz="0 0 0"/>
			<material name="right_shoulder_color">
				<color rgba="0.176471 0.176471 0.176471 1"/>
			</material>
		</visual>
		<collision>
			<geometry>
				<mesh filename="mesh/right_shoulder.stl"/>
			</geometry>
			<origin rpy="0 0 0" xyz="0 0 0"/>
		</collision>
		<inertial>
			<mass value="0.084038"/>
			<inertia ixx="0.000026" ixy="-0.000001" ixz="-0.000002" iyy="0.000034" iyz="-0" izz="0.000033"/>
			<origin rpy="0 0 0" xyz="0.005637 0.000876 0.033153"/>
		</inertial>
	</link>
	<joint name="r_shoulder_z_rjoint" type="revolute">
		<parent link="torso"/>
		<child link="right_shoulder"/>
		<origin rpy="0 0 0" xyz="0.0 -0.045 0.23"/>
		<axis xyz="0 0 1"/>
		<limit effort="30" lower="-1.745" upper="2.182" velocity="1"/>
	</joint>
	<link name="right_collarbone">
		<visual>
			<geometry>
				<mesh filename="mesh/right_collar.stl"/>
			</geometry>
			<origin rpy="0 0 0" xyz="0 0 0"/>
			<material name="right_collarbone_color">
				<color rgba="0.176471 0.176471 0.176471 1"/>
			</material>
		</visual>
		<collision>
			<geometry>
				<mesh filename="mesh/right_collar.stl"/>
			</geometry>
			<origin rpy="0 0 0" xyz="0 0 0"/>
		</collision>
		<inertial>
			<mass value="0.024811"/>
			<inertia ixx="0.000014" ixy="-0" ixz="0" iyy="0.000011" iyz="-0.000001" izz="0.000019"/>
			<origin rpy="0 0 0" xyz="-0 -0.041345 -0.002364"/>
		</inertial>
	</link>
	<joint name="r_shoulder_y_rjoint" type="revolute">
		<parent link="right_shoulder"/>
		<child link="right_collarbone"/>
		<origin rpy="0 0 0" xyz="-0.021 -0.023 0.033"/>
		<axis xyz="0 -1 0"/>
		<limit effort="30" lower="-3.142" upper="3.124" velocity="1"/>
	</joint>
	<link name="right_upper_arm">
		<visual>
			<geometry>
				<mesh filename="mesh/right_upper_arm.stl"/>
			</geometry>
			<origin rpy="0 0 0" xyz="0 0 0"/>
			<material name="right_upper_arm_color">
				<color rgba="0.176471 0.176471 0.176471 1"/>
			</material>
		</visual>
		<collision>
			<geometry>
				<mesh filename="mesh/right_upper_arm.stl"/>
			</geometry>
			<origin rpy="0 0 0" xyz="0 0 0"/>
		</collision>
		<inertial>
			<mass value="0.189729"/>
			<inertia ixx="0.000851" ixy="0" ixz="0" iyy="0.000851" iyz="-0.000005" izz="0.000048"/>
			<origin rpy="0 0 0" xyz="-0.02306 -0.000321 -0.0866"/>
		</inertial>
	</link>
	<joint name="r_upperarm_x_rjoint" type="revolute">
		<parent link="right_collarbone"/>
		<child link="right_upper_arm"/>
		<origin rpy="0 0 0" xyz="0.00 -0.073 -0.023"/>
		<axis xyz="1 0 0"/>
		<limit effort="30" lower="-3.002" upper="1.8675" velocity="1"/>
	</joint>
	<link name="right_lower_arm">
		<visual>
			<geometry>
				<mesh filename="mesh/right_lower_arm.stl"/>
			</geometry>
			<origin rpy="0 0 0" xyz="0 0 0"/>
			<material name="right_lower_arm_color">
				<color rgba="0.176471 0.176471 0.176471 1"/>
			</material>
		</visual>
		<collision>
			<geometry>
				<mesh filename="mesh/right_lower_arm.stl"/>
			</geometry>
			<origin rpy="0 0 0" xyz="0 0 0"/>
		</collision>
		<inertial>
			<mass value="0.076793"/>
			<inertia ixx="0.000104" ixy="-0" ixz="-0" iyy="0.000095" iyz="-0.000002" izz="0.000021"/>
			<origin rpy="0 0 0" xyz="0 0.022485 -0.081055"/>
		</inertial>
	</link>
	<joint name="r_elbow_y_rjoint" type="revolute">
		<parent link="right_upper_arm"/>
		<child link="right_lower_arm"/>
		<origin rpy="0 0 0" xyz="0.0 0 -0.17"/>
		<axis xyz="0 1 0"/>
		<limit effort="30" lower="-1.745" upper="1.745" velocity="1"/>
	</joint>
	<link name="right_wrist:11">
		<visual>
			<geometry>
				<mesh filename="meshes/rh6d_shell_simple.stl" scale="0.001 0.001 0.001"/>
			</geometry>
			<origin rpy="1.571 0 1.571" xyz="-0.000319 0.006617 -0.050181"/>
			<material name="right_wrist:11_color">
				<color rgba="0.74902 0.74902 0.74902 1"/>
			</material>
		</visual>
		<collision>
			<geometry>
				<mesh filename="meshes/rh6d_shell_simple.stl" scale="0.001 0.001 0.001"/>
			</geometry>
			<origin rpy="1.571 0 1.571" xyz="-0.000319 0.006617 -0.050181"/>
		</collision>
		<inertial>
			<mass value="0.028397"/>
			<inertia ixx="0.000043" ixy="-0" ixz="0.000004" iyy="0.000058" iyz="-0.000007" izz="0.000029"/>
			<origin rpy="0 0 0" xyz="0.000031 -0.011056 -0.0675"/>
		</inertial>
	</link>
	<joint name="r_wrist_z_rjoint" type="revolute">
		<parent link="right_lower_arm"/>
		<child link="right_wrist:11"/>
		<origin rpy="0 0 0.028946" xyz="0 0.0102 -0.12605"/>
		<axis xyz="0 0 1"/>
		<limit effort="30" lower="-1.571" upper="1.571" velocity="1"/>
	</joint>
	<link name="gripper"> <!--gripper-->
		<visual>
			<geometry>
				<mesh filename="meshes/rh6d_palm_simple.stl" scale="0.001 0.001 0.001"/>
			</geometry>
			<origin rpy="1.571 0 3.1415" xyz="-0.022933 0.012906 -0.045"/>
			<material name="gripper_color">
				<color rgba="0.74902 0.74902 0.74902 1"/>
			</material>
		</visual>
		<collision>
			<geometry>
				<mesh filename="meshes/right_palm_simple.stl" scale="0.001 0.001 0.001"/>
			</geometry>
			<origin rpy="1.571 0 3.1415" xyz="-0.022933 0.012906 -0.05"/>
		</collision>
		<inertial>
			<mass value="0.005332"/>
			<inertia ixx="0.000015" ixy="0.000001" ixz="-0.000004" iyy="0.000017" iyz="0.000004" izz="0.000006"/>
			<origin rpy="0 0 0" xyz="-0.029511 0.002253 -0.023968"/>
		</inertial>
	</link>
	<joint name="r_wrist_x_rjoint" type="revolute">
		<parent link="right_wrist:11"/>
		<child link="gripper"/>
		<origin rpy="-0.433097 0 0" xyz="0.023416 0.006052 -0.070337"/>
		<axis xyz="1 0 0"/>
		<limit effort="30" lower="0" upper="0.872665" velocity="1"/>
	</joint>
	<link name="endeffector">
    	<visual>
      		<origin rpy="0 0 0" xyz="0 0.0 0.0"/>
      		<geometry>
        		<sphere radius="0.005"/>
      		</geometry>
    	</visual>
  	</link>
	<joint name="endeffector_joint" type="fixed">
    	<parent link="gripper"/>
    	<child link="endeffector"/>
    	<origin rpy="0 0 0" xyz="-0.025 0.00 -0.14"/>
	</joint>
	
	<link name="left_shoulder:11">
		<visual>
			<geometry>
				<mesh filename="meshes/left_shoulder_simple.stl" scale="0.001 0.001 0.001"/>
			</geometry>
			<origin rpy="0 0 0" xyz="0.014919 0.097299 -0.01461"/>
			<material name="left_shoulder:11_color">
				<color rgba="0.176471 0.176471 0.176471 1"/>
			</material>
		</visual>
		<collision>
			<geometry>
				<mesh filename="meshes/left_shoulder_simple.stl" scale="0.001 0.001 0.001"/>
			</geometry>
			<origin rpy="0 0 0" xyz="0.014919 0.097299 -0.01461"/>
		</collision>
		<inertial>
			<mass value="0.084038"/>
			<inertia ixx="0.000026" ixy="-0.000001" ixz="-0.000002" iyy="0.000034" iyz="-0" izz="0.000033"/>
			<origin rpy="0 0 0" xyz="0.005702 0.000175 0.033153"/>
		</inertial>
	</link>
	<joint name="l_shoulder_z" type="fixed">
		<parent link="torso"/>
		<child link="left_shoulder:11"/>
		<origin rpy="0 0 0.019617" xyz="0.0 0.045 0.23"/>
		<axis xyz="0 0 1"/>
		<limit effort="30" lower="-2.182" upper="1.745" velocity="1"/>
	</joint>
	<link name="left_collarbone:11">
		<visual>
			<geometry>
				<mesh filename="meshes/left_upper_arm_simple.stl" scale="0.001 0.001 0.001"/>
			</geometry>
			<origin rpy="0 0 0" xyz="-0.00032 -0.000277 0.000298"/>
			<material name="left_collarbone:11_color">
				<color rgba="0.176471 0.176471 0.176471 1"/>
			</material>
		</visual>
		<collision>
			<geometry>
				<mesh filename="meshes/left_upper_arm_simple.stl" scale="0.001 0.001 0.001"/>
			</geometry>
			<origin rpy="0 0 0" xyz="-0.00032 -0.000277 0.000298"/>
		</collision>
		<inertial>
			<mass value="0.024811"/>
			<inertia ixx="0.000014" ixy="0" ixz="0" iyy="0.000011" iyz="0.000001" izz="0.000019"/>
			<origin rpy="0 0 0" xyz="-0 0.041345 -0.002364"/>
		</inertial>
	</link>
	<joint name="l_shoulder_y" type="fixed">
		<parent link="left_shoulder:11"/>
		<child link="left_collarbone:11"/>
		<origin rpy="0 -0.00445 -0.019538" xyz="0.022445 0.022567 0.037"/>
		<axis xyz="0 1 0"/>
		<limit effort="30" lower="-3.124" upper="3.142" velocity="1"/>
	</joint>
	<link name="left_upper_arm:11">
		<visual>
			<geometry>
				<mesh filename="meshes/left_lower_arm_simple.stl" scale="0.001 0.001 0.001"/>
			</geometry>
			<origin rpy="0 0 0" xyz="-0.044837 -0.009349 -0.161585"/>
			<material name="left_upper_arm:11_color">
				<color rgba="0.176471 0.176471 0.176471 1"/>
			</material>
		</visual>
		<inertial>
			<mass value="0.192388"/>
			<inertia ixx="0.00085" ixy="0" ixz="-0.00005" iyy="0.000853" iyz="0.000001" izz="0.000052"/>
			<origin rpy="0 0 0" xyz="-0.028636 -0.000703 -0.084224"/>
		</inertial>
	</link>
	<joint name="l_arm_x" type="fixed">
		<parent link="left_collarbone:11"/>
		<child link="left_upper_arm:11"/>
		<origin rpy="0.000683 -0.051282 -0.000035" xyz="0.0245 0.073663 -0.022853"/>
		<axis xyz="1 0 0"/>
		<limit effort="30" lower="-1.8675" upper="3.002" velocity="1"/>
	</joint>
	<link name="left_lower_arm:11">
		<visual>
			<geometry>
				<mesh filename="meshes/left_lowerarm_simple.stl" scale="0.001 0.001 0.001"/>
			</geometry>
			<origin rpy="0 0 0" xyz="0.000017 -0.010775 -0.12546"/>
			<material name="left_lower_arm:11_color">
				<color rgba="0.176471 0.176471 0.176471 1"/>
			</material>
		</visual>
		<inertial>
			<mass value="0.076791"/>
			<inertia ixx="0.000104" ixy="-0" ixz="-0" iyy="0.000095" iyz="0.000002" izz="0.000021"/>
			<origin rpy="0 0 0" xyz="0 -0.022485 -0.081055"/>
		</inertial>
	</link>
	<joint name="l_elbow_y" type="fixed">
		<parent link="left_upper_arm:11"/>
		<child link="left_lower_arm:11"/>
		<origin rpy="0 -1.405976 0" xyz="-0.034583 0.023066 -0.169859"/>
		<axis xyz="0 -1 0"/>
		<limit effort="30" lower="1.545" upper="1.745" velocity="1"/>
	</joint>
	<link name="left_wrist:11">
		<visual>
			<geometry>
				<mesh filename="meshes/left_wrist_simple.stl" scale="0.001 0.001 0.001"/>
			</geometry>
			<origin rpy="0 0 0" xyz="-0.000319 0.006617 0.070682"/>
			<material name="left_wrist:11_color">
				<color rgba="0.74902 0.74902 0.74902 1"/>
			</material>
		</visual>
		<collision>
			<geometry>
				<mesh filename="meshes/left_wrist_simple.stl" scale="0.001 0.001 0.001"/>
			</geometry>
			<origin rpy="0 0 0" xyz="-0.000319 0.006617 0.070682"/>
		</collision>
		<inertial>
			<mass value="0.028361"/>
			<inertia ixx="0.000038" ixy="-0" ixz="-0" iyy="0.000039" iyz="0.000007" izz="0.000015"/>
			<origin rpy="0 0 0" xyz="0.00007 -0.011053 0.067769"/>
		</inertial>
	</link>
	<joint name="l_wrist_z" type="fixed">
		<parent link="left_lower_arm:11"/>
		<child link="left_wrist:11"/>
		<origin rpy="3.141593 0 0.028703" xyz="0 -0.010201 -0.12555"/>
		<axis xyz="0 0 -1"/>
		<limit effort="30" lower="-1.571" upper="1.571" velocity="1"/>
	</joint>
	<link name="left_palm:11">
		<visual>
			<geometry>
				<mesh filename="meshes/left_palm_simple.stl" scale="0.001 0.001 0.001"/>
			</geometry>
			<origin rpy="0 0 0" xyz="-0.023233 0.001906 0.017234"/>
			<material name="left_palm:11_color">
				<color rgba="0.74902 0.74902 0.74902 1"/>
			</material>
		</visual>
		<collision>
			<geometry>
				<mesh filename="meshes/left_palm_simple.stl" scale="0.001 0.001 0.001"/>
			</geometry>
			<origin rpy="0 0 0" xyz="-0.023233 0.001906 0.017234"/>
		</collision>
		<inertial>
			<mass value="0.005222"/>
			<inertia ixx="0.000001" ixy="0" ixz="-0" iyy="0.000002" iyz="-0" izz="0.000002"/>
			<origin rpy="0 0 0" xyz="-0.027199 0.000117 0.017191"/>
		</inertial>
	</link>
	<joint name="l_wrist_x" type="fixed">
		<parent link="left_wrist:11"/>
		<child link="left_palm:11"/>
		<origin rpy="0.460941 0 0" xyz="0.023416 0.006052 0.070837"/>
		<axis xyz="1 0 0"/>
		<limit effort="30" lower="-0.872665" upper="0" velocity="1"/>
	</joint>
	<link name="finger_segment:24">
		<visual>
			<geometry>
				<mesh filename="meshes/finger_segment_ipt_50d2a7f4.STL" scale="0.001 0.001 0.001"/>
			</geometry>
			<origin rpy="0 0 0" xyz="-0.015691 -0.015508 -0.007416"/>
			<material name="finger_segment:24_color">
				<color rgba="0.74902 0.74902 0.74902 1"/>
			</material>
		</visual>
		<collision>
			<geometry>
				<mesh filename="meshes/finger_segment_ipt_50d2a7f4.STL" scale="0.001 0.001 0.001"/>
			</geometry>
			<origin rpy="0 0 0" xyz="-0.015691 -0.015508 -0.007416"/>
		</collision>
		<inertial>
			<mass value="0.000009"/>
			<inertia ixx="0" ixy="0" ixz="-0" iyy="0" iyz="0" izz="0"/>
			<origin rpy="0 0 0" xyz="-0.004101 0.000556 -0.005752"/>
		</inertial>
	</link>
	<joint name="l_thumb_x" type="fixed">
		<parent link="left_palm:11"/>
		<child link="finger_segment:24"/>
		<origin rpy="-1.130534 0 -3.141593" xyz="-0.028 0.0199 0.00842"/>
		<axis xyz="1 0 0"/>
		<limit effort="30" lower="-1.309" upper="0" velocity="1"/>
	</joint>
	<link name="finger_segment:14">
		<visual>
			<geometry>
				<mesh filename="meshes/finger_segment_ipt_50d2a7f4.STL" scale="0.001 0.001 0.001"/>
			</geometry>
			<origin rpy="0 0 0" xyz="-0.006181 -0.015507 -0.007417"/>
			<material name="finger_segment:14_color">
				<color rgba="0.74902 0.74902 0.74902 1"/>
			</material>
		</visual>
		<collision>
			<geometry>
				<mesh filename="meshes/finger_segment_ipt_50d2a7f4.STL" scale="0.001 0.001 0.001"/>
			</geometry>
			<origin rpy="0 0 0" xyz="-0.006181 -0.015507 -0.007417"/>
		</collision>
		<inertial>
			<mass value="0.000009"/>
			<inertia ixx="0" ixy="0" ixz="-0" iyy="0" iyz="0" izz="0"/>
			<origin rpy="0 0 0" xyz="0.005409 0.000556 -0.005751"/>
		</inertial>
	</link>
	<joint name="l_thumb_1st_x" type="fixed">
		<parent link="finger_segment:24"/>
		<child link="finger_segment:14"/>
		<origin rpy="-0.095246 0 0" xyz="-0.00951 0 -0.016"/>
		<axis xyz="1 0 0"/>
		<limit effort="30" lower="-1.309" upper="0" velocity="1"/>
	</joint>
	<link name="fingertip:14">
		<visual>
			<geometry>
				<mesh filename="meshes/fingertip_ipt_8417b8a9.STL" scale="0.001 0.001 0.001"/>
			</geometry>
			<origin rpy="0 0 0" xyz="0.005514 0.000374 -0.010171"/>
			<material name="fingertip:14_color">
				<color rgba="0.74902 0.74902 0.74902 1"/>
			</material>
		</visual>
		<collision>
			<geometry>
				<mesh filename="meshes/fingertip_ipt_8417b8a9.STL" scale="0.001 0.001 0.001"/>
			</geometry>
			<origin rpy="0 0 0" xyz="0.005514 0.000374 -0.010171"/>
		</collision>
		<inertial>
			<mass value="0.000008"/>
			<inertia ixx="0" ixy="-0" ixz="-0" iyy="0" iyz="-0" izz="0"/>
			<origin rpy="0 0 0" xyz="0.005013 0.000408 -0.010216"/>
		</inertial>
	</link>
	<joint name="l_thumb_2nd_x" type="fixed">
		<parent link="finger_segment:14"/>
		<child link="fingertip:14"/>
		<origin rpy="-0.109614 0 0" xyz="0 -0 -0.016"/>
		<axis xyz="1 0 0"/>
		<limit effort="30" lower="-1.309" upper="0" velocity="1"/>
	</joint>
	<link name="finger_segment:25">
		<visual>
			<geometry>
				<mesh filename="meshes/finger_segment_ipt_50d2a7f4.STL" scale="0.001 0.001 0.001"/>
			</geometry>
			<origin rpy="0 0 0" xyz="-0.015691 -0.015506 -0.007417"/>
			<material name="finger_segment:25_color">
				<color rgba="0.74902 0.74902 0.74902 1"/>
			</material>
		</visual>
		<collision>
			<geometry>
				<mesh filename="meshes/finger_segment_ipt_50d2a7f4.STL" scale="0.001 0.001 0.001"/>
			</geometry>
			<origin rpy="0 0 0" xyz="-0.015691 -0.015506 -0.007417"/>
		</collision>
		<inertial>
			<mass value="0.000009"/>
			<inertia ixx="0" ixy="0" ixz="-0" iyy="0" iyz="0" izz="0"/>
			<origin rpy="0 0 0" xyz="-0.004101 0.000556 -0.005752"/>
		</inertial>
	</link>
	<joint name="l_indexfingers_x" type="fixed">
		<parent link="left_palm:11"/>
		<child link="finger_segment:25"/>
		<origin rpy="2.492946 0.062904 0" xyz="-0.001439 0.006226 0.040004"/>
		<axis xyz="0.99794 -0.0170003 -0.0618655"/>
		<limit effort="30" lower="-1.309" upper="0" velocity="1"/>
	</joint>
	<link name="finger_segment:15">
		<visual>
			<geometry>
				<mesh filename="meshes/finger_segment_ipt_50d2a7f4.STL" scale="0.001 0.001 0.001"/>
			</geometry>
			<origin rpy="0 0 0" xyz="-0.006181 -0.015507 -0.007416"/>
			<material name="finger_segment:15_color">
				<color rgba="0.74902 0.74902 0.74902 1"/>
			</material>
		</visual>
		<collision>
			<geometry>
				<mesh filename="meshes/finger_segment_ipt_50d2a7f4.STL" scale="0.001 0.001 0.001"/>
			</geometry>
			<origin rpy="0 0 0" xyz="-0.006181 -0.015507 -0.007416"/>
		</collision>
		<inertial>
			<mass value="0.000009"/>
			<inertia ixx="0" ixy="0" ixz="-0" iyy="0" iyz="0" izz="0"/>
			<origin rpy="0 0 0" xyz="0.005409 0.000556 -0.005751"/>
		</inertial>
	</link>
	<joint name="l_indexfinger_1st_x" type="fixed">
		<parent link="finger_segment:25"/>
		<child link="finger_segment:15"/>
		<origin rpy="-0.095245 0 0" xyz="-0.00951 0 -0.016"/>
		<axis xyz="0.99794 -0.0170003 -0.0618655"/>
		<limit effort="30" lower="-1.309" upper="0" velocity="1"/>
	</joint>
	<link name="fingertip:15">
		<visual>
			<geometry>
				<mesh filename="meshes/fingertip_ipt_8417b8a9.STL" scale="0.001 0.001 0.001"/>
			</geometry>
			<origin rpy="0 0 0" xyz="0.005514 0.000374 -0.010171"/>
			<material name="fingertip:15_color">
				<color rgba="0.74902 0.74902 0.74902 1"/>
			</material>
		</visual>
		<collision>
			<geometry>
				<mesh filename="meshes/fingertip_ipt_8417b8a9.STL" scale="0.001 0.001 0.001"/>
			</geometry>
			<origin rpy="0 0 0" xyz="0.005514 0.000374 -0.010171"/>
		</collision>
		<inertial>
			<mass value="0.000008"/>
			<inertia ixx="0" ixy="-0" ixz="-0" iyy="0" iyz="-0" izz="0"/>
			<origin rpy="0 0 0" xyz="0.005013 0.000408 -0.010216"/>
		</inertial>
	</link>
	<joint name="l_indexfinger_2nd_x" type="fixed">
		<parent link="finger_segment:15"/>
		<child link="fingertip:15"/>
		<origin rpy="-0.109614 0 0" xyz="0 -0 -0.016"/>
		<axis xyz="0.99794 -0.0170003 -0.0618655"/>
		<limit effort="30" lower="-1.309" upper="0" velocity="1"/>
	</joint>
	<link name="finger_segment:26">
		<visual>
			<geometry>
				<mesh filename="meshes/finger_segment_ipt_50d2a7f4.STL" scale="0.001 0.001 0.001"/>
			</geometry>
			<origin rpy="0 0 0" xyz="-0.015691 -0.015507 -0.007416"/>
			<material name="finger_segment:26_color">
				<color rgba="0.74902 0.74902 0.74902 1"/>
			</material>
		</visual>
		<collision>
			<geometry>
				<mesh filename="meshes/finger_segment_ipt_50d2a7f4.STL" scale="0.001 0.001 0.001"/>
			</geometry>
			<origin rpy="0 0 0" xyz="-0.015691 -0.015507 -0.007416"/>
		</collision>
		<inertial>
			<mass value="0.000009"/>
			<inertia ixx="0" ixy="0" ixz="-0" iyy="0" iyz="0" izz="0"/>
			<origin rpy="0 0 0" xyz="-0.004101 0.000556 -0.005751"/>
		</inertial>
	</link>
	<joint name="l_ringfingers_x" type="fixed">
		<parent link="left_palm:11"/>
		<child link="finger_segment:26"/>
		<origin rpy="2.499505 -0.062904 0" xyz="-0.036179 0.006226 0.04057"/>
		<axis xyz="0.998051 0.00234199 0.0623629"/>
		<limit effort="30" lower="-1.309" upper="0" velocity="1"/>
	</joint>
	<link name="finger_segment:16">
		<visual>
			<geometry>
				<mesh filename="meshes/finger_segment_ipt_50d2a7f4.STL" scale="0.001 0.001 0.001"/>
			</geometry>
			<origin rpy="0 0 0" xyz="-0.006181 -0.015508 -0.007416"/>
			<material name="finger_segment:16_color">
				<color rgba="0.74902 0.74902 0.74902 1"/>
			</material>
		</visual>
		<collision>
			<geometry>
				<mesh filename="meshes/finger_segment_ipt_50d2a7f4.STL" scale="0.001 0.001 0.001"/>
			</geometry>
			<origin rpy="0 0 0" xyz="-0.006181 -0.015508 -0.007416"/>
		</collision>
		<inertial>
			<mass value="0.000009"/>
			<inertia ixx="0" ixy="0" ixz="-0" iyy="0" iyz="0" izz="0"/>
			<origin rpy="0 0 0" xyz="0.005409 0.000556 -0.005751"/>
		</inertial>
	</link>
	<joint name="l_ringfinger_1st_x" type="fixed">
		<parent link="finger_segment:26"/>
		<child link="finger_segment:16"/>
		<origin rpy="-0.095246 0 0" xyz="-0.00951 0 -0.016"/>
		<axis xyz="0.998051 0.00234199 0.0623629"/>
		<limit effort="30" lower="-1.309" upper="0" velocity="1"/>
	</joint>
	<link name="fingertip:16">
		<visual>
			<geometry>
				<mesh filename="meshes/fingertip_ipt_8417b8a9.STL" scale="0.001 0.001 0.001"/>
			</geometry>
			<origin rpy="0 0 0" xyz="0.005514 0.000374 -0.010171"/>
			<material name="fingertip:16_color">
				<color rgba="0.74902 0.74902 0.74902 1"/>
			</material>
		</visual>
		<collision>
			<geometry>
				<mesh filename="meshes/fingertip_ipt_8417b8a9.STL" scale="0.001 0.001 0.001"/>
			</geometry>
			<origin rpy="0 0 0" xyz="0.005514 0.000374 -0.010171"/>
		</collision>
		<inertial>
			<mass value="0.000008"/>
			<inertia ixx="0" ixy="-0" ixz="-0" iyy="0" iyz="-0" izz="0"/>
			<origin rpy="0 0 0" xyz="0.005013 0.000408 -0.010216"/>
		</inertial>
	</link>
	<joint name="l_ringfinger_2nd_x" type="fixed">
		<parent link="finger_segment:16"/>
		<child link="fingertip:16"/>
		<origin rpy="-0.109613 0 0" xyz="-0 -0 -0.015999"/>
		<axis xyz="0.998051 0.00234199 0.0623629"/>
		<limit effort="30" lower="-1.309" upper="0" velocity="1"/>
	</joint>
</robot>

