<?xml version="1.0" ?>
<robot name="nico_upper">
	<link name="world" />
	<link name="torso">
		<visual>
			<geometry>
				<box size="0.15 0.12 0.23"/>
			</geometry>
			<origin rpy="0 0 0" xyz="0.0 0.0 0.0"/>
			<material name="torso_color">
				<color rgba="0.270588 0.270588 0.270588 1"/>
			</material>
		</visual>
	</link>
	<joint name="world_to_base_link" type="fixed">
    	<parent link="world"/>
    	<child link="torso"/>
  	</joint>
    <link name="neck">
		<visual>
			<geometry>
				<mesh filename="meshes/neck_long_new.stl"/>
			</geometry>
			<origin rpy="0 0 0" xyz="0.0 0.0 0.0"/>
			<material name="neck:11_color">
				<color rgba="0.74902 0.74902 0.74902 1"/>
			</material>
		</visual>
		<collision>
			<geometry>
				<mesh filename="meshes/neck_long_new.stl"/>
			</geometry>
			<origin rpy="0 0 0" xyz="0.0 0.0 0.0"/>
		</collision>
	</link>
	<joint name="head_z_rjoint" type="revolute">
		<parent link="torso"/>
		<child link="neck"/>
		<origin rpy="0 0 0" xyz="-0.02 0.0 0.23"/>
		<axis xyz="0 0 1"/>
		<limit effort="30" lower="-3.124" upper="3.142" velocity="1"/>
	</joint>
</robot>