 <?xml version="1.0" ?>
<robot name="linear_switch">
    <link name="body" type="fixed">
        <inertial>
            <mass value="10000.0" />
            <origin xyz="0 0 0.0" />
            <inertia  ixx="0.0" ixy="0.0"  ixz="0.0"  iyy="0.0"  iyz="0.0"  izz="0.0" />
        </inertial>
        <visual>
            <origin xyz="0 0 0.0" rpy="0 0 0" />
            <geometry>
                <mesh filename="./stl/linear_switch_body.stl" scale="0.01 0.01 0.01"/>
           </geometry>
        </visual>
        <collision>
            <origin xyz="0 0 0.0" rpy="0 0 0" />
            <geometry>
                <mesh filename="./stl/linear_switch_body.stl" scale="0.01 0.01 0.01"/>
            </geometry>
        </collision>
    </link>
    <joint name="joint" type="prismatic">
        <parent link="body"/>
        <child link="stick"/>
        <origin rpy="0.0 0.0 0.0" xyz="0.0 0.0 0.0"/>
        <axis xyz="1 0 0"/>
        <limit effort="330.0" lower="-0.035" upper="0.035" velocity="2.16"/>
        <dynamics damping="0.0" friction="0.0"/>
    </joint>
    <link name="stick" type="fixed">
        <inertial>
            <mass value="10.0" />
            <origin xyz="0 0 0.0" />
            <inertia ixx="0.4" ixy="0.0" ixz="0.0" iyy="0.4" iyz="0.0" izz="0.2"/>
        </inertial>
        <visual>
            <origin xyz="0 0 0.0" rpy="0 0 0" />
            <geometry>
                <mesh filename="./stl/linear_switch_handle2.stl" scale="0.01 0.01 0.01"/>
            </geometry>
        </visual>
        <collision>
            <origin xyz="0 0 0.0" rpy="0 0 0" />
            <geometry>
                <mesh filename="./stl/linear_switch_handle2.stl" scale="0.01 0.01 0.01"/>
            </geometry>
        </collision>
    </link>
</robot>
