 <?xml version="1.0" ?>
<robot name="steering_wheel">
    <link name="body" type="fixed">
        <inertial>
            <mass value="10000.0" />
            <origin xyz="0 0 0.02" />
            <inertia  ixx="0.0" ixy="0.0"  ixz="0.0"  iyy="0.0"  iyz="0.0"  izz="0.0" />
        </inertial>
        <visual>
            <origin xyz="0 0 0.02" rpy="0 0 0" />
            <geometry>
                <mesh filename="./stl/steering_wheel_base.stl" scale="0.02 0.02 0.02"/>
           </geometry>
        </visual>
        <collision>
            <origin xyz="0 0 0.02" rpy="0 0 0" />
            <geometry>
                <mesh filename="./stl/steering_wheel_base.stl" scale="0.02 0.02 0.02"/>
            </geometry>
        </collision>
    </link>
    <joint name="joint" type="continuous">
        <parent link="body"/>
        <child link="stick"/>
        <origin rpy="0.0 0.0 0.1" xyz="0.0 0.0 0.0"/>
        <axis xyz="0 0 1"/>
        <limit effort="330.0" lower="-6.28318530718" upper="6.28318530718" velocity="2.16"/>
        <dynamics damping="0.0" friction="0.0"/>
    </joint>
    <link name="stick" type="fixed">
        <inertial>
            <mass value="10.0" />
            <origin xyz="0 0 0.01"/>
            <inertia ixx="0.4" ixy="0.0" ixz="0.0" iyy="0.4" iyz="0.0" izz="0.2"/>
        </inertial>
        <visual>
            <origin xyz="0 0 0.02" rpy="0 0 0" />
            <geometry>
                <mesh filename="./stl/steering_wheel_handle2.stl" scale="0.02 0.02 0.02"/>
            </geometry>
        </visual>
        <collision>
            <origin xyz="0 0 0.02" rpy="0 0 0" />
            <geometry>
                <mesh filename="./stl/steering_wheel_handle2.stl" scale="0.02 0.02 0.02"/>
            </geometry>
        </collision>
    </link>
</robot>
