<?xml version="1.0"?>
<robot name="myfirst" xmlns:xacro="http://www.ros.org/wiki/xacro">
    <link name="base_link">
        <inertial>
            <mass value="100.0" />
            <origin xyz="0 0 0.0" />
            <inertia  ixx="0.0" ixy="0.0"  ixz="0.0"  iyy="0.0"  iyz="0.0"  izz="0.0" />
        </inertial>
        <visual>
        <geometry>
            <box size="0.5 0.5 0.5"/>
        </geometry>
        </visual>
        <collision>
            <origin xyz="0 0 0.0" rpy="0 0 0" />
            <geometry>
                <box size="0.5 0.5 0.5"/>
            </geometry>
        </collision>
    </link>

    <joint name="joint1" type="revolute">
    <axis xyz="0 1 0"/>
    <limit effort="1000.0" lower="-0.548" upper="0.548" velocity="0.5"/>
        <parent link="base_link"/>
        <child link="arm2"/>
        <origin xyz="0 0 0.5" rpy="0 0 0" />
      </joint>

    <link name="arm2">
        <inertial>
            <mass value="10.0" />
            <origin xyz="0 0 0.0" />
            <inertia  ixx="0.0" ixy="0.0"  ixz="0.0"  iyy="0.0"  iyz="0.0"  izz="0.0" />
        </inertial>
        <visual>
            <origin xyz="0 0 0.1" rpy="0 0 0" />
            <geometry>
            <cylinder length="0.6" radius="0.04"/>
        </geometry>
        </visual>
        <collision>
            <origin xyz="0 0 0.1" rpy="0 0 0" />
            <geometry>
                <cylinder length="0.6" radius="0.04"/>
            </geometry>
        </collision>
    </link>
</robot>