<?xml version="0.0" ?>
<robot name="">
  <link
    name="base_link">
    <inertial>
			<origin rpy="0.00000 -0.00000 0.00000" xyz="0.00000 0.00000 0.00000"/>
			<mass value="0.00000"/>
			<inertia ixx="0.00000" ixy="0" ixz="0" iyy="0.00000" iyz="0" izz="0.00000"/>
		</inertial>
    <visual>
      <origin
        xyz="0 0 0"
        rpy="0 0 0" />
      <geometry>
        <mesh
          filename="package://righthand/meshes/base_link.stl" />
      </geometry>
      <material
        name="">
        <xacro:base_color/>
      </material>
    </visual>
  </link>

  <link
    name="pad">
    <inertial>
			<origin rpy="0.00000 -0.00000 0.00000" xyz="0.00000 0.00000 0.00000"/>
			<mass value="0.00000"/>
			<inertia ixx="0.00000" ixy="0" ixz="0" iyy="0.00000" iyz="0" izz="0.00000"/>
		</inertial>
    <visual>
      <origin
        xyz="0 0 0"
        rpy="0 0 0" />
      <geometry>
        <mesh
          filename="package://righthand/meshes/pad.stl" />
      </geometry>
      <material
        name="">
        <xacro:pad_color/>
      </material>
    </visual>
  </link>

  <joint
    name="pad_joint"
    type="fixed">
    <origin
      xyz="0.02 0 0.063"
      rpy="1.5707963267949 5.55111512312578E-17 -1.5707963267949" />
    <parent
      link="base_link" />
    <child
      link="pad" />
    <axis
      xyz="0 0 0" />
  </joint>

  <link
    name="swivel_1">
    <inertial>
			<origin rpy="0.00000 -0.00000 0.00000" xyz="0.00000 0.00000 0.00000"/>
			<mass value="0.00000"/>
			<inertia ixx="0.00000" ixy="0" ixz="0" iyy="0.00000" iyz="0" izz="0.00000"/>
		</inertial>
    <visual>
      <origin
        xyz="0 0 0"
        rpy="0 0 0" />
      <geometry>
        <mesh
          filename="package://righthand/meshes/swivel_1.stl" />
      </geometry>
      <material
        name="">
        <xacro:swivel_color/>
      </material>
    </visual>
  </link>

  <joint
    name="preshape_1"
    type="continuous">
    <origin
      xyz="0.0503973683071414 -0.026 0.063"
      rpy="6.75550818663469E-16 1.97993848419069E-16 -2.77555756156289E-16" />
    <parent
      link="base_link" />
    <child
      link="swivel_1" />
    <axis
      xyz="0 0 -1" />
  </joint>

  <link
    name="proximal_1">
    <inertial>
			<origin rpy="0.00000 -0.00000 0.00000" xyz="0.00000 0.00000 0.00000"/>
			<mass value="0.00000"/>
			<inertia ixx="0.00000" ixy="0" ixz="0" iyy="0.00000" iyz="0" izz="0.00000"/>
		</inertial>
    <visual>
      <origin
        xyz="-0.011 0.007 0.011"
        rpy="3.1459 0 0" />
      <geometry>
        <mesh
          filename="package://righthand/meshes/proximal_1.stl" />
      </geometry>
      <material
        name="">
        <xacro:proximal_color/>
      </material>
    </visual>
  </link>

  <joint
    name="proximal_joint_1"
    type="continuous">
    <origin
      xyz="0.01 0 0.0186"
      rpy="-6.20039667432211E-16 2.40507565059625E-17 2.22044604925031E-16" />
    <parent
      link="swivel_1" />
    <child
      link="proximal_1" />
    <axis
      xyz="0 -1 0" />
  </joint>

  <link
    name="proximal_pad_1">
    <inertial>
			<origin rpy="0.00000 -0.00000 0.00000" xyz="0.00000 0.00000 0.00000"/>
			<mass value="0.00000"/>
			<inertia ixx="0.00000" ixy="0" ixz="0" iyy="0.00000" iyz="0" izz="0.00000"/>
		</inertial>
    <visual>
      <origin
        xyz="1.5708 1.5708 0"
        rpy="-0.008 0.014 -0.002" />
      <geometry>
        <mesh
          filename="package://righthand/meshes/proximal_pad_1.stl" />
      </geometry>
      <material
        name="">
        <xacro:pad_color/>
      </material>
    </visual>
  </link>

  <joint
    name="prox1_pad_joint"
    type="fixed">
    <origin
      xyz="0 0 0"
      rpy="1.5707963267949 0 -1.5707963267949" />
    <parent
      link="proximal_1" />
    <child
      link="proximal_pad_1" />
    <axis
      xyz="0 0 0" />
  </joint>

  <link
    name="distal_1">
    <inertial>
			<origin rpy="0.00000 -0.00000 0.00000" xyz="0.00000 0.00000 0.00000"/>
			<mass value="0.00000"/>
			<inertia ixx="0.00000" ixy="0" ixz="0" iyy="0.00000" iyz="0" izz="0.00000"/>
		</inertial>
    <visual>
      <origin
        xyz="-0.077 0.007 0.007"
        rpy="3.1459 0 0" />
      <geometry>
        <mesh
          filename="package://righthand/meshes/distal_1.stl" />
      </geometry>
      <material
        name="">
        <xacro:distal_color/>
      </material>
    </visual>
  </link>

  <joint
    name="distal_joint_1"
    type="continuous">
    <origin
      xyz="0.0760000000000001 0 0.00250000000000002"
      rpy="0 0 0" />
    <parent
      link="proximal_1" />
    <child
      link="distal_1" />
    <axis
      xyz="0 -1 0" />
  </joint>

  <link
    name="distal_pad_1">
    <inertial>
			<origin rpy="0.00000 -0.00000 0.00000" xyz="0.00000 0.00000 0.00000"/>
			<mass value="0.00000"/>
			<inertia ixx="0.00000" ixy="0" ixz="0" iyy="0.00000" iyz="0" izz="0.00000"/>
		</inertial>
    <visual>
      <origin
        xyz="-0.00825 0.009 0.057"
        rpy="1.5708 1.5708 0" />
      <geometry>
        <mesh
          filename="package://righthand/meshes/distal_pad_1.stl" />
      </geometry>
      <material
        name="">
        <xacro:pad_color/>
      </material>
    </visual>
  </link>

  <joint
    name="dist1_pad_joint"
    type="fixed">
    <origin
      xyz="-0.01 0 0.001"
      rpy="1.5707963267949 0 -1.5707963267949" />
    <parent
      link="distal_1" />
    <child
      link="distal_pad_1" />
    <axis
      xyz="0 0 0" />
  </joint>

  <link
    name="swivel_2">
    <inertial>
			<origin rpy="0.00000 -0.00000 0.00000" xyz="0.00000 0.00000 0.00000"/>
			<mass value="0.00000"/>
			<inertia ixx="0.00000" ixy="0" ixz="0" iyy="0.00000" iyz="0" izz="0.00000"/>
		</inertial>
    <visual>
      <origin
        xyz="0 0 0"
        rpy="0 0 0" />
      <geometry>
        <mesh
          filename="package://righthand/meshes/swivel_2.stl" />
      </geometry>
      <material
        name="">
        <xacro:swivel_color/>
      </material>
    </visual>
  </link>

  <joint
    name="preshape_2"
    type="continuous">
    <origin
      xyz="0.0503973683071413 0.0259999999999999 0.063"
      rpy="1.22459340959228E-15 -7.33448407631817E-16 -1.66533453693773E-16" />
    <parent
      link="base_link" />
    <child
      link="swivel_2" />
    <axis
      xyz="0 0 -1" />
  </joint>

  <link
    name="proximal_2">
    <inertial>
			<origin rpy="0.00000 -0.00000 0.00000" xyz="0.00000 0.00000 0.00000"/>
			<mass value="0.00000"/>
			<inertia ixx="0.00000" ixy="0" ixz="0" iyy="0.00000" iyz="0" izz="0.00000"/>
		</inertial>
    <visual>
      <origin
        xyz="-0.011 0.007 0.011"
        rpy="3.1459 0 0" />
      <geometry>
        <mesh
          filename="package://righthand/meshes/proximal_1.stl" />
      </geometry>
      <material
        name="">
        <xacro:proximal_color/>
      </material>
    </visual>
  </link>

  <joint
    name="proximal_joint_2"
    type="continuous">
    <origin
      xyz="0.01 0 0.0186"
      rpy="-1.16908225836102E-15 9.55493012556849E-16 1.11022302462515E-16" />
    <parent
      link="swivel_2" />
    <child
      link="proximal_2" />
    <axis
      xyz="0 -1 0" />
  </joint>

  <link
    name="proximal_pad_2">
    <inertial>
			<origin rpy="0.00000 -0.00000 0.00000" xyz="0.00000 0.00000 0.00000"/>
			<mass value="0.00000"/>
			<inertia ixx="0.00000" ixy="0" ixz="0" iyy="0.00000" iyz="0" izz="0.00000"/>
		</inertial>
    <visual>
      <origin
        xyz="-0.008 0.014 -0.002"
        rpy="1.5708 1.5708 0" />
      <geometry>
        <mesh
          filename="package://righthand/meshes/proximal_pad_1.stl" />
      </geometry>
      <material
        name="">
        <xacro:pad_color/>
      </material>
    </visual>
  </link>

  <joint
    name="prox2_pad_joint"
    type="fixed">
    <origin
      xyz="0 0 0"
      rpy="1.5707963267949 0 -1.5707963267949" />
    <parent
      link="proximal_2" />
    <child
      link="proximal_pad_2" />
    <axis
      xyz="0 0 0" />
  </joint>

  <link
    name="distal_2">
    <inertial>
			<origin rpy="0.00000 -0.00000 0.00000" xyz="0.00000 0.00000 0.00000"/>
			<mass value="0.00000"/>
			<inertia ixx="0.00000" ixy="0" ixz="0" iyy="0.00000" iyz="0" izz="0.00000"/>
		</inertial>
    <visual>
      <origin
        xyz="3.1459 0 0"
        rpy="-0.077 0.007 0.006" />
      <geometry>
        <mesh
          filename="package://righthand/meshes/distal_1.stl" />
      </geometry>
      <material
        name="">
        <xacro:distal_color/>
      </material>
    </visual>
  </link>

  <joint
    name="distal_joint_2"
    type="continuous">
    <inertial>
			<origin rpy="0.00000 -0.00000 0.00000" xyz="0.00000 0.00000 0.00000"/>
			<mass value="0.00000"/>
			<inertia ixx="0.00000" ixy="0" ixz="0" iyy="0.00000" iyz="0" izz="0.00000"/>
		</inertial>
    <origin
      xyz="0.0760000000000001 0 0.00249999999999997"
      rpy="0 0 0" />
    <parent
      link="proximal_2" />
    <child
      link="distal_2" />
    <axis
      xyz="0 -1 0" />
  </joint>

  <link
    name="distal_pad_2">
    <inertial>
			<origin rpy="0.00000 -0.00000 0.00000" xyz="0.00000 0.00000 0.00000"/>
			<mass value="0.00000"/>
			<inertia ixx="0.00000" ixy="0" ixz="0" iyy="0.00000" iyz="0" izz="0.00000"/>
		</inertial>
    <visual>
      <origin
        xyz="-0.00825 0.009 0.057"
        rpy="1.5708 1.5708 0" />
      <geometry>
        <mesh
          filename="package://righthand/meshes/distal_pad_1.stl" />
      </geometry>
      <material
        name="">
        <xacro:pad_color/>
      </material>
    </visual>
  </link>

  <joint
    name="dist2_pad_joint"
    type="fixed">
    <origin
      xyz="-0.01 0 0.001"
      rpy="1.5707963267949 0 -1.5707963267949" />
    <parent
      link="distal_2" />
    <child
      link="distal_pad_2" />
    <axis
      xyz="0 0 0" />
  </joint>

  <link
    name="proximal_3">
    <inertial>
			<origin rpy="0.00000 -0.00000 0.00000" xyz="0.00000 0.00000 0.00000"/>
			<mass value="0.00000"/>
			<inertia ixx="0.00000" ixy="0" ixz="0" iyy="0.00000" iyz="0" izz="0.00000"/>
		</inertial>
    <visual>
      <origin
        xyz="-0.011 0.007 0.011"
        rpy="3.1459 0 0" />
      <geometry>
        <mesh
          filename="package://righthand/meshes/proximal_1.stl" />
      </geometry>
      <material
        name="">
        <xacro:proximal_color/>
      </material>
    </visual>
  </link>

  <joint
    name="proximal_joint_3"
    type="continuous">
    <origin
      xyz="-0.0299999999999996 0 0.0816000000000002"
      rpy="-5.55111512312578E-17 -2.22044604925031E-16 3.14159265358979" />
    <parent
      link="base_link" />
    <child
      link="proximal_3" />
    <axis
      xyz="0 -1 0" />
  </joint>

  <link
    name="proximal_pad_3">
    <inertial>
			<origin rpy="0.00000 -0.00000 0.00000" xyz="0.00000 0.00000 0.00000"/>
			<mass value="0.00000"/>
			<inertia ixx="0.00000" ixy="0" ixz="0" iyy="0.00000" iyz="0" izz="0.00000"/>
		</inertial>
    <visual>
      <origin
        xyz="-0.008 0.014 -0.002"
        rpy="1.5708 1.5708 0" />
      <geometry>
        <mesh
          filename="package://righthand/meshes/proximal_pad_1.stl" />
      </geometry>
      <material
        name="">
        <xacro:pad_color/>
      </material>
    </visual>
  </link>

  <joint
    name="prox3_pad_joint"
    type="fixed">
    <origin
      xyz="0 0 0"
      rpy="1.5707963267949 1.22460635382238E-16 -1.5707963267949" />
    <parent
      link="proximal_3" />
    <child
      link="proximal_pad_3" />
    <axis
      xyz="0 0 0" />
  </joint>

  <link
    name="distal_3">
    <inertial>
			<origin rpy="0.00000 -0.00000 0.00000" xyz="0.00000 0.00000 0.00000"/>
			<mass value="0.00000"/>
			<inertia ixx="0.00000" ixy="0" ixz="0" iyy="0.00000" iyz="0" izz="0.00000"/>
		</inertial>
    <visual>
      <origin
        xyz="-0.077 0.007 0.006"
        rpy="3.1459 0 0" />
      <geometry>
        <mesh
          filename="package://righthand/meshes/distal_1.stl" />
      </geometry>
      <material
        name="">
        <xacro:distal_color/>
      </material>
    </visual>
  </link>

  <joint
    name="distal_joint_3"
    type="continuous">
    <origin
      xyz="0.0760000000000001 0 0.0025"
      rpy="-1.48887961834512E-45 -1.0995850059156E-76 -7.38531841236285E-32" />
    <parent
      link="proximal_3" />
    <child
      link="distal_3" />
    <axis
      xyz="0 -1 0" />
  </joint>

  <link
    name="distal_pad_3">
    <inertial>
			<origin rpy="0.00000 -0.00000 0.00000" xyz="0.00000 0.00000 0.00000"/>
			<mass value="0.00000"/>
			<inertia ixx="0.00000" ixy="0" ixz="0" iyy="0.00000" iyz="0" izz="0.00000"/>
		</inertial>
    <visual>
      <origin
        xyz="0 0 0"
        rpy="0 0 0" />
      <geometry>
        <mesh
          filename="package://righthand/meshes/distal_pad_1.stl" />
      </geometry>
      <material
        name="">
        <xacro:pad_color/>
      </material>
    </visual>
  </link>

  <joint
    name="dist3_pad_joint"
    type="fixed">
    <origin
      xyz="-0.0760000000000001 0 -0.0025"
      rpy="1.5707963267949 -1.22460635382238E-16 -1.5707963267949" />
    <parent
      link="distal_3" />
    <child
      link="distal_pad_3" />
    <axis
      xyz="0 0 0" />
  </joint>
</robot>
