<?xml version="0.0" ?>
<robot name="">
	


<link name="link1_25">
		<inertial>
			<origin rpy="0.00000 -0.00000 0.00000" xyz="0.00000 0.00000 0.00000"/>
			<mass value="0.00000"/>
			<inertia ixx="0.00000" ixy="0" ixz="0" iyy="0.00000" iyz="0" izz="0.00000"/>
		</inertial>
	</link>
	<link name="link1_26">
		<inertial>
			<origin rpy="0.00000 -0.00000 0.00000" xyz="0.00000 0.00000 0.00000"/>
			<mass value="0.00000"/>
			<inertia ixx="0.00000" ixy="0" ixz="0" iyy="0.00000" iyz="0" izz="0.00000"/>
		</inertial>
	</link>
	<link name="right_upper_arm">
		<inertial>
			<origin rpy="0.00000 -0.00000 0.00000" xyz="0.08000 -0.08000 -0.08000"/>
			<mass value="1.66108"/>
			<inertia ixx="0.02368" ixy="0" ixz="0" iyy="0.02368" iyz="0" izz="0.02267"/>
		</inertial>
		<collision>
			<origin rpy="2.35619 0.61548 1.30900" xyz="0.08000 -0.08000 -0.08000"/>
			<geometry>
				<capsule length="0.27713" radius="0.04000"/>
			</geometry>
		</collision>
	</link>
	<link name="link1_28">
		<inertial>
			<origin rpy="0.00000 -0.00000 0.00000" xyz="0.00000 0.00000 0.00000"/>
			<mass value="0.00000"/>
			<inertia ixx="0.00000" ixy="0" ixz="0" iyy="0.00000" iyz="0" izz="0.00000"/>
		</inertial>
	</link>
	<link name="right_lower_arm">
		<inertial>
			<origin rpy="0.00000 -0.00000 0.00000" xyz="0.00000 0.00000 0.00000"/>
			<mass value="1.22954"/>
			<inertia ixx="0.01419" ixy="0" ixz="0" iyy="0.01419" iyz="0" izz="0.01374"/>
		</inertial>
		<collision> 
			<origin rpy="-0.78540 0.61548 -0.26180" xyz="0.09000 0.09000 0.09000"/>
			<geometry>
				<capsule length="0.27713" radius="0.03100"/>
			</geometry>
		</collision>

	</link>

	
	<joint name="right_shoulder2" type="continuous">
		<parent link="link1_25"/>
		<child link="link1_26"/>
		<dynamics damping="1.0" friction="0.0001"/>
		<origin rpy="0.00000 -0.00000 0.00000" xyz="0.00000 0.00000 0.00000"/>
		<axis xyz="0.00000 -1.00000 1.00000"/>
	</joint>
	<joint name="jointfix_9_26" type="fixed">
		<parent link="link1_26"/>
		<child link="right_upper_arm"/>
		<dynamics damping="1.0" friction="0.0001"/>
		<origin rpy="0.00000 -0.00000 0.00000" xyz="0.00000 0.00000 0.00000"/>
		<axis xyz="0.00000 0.00000 0.00000"/>
	</joint>
	<joint name="right_elbow" type="continuous">
		<parent link="right_upper_arm"/>
		<child link="link1_28"/>
		<dynamics damping="1.0" friction="0.0001"/>
		<origin rpy="0.00000 -0.00000 0.00000" xyz="0.18000 -0.18000 -0.18000"/>
		<axis xyz="0.00000 -1.00000 1.00000"/>
	</joint>
	<joint name="jointfix_8_28" type="fixed">
		<parent link="link1_28"/>
		<child link="right_lower_arm"/>
		<dynamics damping="1.0" friction="0.0001"/>
		<origin rpy="0.00000 -0.00000 0.00000" xyz="0.00000 0.00000 0.00000"/>
		<axis xyz="0.00000 0.00000 0.00000"/>
	</joint>


<!--
<link name="link1_25">
		<inertial>
			<origin rpy="0.00000 -0.00000 0.00000" xyz="0.00000 0.00000 0.00000"/>
			<mass value="0.00000"/>
			<inertia ixx="0.00000" ixy="0" ixz="0" iyy="0.00000" iyz="0" izz="0.00000"/>
		</inertial>
	</link>
	<link name="link1_26">
		<inertial>
			<origin rpy="0.00000 -0.00000 0.00000" xyz="0.00000 0.00000 0.00000"/>
			<mass value="0.00000"/>
			<inertia ixx="0.00000" ixy="0" ixz="0" iyy="0.00000" iyz="0" izz="0.00000"/>
		</inertial>
	</link>
	<link name="right_upper_arm">
		<inertial>
			<origin rpy="0.00000 -0.00000 0.00000" xyz="0.08000 -0.08000 -0.08000"/>
			<mass value="1.66108"/>
			<inertia ixx="0.02368" ixy="0" ixz="0" iyy="0.02368" iyz="0" izz="0.02267"/>
		</inertial>
		<collision>
			<origin rpy="2.35619 0.61548 1.30900" xyz="0.08000 -0.08000 -0.08000"/>
			<geometry>
				<capsule length="0.27713" radius="0.04000"/>
			</geometry>
		</collision>
	</link>
	<link name="link1_28">
		<inertial>
			<origin rpy="0.00000 -0.00000 0.00000" xyz="0.00000 0.00000 0.00000"/>
			<mass value="0.00000"/>
			<inertia ixx="0.00000" ixy="0" ixz="0" iyy="0.00000" iyz="0" izz="0.00000"/>
		</inertial>
	</link>
	<link name="right_lower_arm">
		<inertial>
			<origin rpy="0.00000 -0.00000 0.00000" xyz="0.00000 0.00000 0.00000"/>
			<mass value="1.22954"/>
			<inertia ixx="0.01419" ixy="0" ixz="0" iyy="0.01419" iyz="0" izz="0.01374"/>
		</inertial>
		<collision> 
			<origin rpy="-0.78540 0.61548 -0.26180" xyz="0.09000 0.09000 0.09000"/>
			<geometry>
				<capsule length="0.27713" radius="0.03100"/>
			</geometry>
		</collision>

	</link>

	
	<joint name="right_shoulder2" type="continuous">
		<parent link="link1_25"/>
		<child link="link1_26"/>
		<dynamics damping="1.0" friction="0.0001"/>
		<origin rpy="0.00000 -0.00000 0.00000" xyz="0.00000 0.00000 0.00000"/>
		<axis xyz="0.00000 -1.00000 1.00000"/>
	</joint>
	<joint name="jointfix_9_26" type="fixed">
		<parent link="link1_26"/>
		<child link="right_upper_arm"/>
		<dynamics damping="1.0" friction="0.0001"/>
		<origin rpy="0.00000 -0.00000 0.00000" xyz="0.00000 0.00000 0.00000"/>
		<axis xyz="0.00000 0.00000 0.00000"/>
	</joint>
	<joint name="right_elbow" type="continuous">
		<parent link="right_upper_arm"/>
		<child link="link1_28"/>
		<dynamics damping="1.0" friction="0.0001"/>
		<origin rpy="0.00000 -0.00000 0.00000" xyz="0.18000 -0.18000 -0.18000"/>
		<axis xyz="0.00000 -1.00000 1.00000"/>
	</joint>
	<joint name="jointfix_8_28" type="fixed">
		<parent link="link1_28"/>
		<child link="right_lower_arm"/>
		<dynamics damping="1.0" friction="0.0001"/>
		<origin rpy="0.00000 -0.00000 0.00000" xyz="0.00000 0.00000 0.00000"/>
		<axis xyz="0.00000 0.00000 0.00000"/>
	</joint>
	-->
</robot>