<?xml version="1.0" ?>
<!-- =================================================================================== -->
<!-- |    This document was autogenerated by xacro from panda_arm_hand.urdf.xacro      | -->
<!-- |    EDITING THIS FILE BY HAND IS NOT RECOMMENDED                                 | -->
<!-- =================================================================================== -->
<robot name="panda" xmlns:xacro="http://www.ros.org/wiki/xacro">
  <link name="world" />
  <link name="panda_link0">
    <inertial>
			<origin rpy="0.00000 -0.00000 0.00000" xyz="0.00000 0.00000 0.00000"/>
			<mass value="0.00000"/>
			<inertia ixx="0.00000" ixy="0" ixz="0" iyy="0.00000" iyz="0" izz="0.00000"/>
		</inertial>
    <visual>
      <geometry>
        <mesh filename="meshes/collision/link0.obj"/>
      </geometry>
      <material name="panda_white"/>
    </visual>
    <collision>
      <geometry>
        <mesh filename="meshes/collision/link0.obj"/>
      </geometry>
      <material name="panda_white"/>
    </collision>
  </link>
  <joint name="world_to_base_link" type="fixed">
    <parent link="world"/>
    <child link="panda_link0"/>
  </joint>
  <link name="panda_link1">
    <visual>
      <geometry>
        <mesh filename="meshes/collision/link1.obj"/>
      </geometry>
      <material name="panda_white"/>
    </visual>
    <collision>
      <geometry>
        <mesh filename="meshes/collision/link1.obj"/>
      </geometry>
      <material name="panda_white"/>
    </collision>
  </link>
  <joint name="panda_rjoint1" type="revolute">
    <safety_controller k_position="100.0" k_velocity="40.0" soft_lower_limit="-2.8973" soft_upper_limit="2.8973"/>
    <origin rpy="0 0 0" xyz="0 0 0.333"/>
    <parent link="panda_link0"/>
    <child link="panda_link1"/>
    <axis xyz="0 0 1"/>
    <limit effort="30" lower="-2.9671" upper="2.9671" velocity="1"/>
  </joint>
  <link name="panda_link2">
    <visual>
      <geometry>
        <mesh filename="meshes/collision/link2.obj"/>
      </geometry>
      <material name="panda_white"/>
    </visual>
    <collision>
      <geometry>
        <mesh filename="meshes/collision/link2.obj"/>
      </geometry>
      <material name="panda_white"/>
    </collision>
  </link>
  <joint name="panda_rjoint2" type="revolute">
    <safety_controller k_position="100.0" k_velocity="40.0" soft_lower_limit="-1.7628" soft_upper_limit="1.7628"/>
    <origin rpy="-1.57079632679 0 0" xyz="0 0 0"/>
    <parent link="panda_link1"/>
    <child link="panda_link2"/>
    <axis xyz="0 0 1"/>
    <limit effort="87" lower="-1.8326" upper="1.8326" velocity="1"/>
  </joint>
  <link name="panda_link3">
    <visual>
      <geometry>
        <mesh filename="meshes/collision/link3.obj"/>
      </geometry>
      <material name="panda_white"/>
    </visual>
    <collision>
      <geometry>
        <mesh filename="meshes/collision/link3.obj"/>
      </geometry>
      <material name="panda_white"/>
    </collision>
  </link>
  <joint name="panda_rjoint3" type="revolute">
    <safety_controller k_position="100.0" k_velocity="40.0" soft_lower_limit="-2.8973" soft_upper_limit="2.8973"/>
    <origin rpy="1.57079632679 0 0" xyz="0 -0.316 0"/>
    <parent link="panda_link2"/>
    <child link="panda_link3"/>
    <axis xyz="0 0 1"/>
    <limit effort="30" lower="-2.9671" upper="2.9671" velocity="1"/>
  </joint>
  <link name="panda_link4">
    <visual>
      <geometry>
        <mesh filename="meshes/collision/link4.obj"/>
      </geometry>
      <material name="panda_white"/>
    </visual>
    <collision>
      <geometry>
        <mesh filename="meshes/collision/link4.obj"/>
      </geometry>
      <material name="panda_white"/>
    </collision>
  </link>
  <joint name="panda_rjoint4" type="revolute">
    <safety_controller k_position="100.0" k_velocity="40.0" soft_lower_limit="-3.0718" soft_upper_limit="-0.0698"/>
    <origin rpy="1.57079632679 0 0" xyz="0.0825 0 0"/>
    <parent link="panda_link3"/>
    <child link="panda_link4"/>
    <axis xyz="0 0 1"/>
    <limit effort="30" lower="-3.1416" upper="0.0" velocity="1"/>
  </joint>
  <link name="panda_link5">
    <visual>
      <geometry>
        <mesh filename="meshes/collision/link5.obj"/>
      </geometry>
      <material name="panda_white"/>
    </visual>
    <collision>
      <geometry>
        <mesh filename="meshes/collision/link5.obj"/>
      </geometry>
      <material name="panda_white"/>
    </collision>
  </link>
  <joint name="panda_rjoint5" type="revolute">
    <safety_controller k_position="100.0" k_velocity="40.0" soft_lower_limit="-2.8973" soft_upper_limit="2.8973"/>
    <origin rpy="-1.57079632679 0 0" xyz="-0.0825 0.384 0"/>
    <parent link="panda_link4"/>
    <child link="panda_link5"/>
    <axis xyz="0 0 1"/>
    <limit effort="30" lower="-2.9671" upper="2.9671" velocity="1"/>
  </joint>Panda
  <link name="panda_link6">
    <visual>
      <geometry>
        <mesh filename="meshes/collision/link6.obj"/>
      </geometry>
      <material name="panda_white"/>
    </visual>
    <collision>
      <geometry>
        <mesh filename="meshes/collision/link6.obj"/>
      </geometry>
      <material name="panda_white"/>
    </collision>
  </link>
  <joint name="panda_rjoint6" type="revolute">
    <safety_controller k_position="100.0" k_velocity="40.0" soft_lower_limit="-0.0175" soft_upper_limit="3.7525"/>
    <origin rpy="1.57079632679 0 0" xyz="0 0 0"/>
    <parent link="panda_link5"/>
    <child link="panda_link6"/>
    <axis xyz="0 0 1"/>
    <limit effort="30" lower="-0.0873" upper="3.8223" velocity="1"/>
  </joint>
  <link name="panda_link7">
    <visual>
      <geometry>
        <mesh filename="meshes/collision/link7.obj"/>
      </geometry>
      <material name="panda_white"/>
    </visual>
    <collision>
      <geometry>
        <mesh filename="meshes/collision/link7.obj"/>
      </geometry>
      <material name="panda_white"/>
    </collision>
  </link>
  <joint name="panda_rjoint7" type="revolute">
    <safety_controller k_position="100.0" k_velocity="40.0" soft_lower_limit="-2.8973" soft_upper_limit="2.8973"/>
    <origin rpy="0 0 0" xyz="0.088 0 0"/> <!--1.57079632679-->
    <parent link="panda_link6"/>
    <child link="panda_link7"/>
    <axis xyz="0 0 1"/>
    <limit effort="30" lower="-2.9671" upper="2.9671" velocity="1"/>
  </joint>
  <link name="panda_link8"/>
  <joint name="panda_rjoint8" type="fixed">
    <origin rpy="0 0 0" xyz="0 0 0.107"/>
    <parent link="panda_link7"/>
    <child link="panda_link8"/>
    <axis xyz="0 0 0"/>
  </joint>
  <joint name="gripper_joint" type="fixed">
    <parent link="panda_link8"/>
    <child link="gripper"/>
    <origin rpy="0 0 -0.785398163397" xyz="0 0 0"/>
  </joint>
  <link name="gripper">
    <visual>
      <geometry>
        <mesh filename="meshes/collision/hand.obj"/>
      </geometry>
      <material name="panda_white"/>
    </visual>
    <collision>
      <geometry>
        <mesh filename="meshes/collision/hand.obj"/>
      </geometry>
      <material name="panda_white"/>
    </collision>
  </link>
    <joint name="endeffector_joint" type="fixed">
    <parent link="gripper"/>
    <child link="endeffector"/>
    <origin rpy="0 0 0" xyz="0 0.0 0.152"/>
  </joint>
  <link name="endeffector">
    <visual>
      <origin rpy="0 0 0" xyz="0 0.0 0.0"/>
      <geometry>
        <sphere radius="0.01"/>
      </geometry>
      <material name="panda_white"/>
    </visual>
  </link>
  <link name="panda_leftfinger">
    <contact>
            <restitution value="0" />
            <lateral_friction value="0"/>
            <rolling_friction value="0"/>
            <spinning_friction value="0"/>
            <linear_damping value="0"/>
            <angular_damping value="0"/>
    </contact>
    <visual>
      <origin rpy="0 0 3.14159265359" xyz="0 0 0"/>
      <geometry>
        <box size=".13 .005 .1"/>
      </geometry>
      <material name="gripper"/>
    </visual>
    <collision>
        <origin rpy="0 0 3.14159265359" xyz="0 0 0"/>
      <geometry>
        <box size=".13 .005 .1"/>
      </geometry>
    </collision>
  </link>
  <link name="panda_leftfinger1"> <!--panda_rightfinger-->
    <contact>
            <restitution value="0" />
            <lateral_friction value="0"/>
            <rolling_friction value="0"/>
            <spinning_friction value="0"/>
            <linear_damping value="0"/>
            <angular_damping value="0"/>
    </contact>
    <visual>
      <origin rpy="1.57 0 3.14159265359" xyz="0 0 0"/>
      <geometry>
        <box size=".13 .005 .05"/>
      </geometry>
      <material name="gripper"/>
    </visual>
    <collision>
      <origin rpy="1.57 0 3.14159265359" xyz="0 0 0"/>
      <geometry>
        <box size=".13 .005 .05"/>
      </geometry>
    </collision>
  </link>
  <link name="panda_leftfinger2"> <!--panda_rightfinger-->
    <contact>
            <restitution value="0" />
            <lateral_friction value="0"/>
            <rolling_friction value="0"/>
            <spinning_friction value="0"/>
            <linear_damping value="0"/>
            <angular_damping value="0"/>
    </contact>
    <visual>
      <origin rpy="1.57 0 3.14159265359" xyz="0 0 0"/>
      <geometry>
        <box size=".13 .005 .05"/>
      </geometry>
      <material name="gripper"/>
    </visual>
    <collision>
      <origin rpy="1.57 0 3.14159265359" xyz="0 0 0"/>
      <geometry>
        <box size=".13 .005 .05"/>
      </geometry>
    </collision>
  </link>
   <link name="panda_leftfinger3"> <!--panda_rightfinger-->
    <contact>
            <restitution value="0" />
            <lateral_friction value="0"/>
            <rolling_friction value="0"/>
            <spinning_friction value="0"/>
            <linear_damping value="0"/>
            <angular_damping value="0"/>
    </contact>
    <visual>
      <origin rpy="1.57 1.57 3.14159265359" xyz="0 0 0"/>
      <geometry>
        <box size=".1 .005 .05"/>
      </geometry>
      <material name="gripper"/>
    </visual>
    <collision>
      <origin rpy="1.57 1.57 3.14159265359" xyz="0 0 0"/>
      <geometry>
        <box size=".1 .005 .05"/>
      </geometry>
    </collision>
  </link>
     <link name="panda_leftfinger4"> <!--panda_rightfinger-->
    <contact>
            <restitution value="0" />
            <lateral_friction value="0"/>
            <rolling_friction value="0"/>
            <spinning_friction value="0"/>
            <linear_damping value="0"/>
            <angular_damping value="0"/>
    </contact>
    <visual>
      <origin rpy="1.57 1.57 3.14159265359" xyz="0 0 0"/>
      <geometry>
        <box size=".1 .005 .05"/>
      </geometry>
      <material name="gripper"/>
    </visual>
    <collision>
      <origin rpy="1.57 1.57 3.14159265359" xyz="0 0 0"/>
      <geometry>
        <box size=".1 .005 .05"/>
      </geometry>
    </collision>
  </link>
  <link name="panda_rightfinger"> <!--panda_rightfinger-->
    <contact>
            <restitution value="0" />
            <lateral_friction value="0"/>
            <rolling_friction value="0"/>
            <spinning_friction value="0"/>
            <linear_damping value="0"/>
            <angular_damping value="0"/>
    </contact>
    <visual>
      <origin rpy="0 0 3.14159265359" xyz="0 0 0"/>
      <geometry>
        <box size=".13 .01 .1"/>
      </geometry>
      <material name="gripper"/>
    </visual>
    <collision>
      <origin rpy="0 0 3.14159265359" xyz="0 0 0"/>
      <geometry>
        <box size=".13 .01 .1"/>
      </geometry>
    </collision>
  </link>
  <link name="panda_rightfinger1"> <!--panda_rightfinger-->
    <contact>
            <restitution value="0" />
            <lateral_friction value="0"/>
            <rolling_friction value="0"/>
            <spinning_friction value="100"/>
            <linear_damping value="0"/>
            <angular_damping value="0"/>
    </contact>
    <visual>
      <origin rpy="1.57 0 3.14159265359" xyz="0 0 0"/>
      <geometry>
        <box size=".13 .005 .05"/>
      </geometry>
      <material name="gripper"/>
    </visual>
    <collision>
      <origin rpy="1.57 0 3.14159265359" xyz="0 0 0"/>
      <geometry>
        <box size=".13 .005 .05"/>
      </geometry>
    </collision>
  </link>
   <link name="panda_rightfinger2"> <!--panda_rightfinger-->
    <contact>
            <restitution value="0" />
            <lateral_friction value="0"/>
            <rolling_friction value="0"/>
            <spinning_friction value="0"/>
            <linear_damping value="0"/>
            <angular_damping value="0"/>
    </contact>
    <visual>
      <origin rpy="1.57 0 3.14159265359" xyz="0 0 0"/>
      <geometry>
        <box size=".13 .005 .05"/>
      </geometry>
      <material name="gripper"/>
    </visual>
    <collision>
      <origin rpy="1.57 0 3.14159265359" xyz="0 0 0"/>
      <geometry>
        <box size=".13 .005 .05"/>
      </geometry>
    </collision>
  </link>
   <link name="panda_rightfinger3"> <!--panda_rightfinger-->
    <contact>
            <restitution value="0" />
            <lateral_friction value="0"/>
            <rolling_friction value="0"/>
            <spinning_friction value="0"/>
            <linear_damping value="0"/>
            <angular_damping value="0"/>
    </contact>
    <visual>
      <origin rpy="1.57 1.57 3.14159265359" xyz="0 0 0"/>
      <geometry>
        <box size=".1 .005 .05"/>
      </geometry>
      <material name="gripper"/>
    </visual>
    <collision>
      <origin rpy="1.57 1.57 3.14159265359" xyz="0 0 0"/>
      <geometry>
        <box size=".1 .005 .05"/>
      </geometry>
    </collision>
  </link>
     <link name="panda_rightfinger4"> <!--panda_rightfinger-->
    <contact>
            <restitution value="0" />
            <lateral_friction value="0"/>
            <rolling_friction value="0"/>
            <spinning_friction value="0"/>
            <linear_damping value="0"/>
            <angular_damping value="0"/>
    </contact>
    <visual>
      <origin rpy="1.57 1.57 3.14159265359" xyz="0 0 0"/>
      <geometry>
        <box size=".1 .005 .05"/>
      </geometry>
      <material name="gripper"/>
    </visual>
    <collision>
      <origin rpy="1.57 1.57 3.14159265359" xyz="0 0 0"/>
      <geometry>
        <box size=".1 .005 .05"/>
      </geometry>
    </collision>
  </link>
  <joint name="panda_finger_gjoint1" type="prismatic">
    <parent link="gripper"/>
    <child link="panda_leftfinger"/>
    <origin rpy="0 0 0" xyz="0 0 0.13"/>
    <axis xyz="0 1 0"/>
    <limit effort="200" lower="0.04" upper="0.1" velocity="1"/>
  </joint>
  <joint name="panda_finger_gjoint2" type="prismatic">
    <parent link="gripper"/>
    <child link="panda_rightfinger"/>
    <origin rpy="0 0 0" xyz="0 0 0.13"/>
    <axis xyz="0 -1 0"/>
    <limit effort="200" lower="0.04" upper="0.1" velocity="1"/>
    <mimic joint="panda_finger_gjoint1"/>
  </joint>
  <joint name="rf_joint" type="fixed">
    <parent link="panda_rightfinger"/>
    <child link="panda_rightfinger1"/>
    <origin rpy="0 0 0" xyz="0 0.02 0.052"/>
  </joint>
   <joint name="rf_joint1" type="fixed">
    <parent link="panda_rightfinger"/>
    <child link="panda_rightfinger2"/>
    <origin rpy="0 0 0" xyz="0 0.02 -0.052"/>
  </joint>
   <joint name="rf_joint2" type="fixed">
    <parent link="panda_rightfinger"/>
    <child link="panda_rightfinger3"/>
    <origin rpy="0 0 0" xyz="0.07 0.02 -0.0"/>
  </joint>
   <joint name="rf_joint3" type="fixed">
    <parent link="panda_rightfinger"/>
    <child link="panda_rightfinger4"/>
    <origin rpy="0 0 0" xyz="-0.07 0.02 -0.0"/>
  </joint>
  <joint name="lf_joint" type="fixed">
    <parent link="panda_leftfinger"/>
    <child link="panda_leftfinger1"/>
    <origin rpy="0 0 0" xyz="0 -0.02 0.052"/>
  </joint>
   <joint name="lf_joint1" type="fixed">
    <parent link="panda_leftfinger"/>
    <child link="panda_leftfinger2"/>
    <origin rpy="0 0 0" xyz="0 -0.02 -0.052"/>
  </joint>
   <joint name="lf_joint2" type="fixed">
    <parent link="panda_leftfinger"/>
    <child link="panda_leftfinger3"/>
    <origin rpy="0 0 0" xyz="0.068 -0.02 -0.0"/>
  </joint>
   <joint name="lf_joint3" type="fixed">
    <parent link="panda_leftfinger"/>
    <child link="panda_leftfinger4"/>
    <origin rpy="0 0 0" xyz="-0.068 -0.02 -0.0"/>
  </joint>
  <material name="panda_white">
    <color rgba="0.9 0.9 0.9 1."/>
  </material>
  <material name="gripper">
    <color rgba="0.0 0.0 1.0 .25"/>
  </material>

</robot>
