<?xml version="1.0" ?>
<robot name="kuka_gripper" xmlns:xacro="http://www.ros.org/wiki/xacro">
    <!-- Import Rviz colors -->
    <material name="Grey">
        <color rgba="0.1 0.1 0.1 1.0"/>
    </material>
    <material name="MLightGrey">
        <color rgba="0.6 0.6 0.8 1.0"/>
        </material>
      <material name="LightGrey">
        <color rgba="0.8 0.8 0.8 1.0"/>
    </material>
    <material name="Orange">
        <color rgba="1.0 1 1.0 1.0"/>
    </material>
    <material name="Blue">
        <color rgba="1 1 1.0 1.0"/>
    </material>

    <link name="lbr_iiwa_link_0">
        <inertial>
            <origin rpy="0 0 0" xyz=" 0 0 0"/>
            <mass value="0"/>
            <inertia ixx="0.05" ixy="0" ixz="0" iyy="0.06" iyz="0" izz="0.03"/>
        </inertial>
        <visual>
            <origin rpy="0 0 0" xyz="0 0 0"/>
            <geometry>
                <mesh filename="/meshes/link_0.obj"/>
            </geometry>
            <material name="Grey"/>
        </visual>
        <collision>
            <origin rpy="0 0 0" xyz="0 0 0"/>
            <geometry>
                <mesh filename="/meshes/link_0.obj"/>
            </geometry>
        </collision>
    </link>
    <!-- joint between link_0 and link_1 -->
    <joint name="lbr_iiwa_rjoint_1" type="revolute">
        <parent link="lbr_iiwa_link_0"/>
        <child link="lbr_iiwa_link_1"/>
        <origin rpy="0 0 0" xyz="0 0 0.1575"/>
        <axis xyz="0 0 1"/>
        <limit effort="30" lower="-2.96705972839" upper="2.96705972839" velocity="1"/>
        <dynamics damping="1"/>
    </joint>
    <link name="lbr_iiwa_link_1">
        <inertial>
            <origin rpy="0 0 0" xyz="0.0 -0.03 0.12"/>
            <mass value="4"/>
            <inertia ixx="0.1" ixy="0" ixz="0" iyy="0.09" iyz="0" izz="0.02"/>
        </inertial>
        <visual>
            <origin rpy="0 0 0" xyz="0 0 0"/>
            <geometry>
                <mesh filename="/meshes/link_1.obj"/>
            </geometry>
            <material name="Blue"/>
        </visual>
        <collision>
            <origin rpy="0 0 0" xyz="0 0 0"/>
            <geometry>
                <mesh filename="/meshes/link_1.obj"/>
            </geometry>
        </collision>
    </link>
    <!-- joint between link_1 and link_2 -->
    <joint name="lbr_iiwa_rjoint_2" type="revolute">
        <parent link="lbr_iiwa_link_1"/>
        <child link="lbr_iiwa_link_2"/>
        <origin rpy="1.57079632679   0 3.14159265359" xyz="0 0 0.2025"/>
        <axis xyz="0 0 1"/>
        <limit effort="30" lower="-2.09439510239" upper="2.09439510239" velocity="1"/>
        <dynamics damping="1"/>
    </joint>
    <link name="lbr_iiwa_link_2">
        <inertial>
            <origin rpy="0 0 0" xyz="0.0003 0.059 0.042"/>
            <mass value="4"/>
            <inertia ixx="0.05" ixy="0" ixz="0" iyy="0.018" iyz="0" izz="0.044"/>
        </inertial>
        <visual>
            <origin rpy="0 0 0" xyz="0 0 0"/>
            <geometry>
                <mesh filename="/meshes/link_2.obj"/>
            </geometry>
            <material name="Blue"/>
        </visual>
        <collision>
            <origin rpy="0 0 0" xyz="0 0 0"/>
            <geometry>
                <mesh filename="/meshes/link_2.obj"/>
            </geometry>
        </collision>
    </link>
    <!-- joint between link_2 and link_3 -->
    <joint name="lbr_iiwa_rjoint_3" type="revolute">
        <parent link="lbr_iiwa_link_2"/>
        <child link="lbr_iiwa_link_3"/>
        <origin rpy="1.57079632679 0 3.14159265359" xyz="0 0.2045 0"/>
        <axis xyz="0 0 1"/>
        <limit effort="30" lower="-2.96705972839" upper="2.96705972839" velocity="1"/>
        <dynamics damping="1"/>
    </joint>
    <link name="lbr_iiwa_link_3">
        <inertial>
            <origin rpy="0 0 0" xyz="0 0.03 0.13"/>
            <mass value="3"/>
            <inertia ixx="0.08" ixy="0" ixz="0" iyy="0.075" iyz="0" izz="0.01"/>
        </inertial>
        <visual>
            <origin rpy="0 0 0" xyz="0 0 0"/>
            <geometry>
                <mesh filename="/meshes/link_3.obj"/>
            </geometry>
            <material name="Orange"/>
        </visual>
        <collision>
            <origin rpy="0 0 0" xyz="0 0 0"/>
            <geometry>
                <mesh filename="/meshes/link_3.obj"/>
            </geometry>
        </collision>
    </link>
    <!-- joint between link_3 and link_4 -->
    <joint name="lbr_iiwa_rjoint_4" type="revolute">
        <parent link="lbr_iiwa_link_3"/>
        <child link="lbr_iiwa_link_4"/>
        <origin rpy="1.57079632679 0 0" xyz="0 0 0.2155"/>
        <axis xyz="0 0 1"/>
        <limit effort="30" lower="-2.09439510239" upper="2.09439510239" velocity="1"/>
        <dynamics damping="1"/>
    </joint>
    <link name="lbr_iiwa_link_4">
        <inertial>
            <origin rpy="0 0 0" xyz="0 0.067 0.034"/>
            <mass value="2.7"/>
            <inertia ixx="0.03" ixy="0" ixz="0" iyy="0.01" iyz="0" izz="0.029"/>
        </inertial>
        <visual>
            <origin rpy="0 0 0" xyz="0 0 0"/>
            <geometry>
                <mesh filename="/meshes/link_4.obj"/>
            </geometry>
            <material name="Blue"/>
        </visual>
        <collision>
            <origin rpy="0 0 0" xyz="0 0 0"/>
            <geometry>
                <mesh filename="/meshes/link_4.obj"/>
            </geometry>
        </collision>
    </link>
    <!-- joint between link_4 and link_5 -->
    <joint name="lbr_iiwa_rjoint_5" type="revolute">
        <parent link="lbr_iiwa_link_4"/>
        <child link="lbr_iiwa_link_5"/>
        <origin rpy="-1.57079632679 3.14159265359 0" xyz="0 0.1845 0"/>
        <axis xyz="0 0 1"/>
        <limit effort="30" lower="-2.96705972839" upper="2.96705972839" velocity="1"/>
        <dynamics damping="1"/>
    </joint>
    <link name="lbr_iiwa_link_5">
        <inertial>
            <origin rpy="0 0 0" xyz="0.0001 0.021 0.076"/>
            <mass value="1.7"/>
            <inertia ixx="0.02" ixy="0" ixz="0" iyy="0.018" iyz="0" izz="0.005"/>
        </inertial>
        <visual>
            <origin rpy="0 0 0" xyz="0 0 0"/>
            <geometry>
                <mesh filename="/meshes/link_5.obj"/>
            </geometry>
            <material name="Blue"/>
        </visual>
        <collision>
            <origin rpy="0 0 0" xyz="0 0 0"/>
            <geometry>
                <mesh filename="/meshes/link_5.obj"/>
            </geometry>
        </collision>
    </link>
    <!-- joint between link_5 and link_6 -->
    <joint name="lbr_iiwa_rjoint_6" type="revolute">
        <parent link="lbr_iiwa_link_5"/>
        <child link="lbr_iiwa_link_6"/>
        <origin rpy="1.57079632679 0 0" xyz="0 0 0.2155"/>
        <axis xyz="0 0 1"/>
        <limit effort="30" lower="-2.09439510239" upper="2.09439510239" velocity="1"/>
        <dynamics damping="1"/>
    </joint>
    <link name="lbr_iiwa_link_6">
        <inertial>
            <origin rpy="0 0 0" xyz="0 0.0006 0.0004"/>
            <mass value="1.8"/>
            <inertia ixx="0.005" ixy="0" ixz="0" iyy="0.0036" iyz="0" izz="0.0047"/>
        </inertial>
        <visual>
            <origin rpy="0 0 0" xyz="0 0 0"/>
            <geometry>
                <mesh filename="/meshes/link_6.obj"/>
            </geometry>
            <material name="Orange"/>
        </visual>
        <collision>
            <origin rpy="0 0 0" xyz="0 0 0"/>
            <geometry>
                <mesh filename="/meshes/link_6.obj"/>
            </geometry>
        </collision>
    </link>
    <!-- joint between link_6 and link_7 -->
    <joint name="lbr_iiwa_rjoint_7" type="revolute">
        <parent link="lbr_iiwa_link_6"/>
        <child link="lbr_iiwa_link_7"/>
        <origin rpy="-1.57079632679 3.14159265359 0" xyz="0 0.081 0"/>
        <axis xyz="0 0 1"/>
        <limit effort="30" lower="-3.05432619099" upper="3.05432619099" velocity="1"/>
        <dynamics damping="1"/>
    </joint>
    <link name="lbr_iiwa_link_7">
        <inertial>
            <origin rpy="0 0 0" xyz="0 0 0.02"/>
            <mass value="0.3"/>
            <inertia ixx="0.001" ixy="0" ixz="0" iyy="0.001" iyz="0" izz="0.001"/>
        </inertial>
        <visual>
            <origin rpy="0 0 0" xyz="0 0 0"/>
            <geometry>
                <mesh filename="/meshes/link_7.obj"/>
            </geometry>
            <material name="Grey"/>
        </visual>
        <collision>
            <origin rpy="0 0 0" xyz="0 0 0"/>
            <geometry>
                <mesh filename="/meshes/link_7.obj"/>
            </geometry>
        </collision>
    </link>



    <!-- ************************************************************************************ -->
    <!-- ************************************************************************************ -->
    <!-- ************************************************************************************ -->
    <!-- ************************************************************************************ -->
    <!-- ************************************************************************************ -->
    <!-- ************************************************************************************ -->
    <!-- ************************************************************************************ -->



    <!-- joint between kuka and gripper -->
    <joint name="gripper_joint" type="fixed">
        <parent link="lbr_iiwa_link_7"/>
        <child link="gripper"/>
        <origin rpy="0 0 0" xyz="0 0 0.05"/>
    </joint>
    <link name="gripper">
        <inertial>
            <origin rpy="0 0 0" xyz="0 0 0"/>
            <mass value="2.0"/>
            <inertia ixx="1.0" ixy="0" ixz="0" iyy="1.0" iyz="0" izz="1.0"/>
        </inertial>
        <visual>
            <origin rpy="0 0 0" xyz="0 0 0"/>
            <geometry>
                <mesh filename="/meshes/base.obj"/>
            </geometry>
            <material name="MLightGrey"/>
        </visual>
        <collision>
            <origin rpy="0 0 0" xyz="0 0 0"/>
            <geometry>
                <mesh filename="/meshes/base.obj"/>
            </geometry>
        </collision>
    </link>
    <joint name="endeffector_joint" type="fixed">
    <parent link="gripper"/>
    <child link="endeffector"/>
    <origin rpy="0 0 0" xyz="0 0.0 0.1"/>
  </joint>
  <link name="endeffector">
    <visual>
      <origin rpy="0 0 0" xyz="0 0.0 0.0"/>
      <geometry>
        <sphere radius="0.01"/>
      </geometry>
      <material name="panda_white"/>
    </visual>
  </link>
    <!-- joint between link_0 and link_1 -->
    <joint name="base_to_finger00_gjoint" type="revolute">
        <parent link="gripper"/>
        <child link="finger_00"/>
        <origin rpy="0 0 0" xyz="0.023510971786833857 0 0"/>
        <axis xyz="0 1 0"/>
        <limit effort="30" lower="0" upper="1.5707963267948966" velocity="1"/>
        <dynamics damping="1"/>
    </joint>
    <link name="finger_00">
        <contact>
            <restitution value="0.05" />
            <rolling_friction value="0.01"/>
            <spinning_friction value="0.01"/>
        </contact>
        <inertial>
            <origin rpy="0 0 0" xyz="0 0 0"/>
            <mass value="2.0"/>
            <inertia ixx="0.04" ixy="0" ixz="0" iyy="0.04" iyz="0" izz="0.02"/>
        </inertial>
        <visual>
            <origin rpy="0 0 0" xyz="0 0 0"/>
            <geometry>
                <mesh filename="/meshes/finger_0.obj" scale="1 0.7 0.7"/>
            </geometry>
            <material name="LightGrey"/>
        </visual>
        <collision>
            <origin rpy="0 0 0" xyz="0 0 0"/>
            <geometry>
                <mesh filename="/meshes/finger_0.obj" scale="1 0.7 0.7"/>
            </geometry>
        </collision>
    </link>
    <!-- joint between link_1 and link_2 -->
    <joint name="finger00_to_finger01_gjoint" type="revolute">
        <parent link="finger_00"/>
        <child link="finger_01"/>
        <origin rpy="0 0 0" xyz="0 0  0.0768025078369906"/>
        <axis xyz="0 1 0"/>
        <limit effort="30" upper="-1.5707963267948966" lower="0" velocity="1"/>
        <dynamics damping="1"/>
    </joint>
    <link name="finger_01">
        <contact>
            <restitution value="0.05" />
            <rolling_friction value="0.01"/>
            <spinning_friction value="0.01"/>
        </contact>
        <inertial>
            <origin rpy="0 0 0" xyz="0 0 0"/>
            <mass value="2.0"/>
            <inertia ixx="0.04" ixy="0" ixz="0" iyy="0.04" iyz="0" izz="0.02"/>
        </inertial>
        <visual>
            <origin rpy="0 0 0" xyz="0 0 0"/>
            <geometry>
                <mesh filename="/meshes/finger_1.obj" scale="1 0.7 0.7"/>
            </geometry>
            <material name="LightGrey"/>
        </visual>
        <collision>
            <origin rpy="0 0 0" xyz="0 0 0"/>
            <geometry>
                <mesh filename="/meshes/finger_1.obj" scale="1 0.7 0.7"/>
            </geometry>
        </collision>
    </link>





    <!-- joint between link_0 and link_3 -->
    <joint name="base_to_finger10_gjoint" type="revolute">
        <parent link="gripper"/>
        <child link="finger_10"/>
        <origin rpy="0 0 3.141592653589793" xyz="-0.023510971786833857 0 0"/>
        <axis xyz="0 1 0"/>
        <limit effort="30" lower="0" upper="1.5707963267948966" velocity="1"/>
        <dynamics damping="1"/>
    </joint>
    <link name="finger_10">
        <contact>
            <restitution value="0.05" />
            <rolling_friction value="0.01"/>
            <spinning_friction value="0.01"/>
        </contact>
        <inertial>
            <origin rpy="0 0 0" xyz="0 0 0.02"/>
            <mass value="2.0"/>
            <inertia ixx="0.04" ixy="0" ixz="0" iyy="0.04" iyz="0" izz="0.02"/>
        </inertial>
        <visual>
            <origin rpy="0 0 0" xyz="0 0 0"/>
            <geometry>
                <mesh filename="/meshes/finger_0.obj" scale="1 0.7 0.7"/>
            </geometry>
            <material name="LightGrey">
                <texture filename="/meshes/LightGrey.png"/>
            </material>
        </visual>
        <collision>
            <origin rpy="0 0 0" xyz="0 0 0"/>
            <geometry>
                <mesh filename="/meshes/finger_0.obj" scale="1 0.7 0.7"/>
            </geometry>
        </collision>
    </link>
    <!-- joint between link_1 and link_2 -->
    <joint name="finger10_to_finger11_gjoint" type="revolute">
        <parent link="finger_10"/>
        <child link="finger_11"/>
        <origin rpy="0 0 0" xyz="0 0 0.0768025078369906"/>
        <axis xyz="0 1 0"/>
        <limit effort="30" upper="-1.5707963267948966" lower="0" velocity="1"/>
        <dynamics damping="1"/>
    </joint>
    <link name="finger_11">
        <contact>
            <restitution value="0.05" />
            <rolling_friction value="0.01"/>
            <spinning_friction value="0.01"/>
        </contact>
        <inertial>
            <origin rpy="0 0 0" xyz="0 0 0"/>
            <mass value="2.0"/>
            <inertia ixx="0.04" ixy="0" ixz="0" iyy="0.04" iyz="0" izz="0.02"/>
        </inertial>
        <visual>
            <origin rpy="0 0 0" xyz="0 0 0"/>
            <geometry>
                <mesh filename="/meshes/finger_1.obj" scale="1 0.7 0.7"/>
            </geometry>
            <material name="LightGrey">
                <texture filename="/meshes/LightGrey.png"/>
            </material>
        </visual>
        <collision>
            <origin rpy="0 0 0" xyz="0 0 0"/>
            <geometry>
                <mesh filename="/meshes/finger_1.obj" scale="1 0.7 0.7"/>
            </geometry>
        </collision>
    </link>
    <joint name="finger00_to_skin_joint" type="fixed">
        <parent link="finger_00"/>
        <child link="skin_00"/>
        <origin rpy="0 0 -3" xyz="-0.011 0 0.045"/>
    </joint>
    <link name="skin_00">
        <contact>
            <restitution value="0.05" />
            <rolling_friction value="0.01"/>
            <spinning_friction value="0.01"/>
        </contact>
        <inertial>
            <origin rpy="0 0 0" xyz="0 0 0"/>
            <mass value="0.0"/>
            <inertia ixx="1.0" ixy="0" ixz="0" iyy="1.0" iyz="0" izz="1.0"/>
        </inertial>
        <visual>
            <origin rpy="0 0 0" xyz="0 0 0"/>
            <geometry>
                <mesh filename="/meshes/skin_0.obj" scale ="1 0.3 0.7"/>
            </geometry>
            <material name="Blue"/>
        </visual>
        <collision>
            <origin rpy="0 0 0" xyz="0 0 0"/>
            <geometry>
                <mesh filename="/meshes/skin_0.obj" scale ="1 0.3 0.7"/>
            </geometry>
        </collision>
    </link>
    <joint name="finger10_to_skin_joint" type="fixed">
        <parent link="finger_10"/>
        <child link="skin_10"/>
        <origin rpy="0 0 3" xyz="-0.011 0 0.045"/>
    </joint>
    <link name="skin_10">
        <contact>
            <restitution value="0.05" />
            <rolling_friction value="0.01"/>
            <spinning_friction value="0.01"/>
        </contact>
        <inertial>
            <origin rpy="0 0 0" xyz="0 0 0"/>
            <mass value="0.0"/>
            <inertia ixx="1.0" ixy="0" ixz="0" iyy="1.0" iyz="0" izz="1.0"/>
        </inertial>
        <visual>
            <origin rpy="0 0 0" xyz="0 0 0"/>
            <geometry>
                <mesh filename="/meshes/skin_0.obj" scale ="1 0.3 0.7"/>
            </geometry>
            <material name="Blue"/>
        </visual>
        <collision>
            <origin rpy="0 0 0" xyz="0 0 0"/>
            <geometry>
                <mesh filename="/meshes/skin_0.obj" scale ="1 0.3 0.7"/>
            </geometry>
        </collision>
    </link>
    <joint name="finger01_to_skin_joint" type="fixed">
        <parent link="finger_01"/>
        <child link="skin_01"/>
        <origin rpy="0 0 -3" xyz="-0.013 0 0.045"/>
    </joint>
    <link name="skin_01">
        <contact>
            <restitution value="0.05" />
            <rolling_friction value="0.01"/>
            <spinning_friction value="0.01"/>
        </contact>
        <inertial>
            <origin rpy="0 0 0" xyz="0 0 0"/>
            <mass value="0.0"/>
            <inertia ixx="1.0" ixy="0" ixz="0" iyy="1.0" iyz="0" izz="1.0"/>
        </inertial>
        <visual>
            <origin rpy="0 0 0" xyz="0 0 0"/>
            <geometry>
                <mesh filename="/meshes/skin_0.obj" scale ="1 0.3 0.3"/>
            </geometry>
            <material name="Blue"/>
        </visual>
        <collision>
            <origin rpy="0 0 0" xyz="0 0 0"/>
            <geometry>
                <mesh filename="/meshes/skin_0.obj" scale ="1 0.3 0.3"/>
            </geometry>
        </collision>
    </link>
    <joint name="finger11_to_skin_joint" type="fixed">
        <parent link="finger_11"/>
        <child link="skin_11"/>
        <origin rpy="0 0 -3" xyz="-0.013 0 0.045"/>
    </joint>
    <link name="skin_11">
        <contact>
            <restitution value="0.05" />
            <rolling_friction value="0.01"/>
            <spinning_friction value="0.01"/>
        </contact>
        <inertial>
            <origin rpy="0 0 0" xyz="0 0 0"/>
            <mass value="0.0"/>
            <inertia ixx="1.0" ixy="0" ixz="0" iyy="1.0" iyz="0" izz="1.0"/>
        </inertial>
        <visual>
            <origin rpy="0 0 0" xyz="0 0 0"/>
            <geometry>
                <mesh filename="/meshes/skin_0.obj" scale ="1 0.3 0.3"/>
            </geometry>
            <material name="Blue"/>
        </visual>
        <collision>
            <origin rpy="0 0 0" xyz="0 0 0"/>
            <geometry>
                <mesh filename="/meshes/skin_0.obj" scale ="1 0.3 0.3"/>
            </geometry>
        </collision>
    </link>
</robot>
