<?xml version="0.0" ?>
<robot name="">

	<link name="gripper">
		<inertial>
			<origin rpy="0.00000 -0.00000 0.00000" xyz="0.00000 0.00000 0.00000"/>
			<mass value="0.00000"/>
			<inertia ixx="0.00000" ixy="0" ixz="0" iyy="0.00000" iyz="0" izz="0.00000"/>
		</inertial>
		<visual>
			<origin rpy="0.00000 -0.00000 0.00000" xyz="0.00000 0.00000 0.00000"/>
			<geometry>
				<mesh filename="schunk/assets/gripper.stl" scale="0.00100 0.00100 0.00100"/>
			</geometry>
		</visual>
		<collision>
			<origin rpy="0.00000 -0.00000 0.00000" xyz="0.00000 0.00000 0.00000"/>
			<geometry>
				<mesh filename="schunk/assets/gripper.stl" scale="0.00100 0.00100 0.00100"/>
			</geometry>
		</collision>
	</link>

	<link name="link0_2">
		<inertial>
			<origin rpy="0.00000 -0.00000 0.00000" xyz="0.00000 0.00000 0.00000"/>
			<mass value="0.00000"/>
			<inertia ixx="0.00000" ixy="0" ixz="0" iyy="0.00000" iyz="0" izz="0.00000"/>
		</inertial>
	</link>

	<link name="finger_1">
		<inertial>
			<origin rpy="0.00000 -0.00000 0.00000" xyz="0.00000 1.00000 0.00000"/>
			<mass value="0.00000"/>
			<inertia ixx="0.00000" ixy="0" ixz="0" iyy="0.00000" iyz="0" izz="0.00000"/>
		</inertial>
		<visual>
			<origin rpy="0.00000 -0.00000 0.00000" xyz="0.00000 0.00000 0.00000"/>
			<geometry>
				<mesh filename="schunk/assets/finger.stl" scale="0.00100 0.00100 0.00100"/>
			</geometry>
		</visual>
		<collision>
			<origin rpy="0.00000 -0.00000 0.00000" xyz="0.00000 0.00000 0.00000"/>
			<geometry>
				<mesh filename="schunk/assets/finger.stl" scale="0.00100 0.00100 0.00100"/>
			</geometry>
		</collision>
	</link>

	<link name="link0_4">
		<inertial>
			<origin rpy="0.00000 -0.00000 0.00000" xyz="0.00000 0.00000 0.00000"/>
			<mass value="0.00000"/>
			<inertia ixx="0.00000" ixy="0" ixz="0" iyy="0.00000" iyz="0" izz="0.00000"/>
		</inertial>
	</link>

	<link name="finger_2">
		<inertial>
			<origin rpy="0.00000 -0.00000 0.00000" xyz="0.00000 0.00000 0.00000"/>
			<mass value="0.00000"/>
			<inertia ixx="0.00000" ixy="0" ixz="0" iyy="0.00000" iyz="0" izz="0.00000"/>
		</inertial>
		<visual>
			<origin rpy="0.00000 -0.00000 0.00000" xyz="0.00000 0.00000 0.00000"/>
			<geometry>
				<mesh filename="schunk/assets/finger.stl" scale="0.00100 0.00100 0.00100"/>
			</geometry>
		</visual>
		<collision>
			<origin rpy="0.00000 -0.00000 0.00000" xyz="0.00000 0.00000 0.00000"/>
			<geometry>
				<mesh filename="schunk/assets/finger.stl" scale="0.00100 0.00100 0.00100"/>
			</geometry>
		</collision>
	</link>


	<joint name="finger_1" type="prismatic">
		<parent link="gripper"/>
		<child link="link0_2"/>
		<limit effort="1000.0" lower="0.0" upper="0.0215" velocity="0.5"/>
		<dynamics damping="1.0" friction="0.0001"/>
		<origin rpy="0.00000 -0.00000 0.00000" xyz="0.00000 -0.03200 0.10000"/>
		<axis xyz="0.00000 1.00000 0.00000"/>
	</joint>


	<joint name="jointfix_0_2" type="fixed">
		<parent link="link0_2"/>
		<child link="finger_1"/>
		<dynamics damping="1.0" friction="0.0001"/>
		<origin rpy="0.00000 -0.00000 0.00000" xyz="0.00000 -0.00045 0.00110"/>
		<limit effort="1000.0" lower="0.0" upper="0.0" velocity="0.5"/>
		<axis xyz="0.00000 0.00000 0.00000"/>
	</joint>

	<joint name="finger_2" type="prismatic">
		<parent link="gripper"/>
		<child link="link0_4"/>
		<limit effort="1000.0" lower="0.0000" upper="0.0215" velocity="0.5"/>
	  <dynamics damping="1.0" friction="0.0001"/>
		<origin rpy="0.00000 -0.00000 3.14159" xyz="0.00000 0.03200 0.10000"/>
		<axis xyz="0.00000 1.00000 0.00000"/>
	</joint>
	<joint name="jointfix_1_4" type="fixed">
		<parent link="link0_4"/>
		<child link="finger_2"/>
		<dynamics damping="1.0" friction="0.0001"/>
		<origin rpy="0.00000 -0.00000 0.00000" xyz="0.00000 0.00060 0.00100"/>
		<axis xyz="0.00000 0.00000 0.00000"/>
	</joint>

</robot>
