<?xml version="1.0" encoding="utf-8"?>
<robot name="gummi">
  <link name="world" />
  <link
    name="base_link">
    <inertial>
      <origin
        xyz="-9.81410393552373E-06 -0.0460000689343235 -0.0065295158451983"
        rpy="0 0 0" />
      <mass
        value="0.335467320988356" />
      <inertia
        ixx="4.37751934245478E-05"
        ixy="-7.25114187919924E-08"
        ixz="-1.8551473383786E-07"
        iyy="3.79746167195594E-05"
        iyz="-1.48426357415501E-05"
        izz="5.80238931250525E-06" />
    </inertial>
    <visual>
      <origin
        xyz="0 0 0"
        rpy="0 0 0" />
      <geometry>
        <mesh
          filename="package://gummi_arm/meshes/base_link.stl" />
      </geometry>
      <material
        name="">
        <color
          rgba="0.792156862745098 0.819607843137255 0.933333333333333 1" />
      </material>
    </visual>
    <collision>
      <origin
        xyz="0 0 0"
        rpy="0 0 0" />
      <geometry>
        <mesh
          filename="package://gummi_arm/meshes/base_link.stl" />
      </geometry>
    </collision>
  </link>
  <joint name="world_to_base_link" type="fixed">
    <parent link="world"/>
    <child link="base_link"/>
  </joint>
  <link
    name="shoulder_preroll">
    <inertial>
      <origin
        xyz="-2.1762E-05 -0.0041376 0.031717"
        rpy="0 0 0" />
      <mass
        value="0.77225" />
      <inertia
        ixx="0.0026527"
        ixy="1.2427E-07"
        ixz="5.0677E-07"
        iyy="0.003032"
        iyz="4.4108E-05"
        izz="0.0012294" />
    </inertial>
    <visual>
      <origin
        xyz="0 0 0"
        rpy="0 0 0" />
      <geometry>
        <mesh
          filename="package://gummi_arm/meshes/shoulder_preroll.stl" />
      </geometry>
      <material
        name="">
        <color
          rgba="0.79216 0.81961 0.93333 1" />
      </material>
    </visual>
    <collision>
      <origin
        xyz="0 0 0"
        rpy="0 0 0" />
      <geometry>
        <mesh
          filename="package://gummi_arm/meshes/shoulder_preroll.stl" />
      </geometry>
    </collision>
  </link>
  <joint
    name="shoulder_yaw"
    type="revolute">
    <origin
      xyz="-0.00027025 -0.10997 0.008"
      rpy="0 0 0" />
    <parent
      link="base_link" />
    <child
      link="shoulder_preroll" />
    <axis
      xyz="0 0 1" />
    <limit
      lower="-0.75"
      upper="1"
      effort="0"
      velocity="0" />
  </joint>
  <link
    name="shoulder">
    <inertial>
      <origin
        xyz="-6.6912E-05 -0.10412 4.2145E-06"
        rpy="0 0 0" />
      <mass
        value="0.32611" />
      <inertia
        ixx="0.00024984"
        ixy="-1.3E-06"
        ixz="1.74E-07"
        iyy="7.3364E-05"
        iyz="8.2134E-08"
        izz="0.0003232" />
    </inertial>
    <visual>
      <origin
        xyz="0 0 0"
        rpy="0 0 0" />
      <geometry>
        <mesh
          filename="package://gummi_arm/meshes/shoulder.stl" />
      </geometry>
      <material
        name="">
        <color
          rgba="0.79216 0.81961 0.93333 1" />
      </material>
    </visual>
    <collision>
      <origin
        xyz="0 0 0"
        rpy="0 0 0" />
      <geometry>
        <mesh
          filename="package://gummi_arm/meshes/shoulder.stl" />
      </geometry>
    </collision>
  </link>
  <joint
    name="shoulder_roll"
    type="revolute">
    <origin
      xyz="-2.6378E-05 0.057605 0.1302"
      rpy="0 -2 0" /> <!--DEBUG-->
    <parent
      link="shoulder_preroll" />
    <child
      link="shoulder" />
    <axis
      xyz="0 -1 0" />
    <limit
      lower="-0.95"
      upper="2.3"
      effort="0"
      velocity="0" />
  </joint>
  <link
    name="upperarm_preroll">
    <inertial>
      <origin
        xyz="0.031774 -0.0098005 -0.046115"
        rpy="0 0 0" />
      <mass
        value="0.11889" />
      <inertia
        ixx="4.0724E-05"
        ixy="7.0589E-07"
        ixz="1.4611E-05"
        iyy="6.3279E-05"
        iyz="6.4487E-07"
        izz="2.3476E-05" />
    </inertial>
    <visual>
      <origin
        xyz="0 0 0"
        rpy="0 0 0" />
      <geometry>
        <mesh
          filename="package://gummi_arm/meshes/upperarm_preroll.stl" />
      </geometry>
      <material
        name="">
        <color
          rgba="0.79216 0.81961 0.93333 1" />
      </material>
    </visual>
    <collision>
      <origin
        xyz="0 0 0"
        rpy="0 0 0" />
      <geometry>
        <mesh
          filename="package://gummi_arm/meshes/upperarm_preroll.stl" />
      </geometry>
    </collision>
  </link>
  <joint
    name="shoulder_pitch"
    type="revolute">
    <origin
      xyz="-0.024 -0.17679 8.6827E-05"
      rpy="0.15 0 0" /><!--DEBUG-->
    <parent
      link="shoulder" />
    <child
      link="upperarm_preroll" />
    <axis
      xyz="-1 0 0" />
    <limit
      lower="-0.15"
      upper="1.1"
      effort="0"
      velocity="0" />
  </joint>
  <link
    name="upperarm">
    <inertial>
      <origin
        xyz="-0.0024737 -8.3239E-05 -0.1319"
        rpy="0 0 0" />
      <mass
        value="0.26501" />
      <inertia
        ixx="0.00079812"
        ixy="-7.2143E-08"
        ixz="-4.087E-05"
        iyy="0.0007849"
        iyz="-1.9447E-06"
        izz="2.1965E-05" />
    </inertial>
    <visual>
      <origin
        xyz="0 0 0"
        rpy="0 0 0" />
      <geometry>
        <mesh
          filename="package://gummi_arm/meshes/upperarm.stl" />
      </geometry>
      <material
        name="">
        <color
          rgba="0.79216 0.81961 0.93333 1" />
      </material>
    </visual>
    <collision>
      <origin
        xyz="0 0 0"
        rpy="0 0 0" />
      <geometry>
        <mesh
          filename="package://gummi_arm/meshes/upperarm.stl" />
      </geometry>
    </collision>
  </link>
  <joint
    name="upperarm_roll"
    type="revolute">
    <origin
      xyz="0.056992 -0.010088 -0.035587"
      rpy="0 0 0" />
    <parent
      link="upperarm_preroll" />
    <child
      link="upperarm" />
    <axis
      xyz="0 0 -1" />
    <limit
      lower="-1.56"
      upper="1.56"
      effort="0"
      velocity="0" />
  </joint>
  <link
    name="lowerarm_preroll_u">
    <inertial>
      <origin
        xyz="0.030339 -0.01865 -0.003795"
        rpy="0 0 0" />
      <mass
        value="0.034447" />
      <inertia
        ixx="0"
        ixy="0"
        ixz="0"
        iyy="0"
        iyz="0"
        izz="0" />
    </inertial>
    <visual>
      <origin
        xyz="0 0 0"
        rpy="0 0 0" />
      <geometry>
        <mesh
          filename="package://gummi_arm/meshes/lowerarm_preroll_u.stl" />
      </geometry>
      <material
        name="">
        <color
          rgba="0.79216 0.81961 0.93333 1" />
      </material>
    </visual>
    <collision>
      <origin
        xyz="0 0 0"
        rpy="0 0 0" />
      <geometry>
        <mesh
          filename="package://gummi_arm/meshes/lowerarm_preroll_u.stl" />
      </geometry>
    </collision>
  </link>
  <joint
    name="elbow"
    type="revolute">
    <origin
      xyz="-0.006 0.0184 -0.23533"
      rpy="0 1 0" /><!--DEBUG-->
    <parent
      link="upperarm" />
    <child
      link="lowerarm_preroll_u" />
    <axis
      xyz="0 -1 0" />
    <limit
      lower="-0.75"
      upper="0.35"
      effort="0"
      velocity="0" />
  </joint>

  <link
    name="upperarm_biceps_pulley">
    <inertial>
      <origin
        xyz="-0.0093595 8.3904E-05 3.1839E-09"
        rpy="0 0 0" />
      <mass
        value="0.01522" />
      <inertia
        ixx="4.2234E-11"
        ixy="3.7608E-09"
        ixz="-3.5118E-13"
        iyy="3.3488E-07"
        iyz="3.9438E-15"
        izz="3.3492E-07" />
    </inertial>
    <visual>
      <origin
        xyz="0 0 0"
        rpy="0 0 0" />
      <geometry>
        <mesh
          filename="package://gummi_arm/meshes/upperarm_biceps_pulley.stl" />
      </geometry>
      <material
        name="">
        <color
          rgba="0.79216 0.81961 0.93333 1" />
      </material>
    </visual>
    <collision>
      <origin
        xyz="0 0 0"
        rpy="0 0 0" />
      <geometry>
        <mesh
          filename="package://gummi_arm/meshes/upperarm_biceps_pulley.stl" />
      </geometry>
    </collision>
  </link>
  <joint
    name="upperarm_biceps_pulley_joint"
    type="fixed">
    <origin
      xyz="0.0375 0 -0.10243"
      rpy="0 0 0" />
    <parent
      link="upperarm" />
    <child
      link="upperarm_biceps_pulley" />
    <axis
      xyz="0 0 0" />
  </joint>
  <link
    name="upperarm_triceps_pulley">
    <inertial>
      <origin
        xyz="0.0093595 8.3904E-05 -3.1839E-09"
        rpy="0 0 0" />
      <mass
        value="0.01522" />
      <inertia
        ixx="4.2234E-11"
        ixy="-3.7608E-09"
        ixz="-3.5118E-13"
        iyy="3.3488E-07"
        iyz="-3.9438E-15"
        izz="3.3492E-07" />
    </inertial>
    <visual>
      <origin
        xyz="0 0 0"
        rpy="0 0 0" />
      <geometry>
        <mesh
          filename="package://gummi_arm/meshes/upperarm_triceps_pulley.stl" />
      </geometry>
      <material
        name="">
        <color
          rgba="0.79216 0.81961 0.93333 1" />
      </material>
    </visual>
    <collision>
      <origin
        xyz="0 0 0"
        rpy="0 0 0" />
      <geometry>
        <mesh
          filename="package://gummi_arm/meshes/upperarm_triceps_pulley.stl" />
      </geometry>
    </collision>
  </link>
  <joint
    name="upperarm_triceps_pulley_joint"
    type="fixed">
    <origin
      xyz="-0.0435 0 -0.12843"
      rpy="0 0 0" />
    <parent
      link="upperarm" />
    <child
      link="upperarm_triceps_pulley" />
    <axis
      xyz="-1 0 0" />
    <limit
      effort="0"
      velocity="0" />
  </joint>
  <link
    name="shoulder_roll_top_pulley">
    <inertial>
      <origin
        xyz="-8.3904E-05 -3.1839E-09 -0.0093595"
        rpy="0 0 0" />
      <mass
        value="0.01522" />
      <inertia
        ixx="3.3488E-07"
        ixy="3.9438E-15"
        ixz="-3.7608E-09"
        iyy="3.3492E-07"
        iyz="3.5118E-13"
        izz="4.2234E-11" />
    </inertial>
    <visual>
      <origin
        xyz="0 0 0"
        rpy="0 0 0" />
      <geometry>
        <mesh
          filename="package://gummi_arm/meshes/shoulder_roll_top_pulley.stl" />
      </geometry>
      <material
        name="">
        <color
          rgba="0.79216 0.81961 0.93333 1" />
      </material>
    </visual>
    <collision>
      <origin
        xyz="0 0 0"
        rpy="0 0 0" />
      <geometry>
        <mesh
          filename="package://gummi_arm/meshes/shoulder_roll_top_pulley.stl" />
      </geometry>
    </collision>
  </link>
  <joint
    name="shoulder_roll_top_pulley_joint"
    type="fixed">
    <origin
      xyz="0.0208 -0.06848 0.043"
      rpy="0 0 0" />
    <parent
      link="shoulder" />
    <child
      link="shoulder_roll_top_pulley" />
    <axis
      xyz="0 0 0" />
  </joint>
  <link
    name="shoulder_roll_bottom_pulley">
    <inertial>
      <origin
        xyz="8.3904E-05 -3.1839E-09 0.0093595"
        rpy="0 0 0" />
      <mass
        value="0.01522" />
      <inertia
        ixx="3.3488E-07"
        ixy="-3.9438E-15"
        ixz="-3.7608E-09"
        iyy="3.3492E-07"
        iyz="-3.5118E-13"
        izz="4.2234E-11" />
    </inertial>
    <visual>
      <origin
        xyz="0 0 0"
        rpy="0 0 0" />
      <geometry>
        <mesh
          filename="package://gummi_arm/meshes/shoulder_roll_bottom_pulley.stl" />
      </geometry>
      <material
        name="">
        <color
          rgba="0.79216 0.81961 0.93333 1" />
      </material>
    </visual>
    <collision>
      <origin
        xyz="0 0 0"
        rpy="0 0 0" />
      <geometry>
        <mesh
          filename="package://gummi_arm/meshes/shoulder_roll_bottom_pulley.stl" />
      </geometry>
    </collision>
  </link>
  <joint
    name="shoulder_roll_bottom_pulley"
    type="fixed">
    <origin
      xyz="-0.0208 -0.06848 -0.043"
      rpy="0 0 0" />
    <parent
      link="shoulder" />
    <child
      link="shoulder_roll_bottom_pulley" />
    <axis
      xyz="0 0 -1" />
    <limit
      effort="0"
      velocity="0" />
  </joint>
  <link
    name="shoulder_pitch_front_pulley">
    <inertial>
      <origin
        xyz="-0.0087313 -9.2787E-11 -0.00016773"
        rpy="0 0 0" />
      <mass
        value="0.027251" />
      <inertia
        ixx="2.8324E-10"
        ixy="-6.4973E-15"
        ixz="-1.1745E-08"
        iyy="4.8733E-07"
        iyz="-1.5668E-16"
        izz="4.8705E-07" />
    </inertial>
    <visual>
      <origin
        xyz="0 0 0"
        rpy="0 0 0" />
      <geometry>
        <mesh
          filename="package://gummi_arm/meshes/shoulder_pitch_front_pulley.stl" />
      </geometry>
      <material
        name="">
        <color
          rgba="0.79216 0.81961 0.93333 1" />
      </material>
    </visual>
    <collision>
      <origin
        xyz="0 0 0"
        rpy="0 0 0" />
      <geometry>
        <mesh
          filename="package://gummi_arm/meshes/shoulder_pitch_front_pulley.stl" />
      </geometry>
    </collision>
  </link>
  <joint
    name="shoulder_pitch_pulley_front_joint"
    type="fixed">
    <origin
      xyz="0.067474 -0.024095 0.044"
      rpy="0 0 0" />
    <parent
      link="shoulder_preroll" />
    <child
      link="shoulder_pitch_front_pulley" />
    <axis
      xyz="0 0 0" />
  </joint>
  <link
    name="shoulder_pitch_back_pulley">
    <inertial>
      <origin
        xyz="0.0087313 9.2787E-11 -0.00016773"
        rpy="0 0 0" />
      <mass
        value="0.027251" />
      <inertia
        ixx="2.8324E-10"
        ixy="-6.4973E-15"
        ixz="1.1745E-08"
        iyy="4.8733E-07"
        iyz="1.5668E-16"
        izz="4.8705E-07" />
    </inertial>
    <visual>
      <origin
        xyz="0 0 0"
        rpy="0 0 0" />
      <geometry>
        <mesh
          filename="package://gummi_arm/meshes/shoulder_pitch_back_pulley.stl" />
      </geometry>
      <material
        name="">
        <color
          rgba="0.79216 0.81961 0.93333 1" />
      </material>
    </visual>
    <collision>
      <origin
        xyz="0 0 0"
        rpy="0 0 0" />
      <geometry>
        <mesh
          filename="package://gummi_arm/meshes/shoulder_pitch_back_pulley.stl" />
      </geometry>
    </collision>
  </link>
  <joint
    name="shoulder_pitch_back_pulley_joint"
    type="fixed">
    <origin
      xyz="-0.067526 -0.024095 0.044"
      rpy="0 0 0" />
    <parent
      link="shoulder_preroll" />
    <child
      link="shoulder_pitch_back_pulley" />
    <axis
      xyz="0 0 0" />
  </joint>
  <!--gummi_description_ee-->
  <link
    name="lowerarm_preroll_d">
    <inertial>
      <origin
        xyz="0.0192090313803226 -0.000209732444885397 -0.00477606520095217"
        rpy="0 0 0" />
      <mass
        value="0.0573922743530686" />
      <inertia
        ixx="5.98272304285402E-07"
        ixy="-9.55132100709239E-09"
        ixz="2.00959509125472E-06"
        iyy="7.34863588332809E-06"
        iyz="2.84343934345717E-09"
        izz="6.7503906079721E-06" />
    </inertial>
    <visual>
      <origin
        xyz="0 0 0"
        rpy="0 0 0" />
      <geometry>
        <mesh
          filename="package://gummi_arm/meshes/lowerarm_preroll_d.stl" />
      </geometry>
      <material
        name="">
        <color
          rgba="0.792156862745098 0.819607843137255 0.933333333333333 1" />
      </material>
    </visual>
    <collision>
      <origin
        xyz="0 0 0"
        rpy="0 0 0" />
      <geometry>
        <mesh
          filename="package://gummi_arm/meshes/lowerarm_preroll_d.stl" />
      </geometry>
    </collision>
  </link>
  <joint
    name="fastswitch"
    type="fixed">
    <origin
      xyz="0.056236 -0.019 -0.006"
      rpy="0 0 0" />
    <parent
      link="lowerarm_preroll_u" />
    <child
      link="lowerarm_preroll_d" />
    <axis
      xyz="0 0 0" />
  </joint>
  <link
    name="lowerarm">
    <inertial>
      <origin
        xyz="0.076518166900465 0.000154587846369382 0.00668942647768447"
        rpy="0 0 0" />
      <mass
        value="0.214658222402075" />
      <inertia
        ixx="2.53797627665925E-05"
        ixy="-3.78406001691015E-09"
        ixz="1.36269412886066E-05"
        iyy="0.000325304336296306"
        iyz="3.75496083335353E-07"
        izz="0.000302080494837117" />
    </inertial>
    <visual>
      <origin
        xyz="0 0 0"
        rpy="0 0 0" />
      <geometry>
        <mesh
          filename="package://gummi_arm/meshes/lowerarm.stl" />
      </geometry>
      <material
        name="">
        <color
          rgba="0.792156862745098 0.819607843137255 0.933333333333333 1" />
      </material>
    </visual>
    <collision>
      <origin
        xyz="0 0 0"
        rpy="0 0 0" />
      <geometry>
        <mesh
          filename="package://gummi_arm/meshes/lowerarm.stl" />
      </geometry>
    </collision>
  </link>
  <joint
    name="forearm_roll"
    type="continuous">
    <origin
      xyz="0.043506 -0.00023376 -0.019876"
      rpy="0 0 0" />
    <parent
      link="lowerarm_preroll_d" />
    <child
      link="lowerarm" />
    <axis
      xyz="-1 0 0" />
    <limit
      effort="0"
      velocity="1" />
  </joint>
  <link
    name="wrist">
    <inertial>
      <origin
        xyz="0.0484512742480244 0.0139768664666073 0.000956995637939325"
        rpy="0 0 0" />
      <mass
        value="0.0644774651698934" />
      <inertia
        ixx="8.67406414845019E-06"
        ixy="-1.3193756197629E-05"
        ixz="-3.41916035169704E-06"
        iyy="4.217442276821E-05"
        iyz="-4.04257224014858E-07"
        izz="4.91399139463636E-05" />
    </inertial>
    <visual>
      <origin
        xyz="0 0 0"
        rpy="0 0 0" />
      <geometry>
        <mesh
          filename="package://gummi_arm/meshes/wrist.stl" />
      </geometry>
      <material
        name="">
        <color
          rgba="0.792156862745098 0.819607843137255 0.933333333333333 1" />
      </material>
    </visual>
    <collision>
      <origin
        xyz="0 0 0"
        rpy="0 0 0" />
      <geometry>
        <mesh
          filename="package://gummi_arm/meshes/wrist.stl" />
      </geometry>
    </collision>
  </link>
  <joint
    name="wrist_pitch"
    type="revolute">
    <origin
      xyz="0.1511 -0.01935 0.0048471"
      rpy="0 0 0" />
    <parent
      link="lowerarm" />
    <child
      link="wrist" />
    <axis
      xyz="0 1 0" />
    <limit
      lower="-1"
      upper="1"
      effort="0"
      velocity="0" />
  </joint>
  <!--
  making sure I can move my fingers in a synchronized way. also if they move at
  different rates, set the mimic tag to something different. it allows for an
  offset and a multiplication rate. check ros docs for details
  -->
  <joint name="gripper" type="revolute">
    <origin rpy="0 0 0" xyz="0 0 0"/>
    <parent link="wrist"/>
    <child link="gripper"/>
    <axis xyz="0 1 0"/>
    <limit effort="0" lower="0" upper="2" velocity="0"/>
  </joint>
  <link 
    name="gripper">
    <inertial>
      <origin
        xyz="0.0 0.0 0.0"
        rpy="0 0 0" />
      <mass
        value="0.001" />
      <inertia
        ixx="3.56498343502738E-08"
        ixy="-7.51978011656011E-09"
        ixz="7.65091950170785E-08"
        iyy="1.38099634070148E-06"
        iyz="2.95085409823962E-09"
        izz="1.34584197546666E-06" />
    </inertial>
  </link>
  <link
    name="i1">
    <inertial>
      <origin
        xyz="0.0230748926267925 0.00588066789200992 0.00129219082652174"
        rpy="0 0 0" />
      <mass
        value="0.00632408233084942" />
      <inertia
        ixx="3.56498343502738E-08"
        ixy="-7.51978011656011E-09"
        ixz="7.65091950170785E-08"
        iyy="1.38099634070148E-06"
        iyz="2.95085409823962E-09"
        izz="1.34584197546666E-06" />
    </inertial>
    <visual>
      <origin
        xyz="0 0 0"
        rpy="0 0 0" />
      <geometry>
        <mesh
          filename="package://gummi_arm/meshes/i1.stl" />
      </geometry>
      <material
        name="">
        <color
          rgba="0.792156862745098 0.819607843137255 0.933333333333333 1" />
      </material>
    </visual>
    <collision>
      <origin
        xyz="0 0 0"
        rpy="0 0 0" />
      <geometry>
        <mesh
          filename="package://gummi_arm/meshes/i1.stl" />
      </geometry>
    </collision>
  </link>
  <joint
    name="i1f"
    type="fixed"> <!--revolute-->
    <origin
      xyz="0.059922 -0.031986 0.0029515"
      rpy="-0.79367 0.12795 -0.91441" />
    <parent
      link="wrist" />
    <child
      link="i1" />
    <axis
      xyz="0 -1 0" />
    <limit
      lower="0"
      upper="0.8"
      effort="0"
      velocity="0" />
    <mimic joint="gripper"/>

  </joint>
  <link
    name="end_effector"> <!--i2-->
    <inertial>
      <origin
        xyz="0.029386051121549 0.00499999330192313 0.000893559269171462"
        rpy="0 0 0" />
      <mass
        value="0.00478605585780196" />
      <inertia
        ixx="1.44402270123506E-08"
        ixy="-2.56581222941725E-11"
        ixz="2.53254035448901E-08"
        iyy="1.75264603448073E-06"
        iyz="-2.73166158730175E-14"
        izz="1.73820581728879E-06" />
    </inertial>
    <visual>
      <origin
        xyz="0 0 0"
        rpy="0 0 0" />
      <geometry>
        <mesh
          filename="package://gummi_arm/meshes/i2.stl" />
      </geometry>
      <material
        name="">
        <color
          rgba="0.792156862745098 0.819607843137255 0.933333333333333 1" />
      </material>
    </visual>
    <collision>
      <origin
        xyz="0 0 0"
        rpy="0 0 0" />
      <geometry>
        <mesh
          filename="package://gummi_arm/meshes/i2.stl" />
      </geometry>
    </collision>
  </link>
  <joint
    name="i2f"
    type="fixed"> <!--revolute-->
    <origin
      xyz="0.12886 -0.0060786 -0.0024749"
      rpy="-6.9389E-16 -8.4436E-17 -0.12109" />
    <parent
      link="wrist" />
    <child
      link="end_effector" />
    <axis
      xyz="0 -1 0" />
    <limit
      lower="0"
      upper="0.8"
      effort="0"
      velocity="0" />
    <mimic joint="gripper"/>

  </joint>
  <link
    name="i3">
    <inertial>
      <origin
        xyz="0.0333094448268015 0.00500062828207009 0.000926424894512667"
        rpy="0 0 0" />
      <mass
        value="0.00575461720344836" />
      <inertia
        ixx="1.7528524706522E-08"
        ixy="5.05837929681755E-11"
        ixz="3.40539002999804E-08"
        iyy="2.72253553073577E-06"
        iyz="-1.34658964758198E-11"
        izz="2.70500702907738E-06" />
    </inertial>
    <visual>
      <origin
        xyz="0 0 0"
        rpy="0 0 0" />
      <geometry>
        <mesh
          filename="package://gummi_arm/meshes/i3.stl" />
      </geometry>
      <material
        name="">
        <color
          rgba="0.792156862745098 0.819607843137255 0.933333333333333 1" />
      </material>
    </visual>
    <collision>
      <origin
        xyz="0 0 0"
        rpy="0 0 0" />
      <geometry>
        <mesh
          filename="package://gummi_arm/meshes/i3.stl" />
      </geometry>
    </collision>
  </link>
  <joint
    name="i3f"
    type="fixed"> <!--revolute-->
    <origin
      xyz="0.13223 0.0086295 -0.0025"
      rpy="-1.0408E-15 -5.7778E-30 -5.5511E-15" />
    <parent
      link="wrist" />
    <child
      link="i3" />
    <axis
      xyz="0 -1 0" />
    <limit
      lower="0"
      upper="0.8"
      effort="0"
      velocity="0" />
    <mimic joint="gripper"/>

  </joint>
  <link
    name="i4">
    <inertial>
      <origin
        xyz="0.0292482948728239 0.00500042157737766 0.00089292978084992"
        rpy="0 0 0" />
      <mass
        value="0.00478456052942582" />
      <inertia
        ixx="1.4454849144576E-08"
        ixy="2.0656237329945E-11"
        ixz="2.47125764221831E-08"
        iyy="1.78182532599838E-06"
        iyz="-7.47440915183542E-12"
        izz="1.76737048495524E-06" />
    </inertial>
    <visual>
      <origin
        xyz="0 0 0"
        rpy="0 0 0" />
      <geometry>
        <mesh
          filename="package://gummi_arm/meshes/i4.stl" />
      </geometry>
      <material
        name="">
        <color
          rgba="0.792156862745098 0.819607843137255 0.933333333333333 1" />
      </material>
    </visual>
    <collision>
      <origin
        xyz="0 0 0"
        rpy="0 0 0" />
      <geometry>
        <mesh
          filename="package://gummi_arm/meshes/i4.stl" />
      </geometry>
    </collision>
  </link>
  <joint
    name="i4f"
    type="fixed"> <!--revolute-->
    <origin
      xyz="0.13046 0.023543 -0.0025"
      rpy="-1.0408E-15 1.4051E-16 0.13418" />
    <parent
      link="wrist" />
    <child
      link="i4" />
    <axis
      xyz="0 -1 0" />
    <limit
      lower="0"
      upper="0.8"
      effort="0"
      velocity="0" />
    <mimic joint="gripper"/>

  </joint>
  <link
    name="i5">
    <inertial>
      <origin
        xyz="0.0271094932224739 0.00500024784027392 0.000539597160873585"
        rpy="0 0 0" />
      <mass
        value="0.00396686667442233" />
      <inertia
        ixx="8.23853712957584E-09"
        ixy="2.89272292618791E-12"
        ixz="-1.05009595857809E-08"
        iyy="1.12916579855789E-06"
        iyz="-4.09427058097684E-12"
        izz="1.12092726589941E-06" />
    </inertial>
    <visual>
      <origin
        xyz="0 0 0"
        rpy="0 0 0" />
      <geometry>
        <mesh
          filename="package://gummi_arm/meshes/i5.stl" />
      </geometry>
      <material
        name="">
        <color
          rgba="0.792156862745098 0.819607843137255 0.933333333333333 1" />
      </material>
    </visual>
    <collision>
      <origin
        xyz="0 0 0"
        rpy="0 0 0" />
      <geometry>
        <mesh
          filename="package://gummi_arm/meshes/i5.stl" />
      </geometry>
    </collision>
  </link>
  <joint
    name="i5f"
    type="fixed"> <!--revolute-->
    <origin
      xyz="0.12703 0.037692 -0.0025"
      rpy="1.9429E-14 -3.8109E-15 0.19369" />
    <parent
      link="wrist" />
    <child
      link="i5" />
    <axis
      xyz="0 -1 0" />
    <limit
      lower="0"
      upper="0.8"
      effort="0"
      velocity="0" />
    <mimic joint="gripper"/>

  </joint>
</robot>
