<?xml version="1.0" encoding="utf-8"?>
<robot name="gummi">
  <link
    name="base_link">
    <inertial>
      <origin
        xyz="-9.81410393552373E-06 -0.0460000689343235 -0.0065295158451983"
        rpy="0 0 0" />
      <mass
        value="0.335467320988356" />
      <inertia
        ixx="4.37751934245478E-05"
        ixy="-7.25114187919924E-08"
        ixz="-1.8551473383786E-07"
        iyy="3.79746167195594E-05"
        iyz="-1.48426357415501E-05"
        izz="5.80238931250525E-06" />
    </inertial>
    <visual>
      <origin
        xyz="0 0 0"
        rpy="0 0 0" />
      <geometry>
        <mesh
          filename="package://gummi_arm/meshes/base_link.STL" />
      </geometry>
      <material
        name="">
        <color
          rgba="0.792156862745098 0.819607843137255 0.933333333333333 1" />
      </material>
    </visual>
    <collision>
      <origin
        xyz="0 0 0"
        rpy="0 0 0" />
      <geometry>
        <mesh
          filename="package://gummi_arm/meshes/base_link.STL" />
      </geometry>
    </collision>
  </link>
  <link
    name="shoulder_preroll">
    <inertial>
      <origin
        xyz="-2.1762E-05 -0.0041376 0.031717"
        rpy="0 0 0" />
      <mass
        value="0.77225" />
      <inertia
        ixx="0.0026527"
        ixy="1.2427E-07"
        ixz="5.0677E-07"
        iyy="0.003032"
        iyz="4.4108E-05"
        izz="0.0012294" />
    </inertial>
    <visual>
      <origin
        xyz="0 0 0"
        rpy="0 0 0" />
      <geometry>
        <mesh
          filename="package://gummi_arm/meshes/shoulder_preroll.STL" />
      </geometry>
      <material
        name="">
        <color
          rgba="0.79216 0.81961 0.93333 1" />
      </material>
    </visual>
    <collision>
      <origin
        xyz="0 0 0"
        rpy="0 0 0" />
      <geometry>
        <mesh
          filename="package://gummi_arm/meshes/shoulder_preroll.STL" />
      </geometry>
    </collision>
  </link>
  <joint
    name="shoulder_yaw"
    type="revolute">
    <origin
      xyz="-0.00027025 -0.10997 0.008"
      rpy="0 0 0" />
    <parent
      link="base_link" />
    <child
      link="shoulder_preroll" />
    <axis
      xyz="0 0 1" />
    <limit
      lower="-0.75"
      upper="1"
      effort="0"
      velocity="0" />
  </joint>
  <link
    name="shoulder">
    <inertial>
      <origin
        xyz="-6.6912E-05 -0.10412 4.2145E-06"
        rpy="0 0 0" />
      <mass
        value="0.32611" />
      <inertia
        ixx="0.00024984"
        ixy="-1.3E-06"
        ixz="1.74E-07"
        iyy="7.3364E-05"
        iyz="8.2134E-08"
        izz="0.0003232" />
    </inertial>
    <visual>
      <origin
        xyz="0 0 0"
        rpy="0 0 0" />
      <geometry>
        <mesh
          filename="package://gummi_arm/meshes/shoulder.STL" />
      </geometry>
      <material
        name="">
        <color
          rgba="0.79216 0.81961 0.93333 1" />
      </material>
    </visual>
    <collision>
      <origin
        xyz="0 0 0"
        rpy="0 0 0" />
      <geometry>
        <mesh
          filename="package://gummi_arm/meshes/shoulder.STL" />
      </geometry>
    </collision>
  </link>
  <joint
    name="shoulder_roll"
    type="revolute">
    <origin
      xyz="-2.6378E-05 0.057605 0.1302"
      rpy="0 0 0" />
    <parent
      link="shoulder_preroll" />
    <child
      link="shoulder" />
    <axis
      xyz="0 -1 0" />
    <limit
      lower="-0.95"
      upper="2.3"
      effort="0"
      velocity="0" />
  </joint>
  <link
    name="upperarm_preroll">
    <inertial>
      <origin
        xyz="0.031774 -0.0098005 -0.046115"
        rpy="0 0 0" />
      <mass
        value="0.11889" />
      <inertia
        ixx="4.0724E-05"
        ixy="7.0589E-07"
        ixz="1.4611E-05"
        iyy="6.3279E-05"
        iyz="6.4487E-07"
        izz="2.3476E-05" />
    </inertial>
    <visual>
      <origin
        xyz="0 0 0"
        rpy="0 0 0" />
      <geometry>
        <mesh
          filename="package://gummi_arm/meshes/upperarm_preroll.STL" />
      </geometry>
      <material
        name="">
        <color
          rgba="0.79216 0.81961 0.93333 1" />
      </material>
    </visual>
    <collision>
      <origin
        xyz="0 0 0"
        rpy="0 0 0" />
      <geometry>
        <mesh
          filename="package://gummi_arm/meshes/upperarm_preroll.STL" />
      </geometry>
    </collision>
  </link>
  <joint
    name="shoulder_pitch"
    type="revolute">
    <origin
      xyz="-0.024 -0.17679 8.6827E-05"
      rpy="0 0 0" />
    <parent
      link="shoulder" />
    <child
      link="upperarm_preroll" />
    <axis
      xyz="-1 0 0" />
    <limit
      lower="-0.15"
      upper="1.1"
      effort="0"
      velocity="0" />
  </joint>
  <link
    name="upperarm">
    <inertial>
      <origin
        xyz="-0.0024737 -8.3239E-05 -0.1319"
        rpy="0 0 0" />
      <mass
        value="0.26501" />
      <inertia
        ixx="0.00079812"
        ixy="-7.2143E-08"
        ixz="-4.087E-05"
        iyy="0.0007849"
        iyz="-1.9447E-06"
        izz="2.1965E-05" />
    </inertial>
    <visual>
      <origin
        xyz="0 0 0"
        rpy="0 0 0" />
      <geometry>
        <mesh
          filename="package://gummi_arm/meshes/upperarm.STL" />
      </geometry>
      <material
        name="">
        <color
          rgba="0.79216 0.81961 0.93333 1" />
      </material>
    </visual>
    <collision>
      <origin
        xyz="0 0 0"
        rpy="0 0 0" />
      <geometry>
        <mesh
          filename="package://gummi_arm/meshes/upperarm.STL" />
      </geometry>
    </collision>
  </link>
  <joint
    name="upperarm_roll"
    type="revolute">
    <origin
      xyz="0.056992 -0.010088 -0.035587"
      rpy="0 0 0" />
    <parent
      link="upperarm_preroll" />
    <child
      link="upperarm" />
    <axis
      xyz="0 0 -1" />
    <limit
      lower="-1.56"
      upper="1.56"
      effort="0"
      velocity="0" />
  </joint>
  <link
    name="lowerarm_preroll_u">
    <inertial>
      <origin
        xyz="0.030339 -0.01865 -0.003795"
        rpy="0 0 0" />
      <mass
        value="0.034447" />
      <inertia
        ixx="0"
        ixy="0"
        ixz="0"
        iyy="0"
        iyz="0"
        izz="0" />
    </inertial>
    <visual>
      <origin
        xyz="0 0 0"
        rpy="0 0 0" />
      <geometry>
        <mesh
          filename="package://gummi_arm/meshes/lowerarm_preroll_u.STL" />
      </geometry>
      <material
        name="">
        <color
          rgba="0.79216 0.81961 0.93333 1" />
      </material>
    </visual>
    <collision>
      <origin
        xyz="0 0 0"
        rpy="0 0 0" />
      <geometry>
        <mesh
          filename="package://gummi_arm/meshes/lowerarm_preroll_u.STL" />
      </geometry>
    </collision>
  </link>
  <joint
    name="elbow"
    type="revolute">
    <origin
      xyz="-0.006 0.0184 -0.23533"
      rpy="0 0 0" />
    <parent
      link="upperarm" />
    <child
      link="lowerarm_preroll_u" />
    <axis
      xyz="0 -1 0" />
    <limit
      lower="-0.75"
      upper="0.35"
      effort="0"
      velocity="0" />
  </joint>

  <link
    name="upperarm_biceps_pulley">
    <inertial>
      <origin
        xyz="-0.0093595 8.3904E-05 3.1839E-09"
        rpy="0 0 0" />
      <mass
        value="0.01522" />
      <inertia
        ixx="4.2234E-11"
        ixy="3.7608E-09"
        ixz="-3.5118E-13"
        iyy="3.3488E-07"
        iyz="3.9438E-15"
        izz="3.3492E-07" />
    </inertial>
    <visual>
      <origin
        xyz="0 0 0"
        rpy="0 0 0" />
      <geometry>
        <mesh
          filename="package://gummi_arm/meshes/upperarm_biceps_pulley.STL" />
      </geometry>
      <material
        name="">
        <color
          rgba="0.79216 0.81961 0.93333 1" />
      </material>
    </visual>
    <collision>
      <origin
        xyz="0 0 0"
        rpy="0 0 0" />
      <geometry>
        <mesh
          filename="package://gummi_arm/meshes/upperarm_biceps_pulley.STL" />
      </geometry>
    </collision>
  </link>
  <joint
    name="upperarm_biceps_pulley_joint"
    type="fixed">
    <origin
      xyz="0.0375 0 -0.10243"
      rpy="0 0 0" />
    <parent
      link="upperarm" />
    <child
      link="upperarm_biceps_pulley" />
    <axis
      xyz="0 0 0" />
  </joint>
  <link
    name="upperarm_triceps_pulley">
    <inertial>
      <origin
        xyz="0.0093595 8.3904E-05 -3.1839E-09"
        rpy="0 0 0" />
      <mass
        value="0.01522" />
      <inertia
        ixx="4.2234E-11"
        ixy="-3.7608E-09"
        ixz="-3.5118E-13"
        iyy="3.3488E-07"
        iyz="-3.9438E-15"
        izz="3.3492E-07" />
    </inertial>
    <visual>
      <origin
        xyz="0 0 0"
        rpy="0 0 0" />
      <geometry>
        <mesh
          filename="package://gummi_arm/meshes/upperarm_triceps_pulley.STL" />
      </geometry>
      <material
        name="">
        <color
          rgba="0.79216 0.81961 0.93333 1" />
      </material>
    </visual>
    <collision>
      <origin
        xyz="0 0 0"
        rpy="0 0 0" />
      <geometry>
        <mesh
          filename="package://gummi_arm/meshes/upperarm_triceps_pulley.STL" />
      </geometry>
    </collision>
  </link>
  <joint
    name="upperarm_triceps_pulley_joint"
    type="fixed">
    <origin
      xyz="-0.0435 0 -0.12843"
      rpy="0 0 0" />
    <parent
      link="upperarm" />
    <child
      link="upperarm_triceps_pulley" />
    <axis
      xyz="-1 0 0" />
    <limit
      effort="0"
      velocity="0" />
  </joint>
  <link
    name="shoulder_roll_top_pulley">
    <inertial>
      <origin
        xyz="-8.3904E-05 -3.1839E-09 -0.0093595"
        rpy="0 0 0" />
      <mass
        value="0.01522" />
      <inertia
        ixx="3.3488E-07"
        ixy="3.9438E-15"
        ixz="-3.7608E-09"
        iyy="3.3492E-07"
        iyz="3.5118E-13"
        izz="4.2234E-11" />
    </inertial>
    <visual>
      <origin
        xyz="0 0 0"
        rpy="0 0 0" />
      <geometry>
        <mesh
          filename="package://gummi_arm/meshes/shoulder_roll_top_pulley.STL" />
      </geometry>
      <material
        name="">
        <color
          rgba="0.79216 0.81961 0.93333 1" />
      </material>
    </visual>
    <collision>
      <origin
        xyz="0 0 0"
        rpy="0 0 0" />
      <geometry>
        <mesh
          filename="package://gummi_arm/meshes/shoulder_roll_top_pulley.STL" />
      </geometry>
    </collision>
  </link>
  <joint
    name="shoulder_roll_top_pulley_joint"
    type="fixed">
    <origin
      xyz="0.0208 -0.06848 0.043"
      rpy="0 0 0" />
    <parent
      link="shoulder" />
    <child
      link="shoulder_roll_top_pulley" />
    <axis
      xyz="0 0 0" />
  </joint>
  <link
    name="shoulder_roll_bottom_pulley">
    <inertial>
      <origin
        xyz="8.3904E-05 -3.1839E-09 0.0093595"
        rpy="0 0 0" />
      <mass
        value="0.01522" />
      <inertia
        ixx="3.3488E-07"
        ixy="-3.9438E-15"
        ixz="-3.7608E-09"
        iyy="3.3492E-07"
        iyz="-3.5118E-13"
        izz="4.2234E-11" />
    </inertial>
    <visual>
      <origin
        xyz="0 0 0"
        rpy="0 0 0" />
      <geometry>
        <mesh
          filename="package://gummi_arm/meshes/shoulder_roll_bottom_pulley.STL" />
      </geometry>
      <material
        name="">
        <color
          rgba="0.79216 0.81961 0.93333 1" />
      </material>
    </visual>
    <collision>
      <origin
        xyz="0 0 0"
        rpy="0 0 0" />
      <geometry>
        <mesh
          filename="package://gummi_arm/meshes/shoulder_roll_bottom_pulley.STL" />
      </geometry>
    </collision>
  </link>
  <joint
    name="shoulder_roll_bottom_pulley"
    type="fixed">
    <origin
      xyz="-0.0208 -0.06848 -0.043"
      rpy="0 0 0" />
    <parent
      link="shoulder" />
    <child
      link="shoulder_roll_bottom_pulley" />
    <axis
      xyz="0 0 -1" />
    <limit
      effort="0"
      velocity="0" />
  </joint>
  <link
    name="shoulder_pitch_front_pulley">
    <inertial>
      <origin
        xyz="-0.0087313 -9.2787E-11 -0.00016773"
        rpy="0 0 0" />
      <mass
        value="0.027251" />
      <inertia
        ixx="2.8324E-10"
        ixy="-6.4973E-15"
        ixz="-1.1745E-08"
        iyy="4.8733E-07"
        iyz="-1.5668E-16"
        izz="4.8705E-07" />
    </inertial>
    <visual>
      <origin
        xyz="0 0 0"
        rpy="0 0 0" />
      <geometry>
        <mesh
          filename="package://gummi_arm/meshes/shoulder_pitch_front_pulley.STL" />
      </geometry>
      <material
        name="">
        <color
          rgba="0.79216 0.81961 0.93333 1" />
      </material>
    </visual>
    <collision>
      <origin
        xyz="0 0 0"
        rpy="0 0 0" />
      <geometry>
        <mesh
          filename="package://gummi_arm/meshes/shoulder_pitch_front_pulley.STL" />
      </geometry>
    </collision>
  </link>
  <joint
    name="shoulder_pitch_pulley_front_joint"
    type="fixed">
    <origin
      xyz="0.067474 -0.024095 0.044"
      rpy="0 0 0" />
    <parent
      link="shoulder_preroll" />
    <child
      link="shoulder_pitch_front_pulley" />
    <axis
      xyz="0 0 0" />
  </joint>
  <link
    name="shoulder_pitch_back_pulley">
    <inertial>
      <origin
        xyz="0.0087313 9.2787E-11 -0.00016773"
        rpy="0 0 0" />
      <mass
        value="0.027251" />
      <inertia
        ixx="2.8324E-10"
        ixy="-6.4973E-15"
        ixz="1.1745E-08"
        iyy="4.8733E-07"
        iyz="1.5668E-16"
        izz="4.8705E-07" />
    </inertial>
    <visual>
      <origin
        xyz="0 0 0"
        rpy="0 0 0" />
      <geometry>
        <mesh
          filename="package://gummi_arm/meshes/shoulder_pitch_back_pulley.STL" />
      </geometry>
      <material
        name="">
        <color
          rgba="0.79216 0.81961 0.93333 1" />
      </material>
    </visual>
    <collision>
      <origin
        xyz="0 0 0"
        rpy="0 0 0" />
      <geometry>
        <mesh
          filename="package://gummi_arm/meshes/shoulder_pitch_back_pulley.STL" />
      </geometry>
    </collision>
  </link>
  <joint
    name="shoulder_pitch_back_pulley_joint"
    type="fixed">
    <origin
      xyz="-0.067526 -0.024095 0.044"
      rpy="0 0 0" />
    <parent
      link="shoulder_preroll" />
    <child
      link="shoulder_pitch_back_pulley" />
    <axis
      xyz="0 0 0" />
  </joint>
</robot>
