<?xml version="1.0" encoding="utf-8"?>
<!-- =================================================================================== -->
<!-- |    This document was autogenerated by xacro from /home/llach/tactile_ws/src/tiago_robot/tiago_description/robots/tiago.urdf.xacro | -->
<!-- |    EDITING THIS FILE BY HAND IS NOT RECOMMENDED                                 | -->
<!-- =================================================================================== -->
<!--
  Copyright (c) 2023, Incognite
  All rights reserved.
  Tiago for myGym
  This work is licensed under the Creative Commons Attribution-NonCommercial-NoDerivs 3.0 Unported License.
  To view a copy of this license, visit http://creativecommons.org/licenses/by-nc-nd/3.0/ or send a letter to
  Creative Commons, 444 Castro Street, Suite 900, Mountain View, California, 94041, USA.
-->
<robot name="tiago">
  <material name="Hey5DarkGrey">
    <color rgba="0.1 0.1 0.1 1.0"/>
  </material>
  <material name="Blue">
    <color rgba="0.0 0.0 0.8 1.0"/>
  </material>
  <material name="Green">
    <color rgba="0.0 0.8 0.0 1.0"/>
  </material>
  <material name="Grey">
    <color rgba="0.7 0.7 0.7 1.0"/>
  </material>
  <material name="LightGrey">
    <color rgba="0.9 0.9 0.9 1.0"/>
  </material>
  <material name="DarkGrey">
    <color rgba="0.1 0.1 0.1 1.0"/>
  </material>
  <material name="Red">
    <color rgba="0.8 0.0 0.0 1.0"/>
  </material>
  <material name="White">
    <color rgba="1.0 1.0 1.0 1.0"/>
  </material>
  <material name="Yellow">
    <color rgba="0.96 0.88 0.14 1.0"/>
  </material>
  <!-- Base -->
  <link name="base_link">
    <inertial>
      <origin rpy="0 0 0" xyz="-0.00000106 0.00000109 0.0000387"/>
      <mass value="28.26649"/>
      <inertia ixx="0.465408937" ixy="0.002160024" ixz="-0.001760255" iyy="0.483193291" iyz="-0.000655952" izz="0.550939703"/>
    </inertial>
    <visual>
      <origin rpy="0 0 0" xyz="0 0 0"/>
      <geometry>
        <mesh filename="meshes/base/base.stl"/>
      </geometry>
      <material name="White"/>
    </visual>
    <collision>
      <origin rpy="0 0 0" xyz="0 0 0"/>
      <geometry>
        <mesh filename="meshes/base/base_collision.stl"/>
      </geometry>
      <material name="White"/>
    </collision>
  </link>
  <!-- Base footprint -->
  <link name="base_footprint">
    <inertial>
      <origin rpy="0 0 0" xyz="0 0 0"/>
       <mass value="100.0"/>
       <inertia ixx="1" ixy="0" ixz="0" iyy="1" iyz="0" izz="1"/>
    </inertial>1
  </link>
  <joint name="base_footprint_joint" type="fixed">
    <origin rpy="0 0 0" xyz="0 0 0.0985"/>
    <child link="base_link"/>
    <parent link="base_footprint"/>
  </joint>
  <link name="base_cover_link">
    <inertial>
      <origin rpy="0 0 0" xyz="0.22414000000 0.00002000000 0.04681000000"/>
      <mass value="0.25821000000"/>
      <inertia ixx="0.00023719188" ixy="0.00000006119" ixz="-0.00000011799" iyy="0.00028335052" iyz="0.00000000774" izz="0.00038497063"/>
    </inertial>
    <visual>
      <origin rpy="0 0 0" xyz="0 0 0"/>
      <geometry>
        <mesh filename="meshes/base/base_ring.stl"/>
      </geometry>
      <material name="Orange"/>
    </visual>
  </link>
  <joint name="cover_joint" type="fixed">
    <parent link="base_footprint"/>
    <child link="base_cover_link"/>
    <origin rpy="0 0 0" xyz="0 0 0.13"/>
  </joint>
  <link name="wheel_right_link">
    <inertial>
      <origin rpy="0 0 0" xyz="0 0 -0.00207"/>
      <mass value="1.82362"/>
      <inertia ixx="0.00499743171" ixy="4.464e-08" ixz="-0.00000002245" iyy="0.00499741733" iyz="-1.64e-09" izz="0.00839239692"/>
    </inertial>
    <visual>
      <origin rpy="-0.0 0 0" xyz="0 0 0"/>
      <geometry>
        <mesh filename="meshes/wheels/wheel.stl"/>
      </geometry>
      <material name="DarkGrey"/>
    </visual>
    <collision>
      <origin rpy="0 0 0" xyz="0 0 0"/>
      <geometry>
        <sphere radius="0.0985"/>
        <!-- length="${width}"/> -->
      </geometry>
    </collision>
  </link>
  <link name="suspension_right_link">
    <inertial>
      <origin rpy="0 0 0" xyz="0 0 -0.02"/>
      <mass value="10"/>
      <inertia ixx="1.0" ixy="0" ixz="0" iyy="1.0" iyz="0" izz="1.0"/>
    </inertial>
    <kinematic>0</kinematic>
    <gravity>1</gravity>
  </link>
  <joint name="suspension_right_joint" type="fixed">
    <origin rpy="0 0 0" xyz="0 0 0"/>
    <axis xyz="0 0 1"/>
    <limit effort="100.0" lower="-0.005" upper="0.005" velocity="1.0"/>
    <child link="suspension_right_link"/>
    <parent link="base_link"/>
    <calibration rising="0.0"/>
    <dynamics damping="100"/>
    <safety_controller k_position="0" k_velocity="10" soft_lower_limit="-0.005" soft_upper_limit="0.005"/>
  </joint>
  <joint name="wheel_right_joint" type="fixed">
    <parent link="suspension_right_link"/>
    <child link="wheel_right_link"/>
    <origin rpy="-1.57079632679 0 0" xyz="0 -0.2022 0.0"/>
    <axis xyz="0 0 1"/>
    <limit effort="6.0" velocity="10.152284264"/>
  </joint>
  <link name="wheel_left_link">
    <inertial>
      <origin rpy="0 0 0" xyz="0 0 0.00207"/>
      <mass value="1.82362"/>
      <inertia ixx="0.00499743171" ixy="-4.464e-08" ixz="-0.00000002245" iyy="0.00499741733" iyz="1.64e-09" izz="0.00839239692"/>
    </inertial>
    <visual>
      <origin rpy="-3.14159265359 0 0" xyz="0 0 0"/>
      <geometry>
        <mesh filename="meshes/wheels/wheel.stl"/>
      </geometry>
      <material name="DarkGrey"/>
    </visual>
    <collision>
      <origin rpy="0 0 0" xyz="0 0 0"/>
      <geometry>
        <sphere radius="0.0985"/>
        <!-- length="${width}"/> -->
      </geometry>
    </collision>
  </link>
  <link name="suspension_left_link">
    <inertial>
      <origin rpy="0 0 0" xyz="0 0 -0.02"/>
      <mass value="10"/>
      <inertia ixx="1.0" ixy="0" ixz="0" iyy="1.0" iyz="0" izz="1.0"/>
    </inertial>
    <kinematic>0</kinematic>
    <gravity>1</gravity>
  </link>
  <joint name="suspension_left_joint" type="fixed">
    <origin rpy="0 0 0" xyz="0 0 0"/>
    <axis xyz="0 0 1"/>
    <limit effort="100.0" lower="-0.005" upper="0.005" velocity="1.0"/>
    <child link="suspension_left_link"/>
    <parent link="base_link"/>
    <calibration rising="0.0"/>
    <dynamics damping="100"/>
    <safety_controller k_position="0" k_velocity="10" soft_lower_limit="-0.005" soft_upper_limit="0.005"/>
  </joint>
  <joint name="wheel_left_joint" type="fixed">
    <parent link="suspension_left_link"/>
    <child link="wheel_left_link"/>
    <origin rpy="-1.57079632679 0 0" xyz="0 0.2022 0.0"/>
    <axis xyz="0 0 1"/>
    <limit effort="6.0" velocity="10.152284264"/>
  </joint>
  <link name="caster_front_right_1_link">
    <inertial>
      <origin rpy="0 0 0" xyz="-0.00634599 0.00005347 -0.02037519"/>
      <mass value="0.05144761"/>
      <inertia ixx="0.00001513" ixy="-0.00000003" ixz="0.00000267" iyy="0.00001309" iyz="-0.00000005" izz="0.00001198"/>
    </inertial>
    <visual>
      <origin rpy="0 0 0" xyz="0 0 0"/>
      <geometry>
        <mesh filename="meshes/wheels/caster_1.stl"/>
      </geometry>
      <material name="Grey"/>
    </visual>
    <!--collision>
        <origin xyz="0 0 0" rpy="0 0 0"/>
        <geometry>
          <cylinder radius="${radius}" length="${width}"/>
        </geometry>
      </collision-->
  </link>
  <link name="caster_front_right_2_link">
    <inertial>
      <origin rpy="0 0 0" xyz="0 0 0"/>
      <mass value="0.08855784"/>
      <inertia ixx="0.00001075" ixy="0" ixz="0" iyy="0.00001541" iyz="0" izz="0.00001075"/>
    </inertial>
    <visual>
      <origin rpy="0 0 0" xyz="0 0 0"/>
      <geometry>
        <mesh filename="meshes/wheels/caster_2.stl"/>
      </geometry>
      <material name="DarkGrey"/>
    </visual>
    <collision>
      <origin rpy="0 0 0" xyz="0 0 0"/>
      <geometry>
        <sphere radius="0.025"/>
      </geometry>
    </collision>
  </link>
  <joint name="caster_front_right_1_joint" type="fixed">
    <parent link="base_link"/>
    <child link="caster_front_right_1_link"/>
    <origin rpy="0 0 0" xyz="0.1695 -0.102 -0.0335"/>
    <axis xyz="0 0 1"/>
    <dynamics damping="0.005" friction="0.0"/>
  </joint>
  <joint name="caster_front_right_2_joint" type="fixed">
    <parent link="caster_front_right_1_link"/>
    <child link="caster_front_right_2_link"/>
    <origin rpy="-1.57079632679 0 0" xyz="-0.016 0.0000 -0.040"/>
    <axis xyz="0 0 1"/>
  </joint>
  <link name="caster_front_left_1_link">
    <inertial>
      <origin rpy="0 0 0" xyz="-0.00634599 0.00005347 -0.02037519"/>
      <mass value="0.05144761"/>
      <inertia ixx="0.00001513" ixy="-0.00000003" ixz="0.00000267" iyy="0.00001309" iyz="-0.00000005" izz="0.00001198"/>
    </inertial>
    <visual>
      <origin rpy="0 0 0" xyz="0 0 0"/>
      <geometry>
        <mesh filename="meshes/wheels/caster_1.stl"/>
      </geometry>
      <material name="Grey"/>
    </visual>
    <!--collision>
        <origin xyz="0 0 0" rpy="0 0 0"/>
        <geometry>
          <cylinder radius="${radius}" length="${width}"/>
        </geometry>
      </collision-->
  </link>
  <link name="caster_front_left_2_link">
    <inertial>
      <origin rpy="0 0 0" xyz="0 0 0"/>
      <mass value="0.08855784"/>
      <inertia ixx="0.00001075" ixy="0" ixz="0" iyy="0.00001541" iyz="0" izz="0.00001075"/>
    </inertial>
    <visual>
      <origin rpy="0 0 0" xyz="0 0 0"/>
      <geometry>
        <mesh filename="meshes/wheels/caster_2.stl"/>
      </geometry>
      <material name="DarkGrey"/>
    </visual>
    <collision>
      <origin rpy="0 0 0" xyz="0 0 0"/>
      <geometry>
        <sphere radius="0.025"/>
      </geometry>
    </collision>
  </link>
  <joint name="caster_front_left_1_joint" type="fixed">
    <parent link="base_link"/>
    <child link="caster_front_left_1_link"/>
    <origin rpy="0 0 0" xyz="0.1695 0.102 -0.0335"/>
    <axis xyz="0 0 1"/>
    <dynamics damping="0.005" friction="0.0"/>
  </joint>
  <joint name="caster_front_left_2_joint" type="fixed">
    <parent link="caster_front_left_1_link"/>
    <child link="caster_front_left_2_link"/>
    <origin rpy="-1.57079632679 0 0" xyz="-0.016 0.0000 -0.040"/>
    <axis xyz="0 0 1"/>
  </joint>
  <link name="caster_back_right_1_link">
    <inertial>
      <origin rpy="0 0 0" xyz="-0.00634599 0.00005347 -0.02037519"/>
      <mass value="0.05144761"/>
      <inertia ixx="0.00001513" ixy="-0.00000003" ixz="0.00000267" iyy="0.00001309" iyz="-0.00000005" izz="0.00001198"/>
    </inertial>
    <visual>
      <origin rpy="0 0 0" xyz="0 0 0"/>
      <geometry>
        <mesh filename="meshes/wheels/caster_1.stl"/>
      </geometry>
      <material name="Grey"/>
    </visual>
    <!--collision>
        <origin xyz="0 0 0" rpy="0 0 0"/>
        <geometry>
          <cylinder radius="${radius}" length="${width}"/>
        </geometry>
      </collision-->
  </link>
  <link name="caster_back_right_2_link">
    <inertial>
      <origin rpy="0 0 0" xyz="0 0 0"/>
      <mass value="0.08855784"/>
      <inertia ixx="0.00001075" ixy="0" ixz="0" iyy="0.00001541" iyz="0" izz="0.00001075"/>
    </inertial>
    <visual>
      <origin rpy="0 0 0" xyz="0 0 0"/>
      <geometry>
        <mesh filename="meshes/wheels/caster_2.stl"/>
      </geometry>
      <material name="DarkGrey"/>
    </visual>
    <collision>
      <origin rpy="0 0 0" xyz="0 0 0"/>
      <geometry>
        <sphere radius="0.025"/>
      </geometry>
    </collision>
  </link>
  <joint name="caster_back_right_1_joint" type="fixed">
    <parent link="base_link"/>
    <child link="caster_back_right_1_link"/>
    <origin rpy="0 0 0" xyz="-0.1735 -0.102 -0.0335"/>
    <axis xyz="0 0 1"/>
    <dynamics damping="0.005" friction="0.0"/>
  </joint>
  <joint name="caster_back_right_2_joint" type="fixed">
    <parent link="caster_back_right_1_link"/>
    <child link="caster_back_right_2_link"/>
    <origin rpy="-1.57079632679 0 0" xyz="-0.016 0.0000 -0.040"/>
    <axis xyz="0 0 1"/>
  </joint>
  <link name="caster_back_left_1_link">
    <inertial>
      <origin rpy="0 0 0" xyz="-0.00634599 0.00005347 -0.02037519"/>
      <mass value="0.05144761"/>
      <inertia ixx="0.00001513" ixy="-0.00000003" ixz="0.00000267" iyy="0.00001309" iyz="-0.00000005" izz="0.00001198"/>
    </inertial>
    <visual>
      <origin rpy="0 0 0" xyz="0 0 0"/>
      <geometry>
        <mesh filename="meshes/wheels/caster_1.stl"/>
      </geometry>
      <material name="Grey"/>
    </visual>
    <!--collision>
        <origin xyz="0 0 0" rpy="0 0 0"/>
        <geometry>
          <cylinder radius="${radius}" length="${width}"/>
        </geometry>
      </collision-->
  </link>
  <link name="caster_back_left_2_link">
    <inertial>
      <origin rpy="0 0 0" xyz="0 0 0"/>
      <mass value="0.08855784"/>
      <inertia ixx="0.00001075" ixy="0" ixz="0" iyy="0.00001541" iyz="0" izz="0.00001075"/>
    </inertial>
    <visual>
      <origin rpy="0 0 0" xyz="0 0 0"/>
      <geometry>
        <mesh filename="meshes/wheels/caster_2.stl"/>
      </geometry>
      <material name="DarkGrey"/>
    </visual>
    <collision>
      <origin rpy="0 0 0" xyz="0 0 0"/>
      <geometry>
        <sphere radius="0.025"/>
      </geometry>
    </collision>
  </link>
  <joint name="caster_back_left_1_joint" type="fixed">
    <parent link="base_link"/>
    <child link="caster_back_left_1_link"/>
    <origin rpy="0 0 0" xyz="-0.1735 0.102 -0.0335"/>
    <axis xyz="0 0 1"/>
    <dynamics damping="0.005" friction="0.0"/>
  </joint>
  <joint name="caster_back_left_2_joint" type="fixed">
    <parent link="caster_back_left_1_link"/>
    <child link="caster_back_left_2_link"/>
    <origin rpy="-1.57079632679 0 0" xyz="-0.016 0.0000 -0.040"/>
    <axis xyz="0 0 1"/>
  </joint>
  <!-- Bottom fixed part of column -->
  <link name="torso_fixed_link">
    <inertial>
      <origin rpy="0.00000 0.00000 0.00000" xyz="0.02435 -0.00464 0.15900"/>
      <mass value="14.01360"/>
      <inertia ixx="0.38341100000" ixy="0.00036400000" ixz="-0.02438900000" iyy="0.40577300000" iyz="-0.00078200000" izz="0.07699800000"/>
    </inertial>
    <visual>
      <origin rpy="0 0 0" xyz="0 0 0"/>
      <geometry>
        <mesh filename="meshes/torso/torso_fix.stl" scale="1 1 1"/>
      </geometry>
      <material name="LightGrey"/>
    </visual>
    <collision>
      <origin rpy="0 0 0" xyz="0.085 0.0 0.02"/>
      <geometry>
        <box size="0.4 0.25 0.04"/>
      </geometry>
    </collision>
    <collision>
      <origin rpy="0 0 0" xyz="0 0 0.05"/>
      <geometry>
        <box size="0.25 0.25 0.1"/>
      </geometry>
    </collision>
  </link>
  <joint name="torso_fixed_joint" type="fixed">
    <origin rpy="0 0 0" xyz="-0.062 0.0 0.193"/>
    <parent link="base_link"/>
    <child link="torso_fixed_link"/>
    <axis xyz="0 0 0"/>
  </joint>
  <!-- Middle extending  -->
  <link name="torso_fixed_column_link">
    <inertial>
      <origin rpy="0 0 0" xyz="0 0 0"/>
      <mass value="0.01"/>
      <inertia ixx="0.000001" ixy="0" ixz="0" iyy="0.000001" iyz="0" izz="0.000001"/>
    </inertial>
    <visual>
      <origin rpy="0 0 0" xyz="0 0 0.275"/>
      <geometry>
        <box size="0.18 0.2 0.55"/>
      </geometry>
      <material name="DarkGrey"/>
    </visual>
    <collision>
      <origin rpy="0 0 0" xyz="0 0 0.275"/>
      <geometry>
        <box size="0.23 0.23 0.55"/>
      </geometry>
      <material name="DarkGrey"/>
    </collision>
  </link>
  <joint name="torso_fixed_column_joint" type="fixed">
    <origin rpy="0 0 0" xyz="-0.062 0 0.195"/>
    <parent link="base_link"/>
    <child link="torso_fixed_column_link"/>
    <axis xyz="0 0 0"/>
  </joint>
  <link name="torso_lift_link">
    <inertial>
      <origin rpy="0.00000 0.00000 0.00000" xyz="0.04361 -0.00116 -0.17334"/>
      <mass value="6.93198"/>
      <inertia ixx="0.24487000000" ixy="-0.00145600000" ixz="-0.00974200000" iyy="0.24926900000" iyz="0.00828100000" izz="0.09039500000"/>
    </inertial>
    <!-- Lifting body -->
    <visual>
      <origin rpy="0 0 0" xyz="0 0 0"/>
      <geometry>
        <mesh filename="meshes/torso/torso_lift_with_arm.stl" scale="1 1 1"/>
      </geometry>
      <material name="White"/>
    </visual>
    <collision>
      <origin rpy="0 0 0" xyz="0 0 0"/>
      <geometry>
        <mesh filename="meshes/torso/torso_lift_collision_core.dae" scale="1 1 1"/>
      </geometry>
      <material name="LightGrey"/>
    </collision>
    <collision>
      <origin rpy="0 0 0" xyz="0 0 0"/>
      <geometry>
        <mesh filename="meshes/torso/torso_lift_collision_shoulder.dae" scale="1 1 1"/>
      </geometry>
      <material name="LightGrey"/>
    </collision>
    <collision>
      <origin rpy="0 0 0" xyz="0 0 0"/>
      <geometry>
        <mesh filename="meshes/torso/torso_lift_collision_neck.dae" scale="1 1 1"/>
      </geometry>
      <material name="LightGrey"/>
    </collision>
  </link>
  <joint name="torso_lift_joint" type="fixed">
    <origin rpy="0.0 0.0 0.0" xyz="0.0 0.0 0.597"/>
    <parent link="torso_fixed_link"/>
    <child link="torso_lift_link"/>
    <axis xyz="0 0 1"/>
    <limit effort="20" lower="0.0" upper="0.55" velocity="1"/>
  </joint>
  <link name="head_1_link">
    <inertial>
      <origin rpy="0.00000 0.00000 0.00000" xyz="-0.00508 0.00237 0.07229"/>
      <mass value="0.62220"/>
      <inertia ixx="0.00119200000" ixy="-0.00000700000" ixz="0.00009600000" iyy="0.00140200000" iyz="0.00000400000" izz="0.00088900000"/>
    </inertial>
    <visual>
      <origin rpy="0 0 0" xyz="0 0 0"/>
      <geometry>
        <mesh filename="meshes/head/head_1.stl" scale="1 1 1"/>
      </geometry>
      <material name="White"/>
    </visual>
    <collision>
      <origin rpy="0 0 0.0" xyz="0.0 0 0"/>
      <geometry>
        <mesh filename="meshes/head/head_1_collision.dae" scale="1 1 1"/>
      </geometry>
      <material name="White"/>
    </collision>
  </link>
  <joint name="head_1_joint" type="fixed">
    <parent link="torso_lift_link"/>
    <child link="head_1_link"/>
    <origin rpy="0 0 0" xyz="0.182 0.0 0.0"/>
    <axis xyz="0 0 1"/>
    <limit effort="5.197" lower="-1.308996939" upper="1.308996939" velocity="3.0"/>
    <dynamics damping="0.5" friction="1.0"/>
    <safety_controller k_position="20" k_velocity="20" soft_lower_limit="-1.238996939" soft_upper_limit="1.238996939"/>
  </joint>
  <link name="head_2_link">
    <inertial>
      <origin rpy="0.00000 0.00000 0.00000" xyz="0.04700 0.05542 0.00022"/>
      <mass value="0.66123"/>
      <inertia ixx="0.00462000000" ixy="0.00068900000" ixz="0.00000600000" iyy="0.00486100000" iyz="0.00000600000" izz="0.00313200000"/>
    </inertial>
    <visual>
      <origin rpy="0 0 0" xyz="0 0 0"/>
      <geometry>
        <mesh filename="meshes/head/head_2.stl" scale="1 1 1"/>
      </geometry>
      <material name="White"/>
    </visual>
    <collision>
      <origin rpy="0 0 0" xyz="0 0 0"/>
      <geometry>
        <mesh filename="meshes/head/head_2_collision.dae" scale="1 1 1"/>
      </geometry>
    </collision>
  </link>
  <joint name="head_2_joint" type="fixed">
    <parent link="head_1_link"/>
    <child link="head_2_link"/>
    <origin rpy="1.57079632679 0 0" xyz="0.005 0.0 0.098"/>
    <axis xyz="0 0 1"/>
    <limit effort="2.77" lower="-1.0471975512" upper="0.785398163397" velocity="3.0"/>
    <dynamics damping="0.5" friction="1.0"/>
    <safety_controller k_position="20" k_velocity="20" soft_lower_limit="-0.977197551197" soft_upper_limit="0.715398163397"/>
  </joint>
  <!--************************-->
  <!--        SHOULDER        -->
  <!--************************-->
  <link name="arm_1_link">
    <inertial>
      <origin rpy="0.00000 0.00000 0.00000" xyz="0.08169 0.01822 -0.01884"/>
      <mass value="2.31325"/>
      <inertia ixx="0.00269400000" ixy="0.00115700000" ixz="-0.00142300000" iyy="0.00704100000" iyz="-0.00031200000" izz="0.00731200000"/>
    </inertial>
    <!-- M90 module -->
    <visual>
      <origin rpy="0 0 0" xyz="0 0 0"/>
      <geometry>
        <mesh filename="meshes/arm/arm_1.stl" scale="1 1 1"/>
      </geometry>
      <material name="White"/>
    </visual>
  <!--  <collision>
      <origin rpy="0 0 0" xyz="0 0 0"/>
      <geometry>
        <mesh filename="meshes/arm/arm_1_collision.dae" scale="1 1 1"/>
      </geometry>
    </collision> -->
  </link>
  <joint name="arm_1_rjoint" type="revolute">
    <parent link="torso_lift_link"/>
    <child link="arm_1_link"/>
    <origin rpy="0 0 -1.57079632679" xyz="0.15505 0.014 -0.151"/>
    <axis xyz="0 0 1"/>
    <limit effort="39.0" lower="-2.74" upper="2.74889357189" velocity="2.7"/>
    <dynamics damping="1.0" friction="1.0"/>
  </joint>
  <link name="arm_2_link">
    <inertial>
      <origin rpy="0.00000 0.00000 0.00000" xyz="-0.03609 -0.00006 0.01649"/>
      <mass value="1.10224"/>
      <inertia ixx="0.00114600000" ixy="0.00000100000" ixz="0.00043500000" iyy="0.00218200000" iyz="-0.00000100000" izz="0.00237300000"/>
    </inertial>
    <visual>
      <!-- <origin xyz="0 0 0" rpy="${180 * deg_to_rad} ${0 * deg_to_rad} ${-90 * deg_to_rad}" /> -->
      <origin rpy="0.0 0.0 0.0" xyz="0 0 0"/>
      <geometry>
        <mesh filename="meshes/arm/arm_2.stl" scale="1 1 1"/>
      </geometry>
      <material name="DarkGrey"/>
    </visual>
    <collision>
      <!-- <origin xyz="0 0 0" rpy="${180 * deg_to_rad} ${0 * deg_to_rad} ${-90 * deg_to_rad}" /> -->
      <origin rpy="0.0 0.0 0.0" xyz="0 0 0"/>
      <geometry>
        <mesh filename="meshes/arm/arm_2_collision.dae" scale="1 1 1"/>
      </geometry>
    </collision>
  </link>
  <joint name="arm_2_rjoint" type="revolute">
    <parent link="arm_1_link"/>
    <child link="arm_2_link"/>
    <origin rpy="1.57079632679 0.0 0.0" xyz="0.125 0.0165 -0.031"/>
    <axis xyz="0 0 1"/>
    <limit effort="39.0" lower="-1.57079632679" upper="1.0908307825" velocity="3.66"/>
    <dynamics damping="1.0" friction="1.0"/>
  </joint>
  <link name="arm_3_link">
    <inertial>
      <origin rpy="0.00000 0.00000 0.00000" xyz="0.00752 0.00244 0.12957"/>
      <mass value="2.42460"/>
      <inertia ixx="0.01441800000" ixy="0.00008400000" ixz="0.00114300000" iyy="0.01478800000" iyz="0.00064200000" izz="0.00256000000"/>
    </inertial>
    <visual>
      <origin rpy="0 0 0" xyz="0 0 0"/>
      <geometry>
        <mesh filename="meshes/arm/arm_3.stl" scale="1 1 1"/>
      </geometry>
      <material name="DarkGrey"/>
    </visual>
    <collision>
      <origin rpy="0 0 0" xyz="0 0 0"/>
      <geometry>
        <mesh filename="meshes/arm/arm_3_collision.dae" scale="1 1 1"/>
      </geometry>
    </collision>
  </link>
  <joint name="arm_3_rjoint" type="revolute">
    <parent link="arm_2_link"/>
    <child link="arm_3_link"/>
    <origin rpy="-1.57079632679 0.0 1.57079632679" xyz="0.0895 0.0 0.0015"/>
    <axis xyz="0 0 1"/>
    <limit effort="17.86" lower="-3.53429173529" upper="1.57079632679" velocity="4.58"/>
    <dynamics damping="1.0" friction="1.0"/>
  </joint>
  <!--************************-->
  <!--        ELBOW           -->
  <!--************************-->
  <link name="arm_4_link">
    <inertial>
      <origin rpy="0.00000 0.00000 0.00000" xyz="0.07426 -0.01306 0.01549"/>
      <mass value="1.45429"/>
      <inertia ixx="0.00195300000" ixy="-0.00059600000" ixz="0.00088000000" iyy="0.00709700000" iyz="-0.00017100000" izz="0.00740500000"/>
    </inertial>
    <visual>
      <origin rpy="0 0 0" xyz="0 0 0"/>
      <geometry>
        <mesh filename="meshes/arm/arm_4.stl" scale="1 1 1"/>
      </geometry>
      <material name="DarkGrey"/>
    </visual>
    <collision>
      <origin rpy="0 0 0" xyz="0 0 0"/>
      <geometry>
        <mesh filename="meshes/arm/arm_4_collision.dae" scale="1 1 1"/>
      </geometry>
    </collision>
  </link>
  <joint name="arm_4_rjoint" type="revolute">
    <parent link="arm_3_link"/>
    <child link="arm_4_link"/>
    <origin rpy="-1.57079632679 -1.57079632679 0.0" xyz="-0.02 -0.027 -0.222"/>
    <axis xyz="0 0 1"/>
    <limit effort="17.86" lower="-0.392699081699" upper="2.35619449019" velocity="4.58"/>
    <dynamics damping="1.0" friction="1.0"/>
    <safety_controller k_position="20" k_velocity="20" soft_lower_limit="-0.372699081699" soft_upper_limit="2.33619449019"/>
  </joint>
  <!--************************-->
  <!--        WRIST           -->
  <!--************************-->
  <link name="arm_5_link">
    <inertial>
      <origin rpy="0.00000 0.00000 0.00000" xyz="0.00003 -0.00028 0.07831"/>
      <mass value="1.07424"/>
      <inertia ixx="0.00168000000" ixy="0.00000100000" ixz="-0.00001500000" iyy="0.00160300000" iyz="-0.00001900000" izz="0.00040400000"/>
    </inertial>
    <visual>
      <origin rpy="0 0 0" xyz="0 0 0"/>
      <geometry>
        <mesh filename="meshes/arm/arm_5.stl" scale="1 1 1"/>
      </geometry>
      <material name="LightGrey"/>
    </visual>
    <collision>
      <origin rpy="0 0 0" xyz="0 0 0"/>
      <geometry>
        <mesh filename="meshes/arm/arm_5_collision.dae" scale="1 1 1"/>
      </geometry>
    </collision>
  </link>
  <joint name="arm_5_rjoint" type="revolute">
    <parent link="arm_4_link"/>
    <child link="arm_5_link"/>
    <origin rpy="0.0 -1.57079632679 0.0" xyz="-0.162 0.02 0.027"/>
    <axis xyz="0 0 1"/>
    <limit effort="3" lower="-2.09439510239" upper="2.09439510239" velocity="1.95"/>
    <dynamics damping="1.0" friction="1.0"/>
    <safety_controller k_position="20" k_velocity="20" soft_lower_limit="-2.07439510239" soft_upper_limit="2.07439510239"/>
  </joint>
  <link name="arm_6_link">
    <inertial>
      <origin rpy="0.00000 0.00000 0.00000" xyz="0.00531 0.00021 0.00002"/>
      <mass value="0.28722"/>
      <inertia ixx="0.00005900000" ixy="-0.00000000000" ixz="-0.00000000000" iyy="0.00010600000" iyz="0.00000000000" izz="0.00012600000"/>
    </inertial>
    <visual>
      <origin rpy="0 0 0" xyz="0 0 0"/>
      <geometry>
        <mesh filename="meshes/arm/arm_6.stl" scale="1 1 1"/>
      </geometry>
      <material name="LightGrey"/>
    </visual>
    <collision>
      <origin rpy="0 0 0" xyz="0 0 0"/>
      <geometry>
        <mesh filename="meshes/arm/arm_6_collision.dae" scale="1 1 1"/>
      </geometry>
    </collision>
  </link>
  <joint name="arm_6_rjoint" type="revolute">
    <parent link="arm_5_link"/>
    <child link="arm_6_link"/>
    <origin rpy="0.0 -1.57079632679 -1.57079632679" xyz="0 0 0.15"/>
    <axis xyz="0 0 1"/>
    <limit effort="6.6" lower="-1.57079632679" upper="1.57079632679" velocity="1.76"/>
    <dynamics damping="1.0" friction="1.0"/>
    <safety_controller k_position="20" k_velocity="20" soft_lower_limit="-1.55079632679" soft_upper_limit="1.55079632679"/>
  </joint>
  <link name="arm_7_link">
    <inertial>
      <origin rpy="0.00000 0.00000 0.00000" xyz="0.00011 -0.00034 0.02405"/>
      <mass value="0.05935"/>
      <inertia ixx="0.00001400000" ixy="-0.00000000000" ixz="-0.00000000000" iyy="0.00001400000" iyz="0.00000000000" izz="0.00000400000"/>
    </inertial>
  </link>
  <joint name="arm_7_rjoint" type="revolute">
    <parent link="arm_6_link"/>
    <child link="arm_7_link"/>
    <origin rpy="1.57079632679 0.0 1.57079632679" xyz="0 0 0"/>
    <axis xyz="0 0 1"/>
    <limit effort="6.6" lower="-2.09439510239" upper="2.09439510239" velocity="1.76"/>
    <dynamics damping="1.0" friction="1.0"/>
    <safety_controller k_position="20" k_velocity="20" soft_lower_limit="-2.07439510239" soft_upper_limit="2.07439510239"/>
  </joint>
  <!--***********************-->
  <!--        TOOL           -->
  <!--***********************-->
  <link name="arm_tool_link">
    <inertial>
      <mass value="0.1"/>
      <inertia ixx="0.0" ixy="0.0" ixz="0.0" iyy="0.0" iyz="0.0" izz="0.0"/>
    </inertial>
    <visual>
      <origin rpy="0 1.57079632679 0" xyz="0.001 0 0"/>
      <geometry>
        <cylinder length="0.005" radius="0.005"/>
      </geometry>
      <material name="LightGrey"/>
    </visual>
    <collision>
      <origin rpy="0 1.57079632679 0" xyz="0.001 0 0"/>
      <geometry>
        <cylinder length="0.005" radius="0.005"/>
      </geometry>
    </collision>
  </link>
  <joint name="arm_tool_rjoint" type="fixed">
    <parent link="arm_7_link"/>
    <child link="arm_tool_link"/>
    <origin rpy="1.57079632679 -1.57079632679 3.14159265359" xyz="0 0 0.046"/>
  </joint>
  <link name="gripper_tool_link">
    <inertial>
      <origin rpy="0 0 0" xyz="0 0 0"/>
      <mass value="0.0001"/>
      <inertia ixx="0.00001" ixy="0.0" ixz="0.0" iyy="0.00001" iyz="0.0" izz="0.00001"/>
    </inertial>
  </link>
  <joint name="gripper_tool_gjoint" type="fixed">
    <origin rpy="1.57079632679 1.57079632679 -1.57079632679" xyz="0.01 0 0"/>
    <parent link="arm_tool_link"/>
    <child link="gripper_tool_link"/>
    <axis xyz="0 0 0"/>
  </joint>
  <link name="gripper_link">
    <inertial>
      <origin rpy="0.0 0.0 0.0" xyz="-0.000294 0.000291 -0.033086"/>
      <mass value="0.602660"/>
      <inertia ixx="0.000693" ixy="0.000045" ixz="-0.000000" iyy="0.001024" iyz="0.000000" izz="0.000672"/>
    </inertial>
    <visual>
      <origin rpy="0 0 0" xyz="0 0 0"/>
      <geometry>
        <mesh filename="meshes/gripper/gripper_link.stl"/>
      </geometry>
      <material name="White"/>
    </visual>
    <collision>
      <origin rpy="0 0 0" xyz="0 0 0"/>
      <geometry>
        <mesh filename="meshes/gripper/gripper_link_collision.stl"/>
      </geometry>
    </collision>
  </link>
  <joint name="gripper_gjoint" type="fixed">
    <origin rpy="1.57079632679 1.57079632679 -1.57079632679" xyz="0.01 0 0"/>
    <parent link="arm_tool_link"/>
    <child link="gripper_link"/>
    <axis xyz="0 0 0"/>
  </joint>
  <link name="gripper_right_finger_link">
    <inertial>
      <origin rpy="0 0 0" xyz="-0.004470 0.010766 -0.121013"/>
      <mass value="0.109980"/>
      <inertia ixx="0.000232" ixy="-0.000005" ixz="-0.000032" iyy="0.000224" iyz="0.000036" izz="0.000029"/>
    </inertial>
    <visual>
      <origin rpy="0 0 3.1415" xyz="0 0 0"/>
      <geometry>
        <mesh filename="meshes/gripper/gripper_finger_link.stl" scale="-1 -1 1"/>
      </geometry>
      <material name="White"/>
    </visual>
    <collision>
      <origin rpy="0 0 3.1415" xyz="0.005 0 -0.165"/>
      <geometry>
        <box size="0.01 0.05 0.11"/>
      </geometry>
    </collision>
  </link>
  <joint name="gripper_right_finger_gjoint" type="prismatic">
    <origin rpy="0 0 0" xyz="0. 0 0"/>
    <parent link="gripper_link"/>
    <child link="gripper_right_finger_link"/>
    <axis xyz="1 0 0"/>
    <limit effort="16" lower="0.0" upper="0.045" velocity="0.05"/>
    <calibration rising="0.0"/>
    <dynamics damping="80"/>
    <safety_controller k_position="20" k_velocity="20" soft_lower_limit="0.001" soft_upper_limit="0.044"/>
  </joint>
  <link name="gripper_left_finger_link">
    <inertial>
      <origin rpy="0 0 0" xyz="-0.004470 0.010766 -0.121013"/>
      <mass value="0.109980"/>
      <inertia ixx="0.000232" ixy="-0.000005" ixz="-0.000032" iyy="0.000224" iyz="0.000036" izz="0.000029"/>
    </inertial>
    <visual>
      <origin rpy="0 0 3.1415" xyz="0 0 0"/>
      <geometry>
        <mesh filename="meshes/gripper/gripper_finger_link.stl"/>
      </geometry>
      <material name="White"/>
    </visual>
    <collision>
      <origin rpy="0 0 3.1415" xyz="-0.005 0 -0.165"/>
      <geometry>
        <box size="0.01 0.05 0.11"/>
      </geometry>
    </collision>
  </link>
  <joint name="gripper_left_finger_gjoint" type="prismatic">
    <origin rpy="0 0 0" xyz="0. 0 0"/>
    <parent link="gripper_link"/>
    <child link="gripper_left_finger_link"/>
    <axis xyz="-1 0 0"/>
    <limit effort="16" lower="0" upper="0.045" velocity="0.05"/>
    <calibration rising="0.0"/>
    <dynamics damping="80"/>
    <safety_controller k_position="20" k_velocity="20" soft_lower_limit="0.001" soft_upper_limit="0.044"/>
  </joint>
  <!-- Grasping frame -->
  <joint name="gripper_grasping_frame_gjoint" type="fixed">
    <parent link="gripper_link"/>
    <child link="gripper"/>
    <origin rpy="-1.5708 1.5708 0" xyz="0 0 -0.12"/>
  </joint>
  <link name="gripper">
    <inertial>
      <origin rpy="0 0 0" xyz="0 0 0"/>
      <mass value="0.0001"/>
      <inertia ixx="0.00001" ixy="0.0" ixz="0.0" iyy="0.00001" iyz="0.0" izz="0.00001"/>
    </inertial>
  </link>
  <joint name="endeffector_gjoint" type="fixed">
    <parent link="gripper"/>
    <child link="endeffector"/>
    <origin rpy="0 0 0" xyz="0.04 0 0"/>
  </joint>
  <link name="endeffector">
    <visual>
      <origin rpy="0 0 0" xyz="0.08 0.0 0.0"/>
      <geometry>
        <sphere radius="0.01"/>
      </geometry>
      <material name="LightGrey"/>
    </visual>
  </link>
</robot>


