<?xml version="1.0" encoding="utf-8"?>
<!-- =================================================================================== -->
<!-- |    This document was autogenerated by xacro from tiago_dual.urdf.xacro          | -->
<!-- |    EDITING THIS FILE BY HAND IS NOT RECOMMENDED                                 | -->
<!-- =================================================================================== -->
<!--
  Copyright (c) 2019, PAL Robotics, S.L.
  All rights reserved.

  This work is licensed under the Creative Commons Attribution-NonCommercial-NoDerivs 3.0 Unported License.
  To view a copy of this license, visit http://creativecommons.org/licenses/by-nc-nd/3.0/ or send a letter to
  Creative Commons, 444 Castro Street, Suite 900, Mountain View, California, 94041, USA.
-->
<robot name="tiago_dual_mygym">
  <material name="Hey5DarkGrey">
    <color rgba="0.1 0.1 0.1 1.0"/>
  </material>
  <material name="Blue">
    <color rgba="0.0 0.0 0.8 1.0"/>
  </material>
  <material name="Green">
    <color rgba="0.0 0.8 0.0 1.0"/>
  </material>
  <material name="Grey">
    <color rgba="0.7 0.7 0.7 1.0"/>
  </material>
  <material name="LightGrey">
    <color rgba="0.7 0.7 0.7 1.0"/>
  </material>
  <material name="DarkGrey">
    <color rgba="0.1 0.1 0.1 1.0"/>
  </material>
  <material name="Red">
    <color rgba="0.8 0.0 0.0 1.0"/>
  </material>
  <material name="Orange">
    <color rgba="1.0 0.35 0.0 1.0"/>
  </material>
  <material name="Black">
    <color rgba="0.0 0.0 0.0 1.0"/>
  </material>  
  <material name="White">
    <color rgba="1.0 1.0 1.0 1.0"/>
  </material>
  <material name="Yellow">
    <color rgba="0.96 0.88 0.14 1.0"/>
  </material>  
  <!-- World link -->
  <link name="world"/>
  <!-- Base footprint -->
  <link name="base_footprint">
      <origin rpy="0 0 0" xyz="0 0 0"/>
  </link>
  <joint name="baseslide_rjoint" type="fixed">
    <origin rpy="0 0 0" xyz="0. 0 0"/>
    <parent link="world"/>
    <child link="base_footprint"/>
    <axis xyz="0 1 0"/>
    <limit effort="500" lower="-0.5" upper="0.5" velocity="1"/>
  </joint>
  <!-- Base -->
  <link name="base_link">
    <inertial>
      <origin rpy="0 0 0" xyz="-0.00000106 0.00000109 0.0000387"/>
      <mass value="28.26649"/>
      <inertia ixx="0.465408937" ixy="0.002160024" ixz="-0.001760255" iyy="0.483193291" iyz="-0.000655952" izz="0.550939703"/>
    </inertial>
    <visual>
      <origin rpy="0 0 0" xyz="0 0 0"/>
      <geometry>
        <mesh filename="package://pmb2_description/meshes/base/base.stl"/>
      </geometry>
      <material name="White"/>
    </visual>
  </link>
  <joint name="baserot_rjoint" type="revolute">
    <origin rpy="0 0 0" xyz="0 0 0"/>
    <child link="base_link"/>
    <parent link="base_footprint"/>
    <axis xyz="0 0 1"/>
    <limit effort="100" lower="-1.9780972451" upper="3.14159265359" velocity="2"/>
  </joint>
  <!-- Bottom fixed part of column -->
  <link name="torso_fixed_link">
    <inertial>
      <origin rpy="0.00000 0.00000 0.00000" xyz="0.02435 -0.00464 0.15900"/>
      <mass value="14.01360"/>
      <inertia ixx="0.38341100000" ixy="0.00036400000" ixz="-0.02438900000" iyy="0.40577300000" iyz="-0.00078200000" izz="0.07699800000"/>
    </inertial>
    <visual>
      <origin rpy="0 0 0" xyz="0 0 0"/>
      <geometry>
        <mesh filename="package://tiago_dual_description/meshes/torso/torso_fix.stl" scale="1 1 1"/>
      </geometry>
      <material name="LightGrey"/>
    </visual>
  </link>
  <joint name="torso_fixed_joint" type="fixed">
    <origin rpy="0 0 0" xyz="-0.062 0.0 0.193"/>
    <parent link="base_link"/>
    <child link="torso_fixed_link"/>
    <axis xyz="0 0 0"/>
  </joint>
  <!-- Middle extending  -->
  <link name="torso_fixed_column_link">
    <inertial>
      <origin rpy="0 0 0" xyz="0 0 0"/>
      <mass value="0.01"/>
      <inertia ixx="0.000001" ixy="0" ixz="0" iyy="0.000001" iyz="0" izz="0.000001"/>
    </inertial>
    <visual>
      <origin rpy="0 0 0" xyz="0 0 0.275"/>
      <geometry>
        <box size="0.18 0.2 0.55"/>
      </geometry>
      <material name="DarkGrey"/>
    </visual>
  </link>
  <joint name="torso_fixed_column_joint" type="fixed">
    <origin rpy="0 0 0" xyz="-0.062 0 0.195"/>
    <parent link="base_link"/>
    <child link="torso_fixed_column_link"/>
    <axis xyz="0 0 0"/>
  </joint>
  <link name="torso_lift_link">
    <inertial>
      <origin rpy="0.00000 0.00000 0.00000" xyz="0.04361 -0.00116 -0.17334"/>
      <mass value="9.594213"/>
      <inertia ixx="0.326395" ixy="-0.000844" ixz="-0.018905" iyy="0.235332" iyz="0.009042" izz="0.176168"/>
    </inertial>
    <!-- Lifting body -->
    <visual>
      <origin rpy="0 0 0" xyz="0 0 0"/>
      <geometry>
        <mesh filename="package://tiago_dual_description/meshes/torso/torso_lift_dual_arm.stl" scale="1 1 1"/>
      </geometry>
      <material name="White"/>
    </visual>
    <collision>
      <origin rpy="0 0 0" xyz="0 0 0"/>
      <geometry>
        <mesh filename="package://tiago_dual_description/meshes/torso/torso_lift_dual_arm.stl" scale="1 1 1"/>
      </geometry>
      <material name="White"/>
    </collision>
  </link>
  <joint name="torso_lift_joint" type="fixed">
    <origin rpy="0.0 0.0 0.0" xyz="0.0 0.0 0.95"/>
    <parent link="torso_fixed_link"/>
    <child link="torso_lift_link"/>
    <axis xyz="0 0 1"/>
    <limit effort="2000" lower="0.349" upper="0.35" velocity="5"/>
    <calibration rising="0.0"/>
    <dynamics damping="1000"/>
    <safety_controller k_position="20" k_velocity="20" soft_lower_limit="0.0" soft_upper_limit="0.35"/>
  </joint>
  <link name="head_1_link">
    <inertial>
      <origin rpy="0.00000 0.00000 0.00000" xyz="-0.00508 0.00237 0.07229"/>
      <mass value="0.62220"/>
      <inertia ixx="0.00119200000" ixy="-0.00000700000" ixz="0.00009600000" iyy="0.00140200000" iyz="0.00000400000" izz="0.00088900000"/>
    </inertial>
    <visual>
      <origin rpy="0 0 0" xyz="0 0 0"/>
      <geometry>
        <mesh filename="package://tiago_description/meshes/head/head_1.stl" scale="1 1 1"/>
      </geometry>
      <material name="White"/>
    </visual>
    <collision>
      <origin rpy="0 0 0.0" xyz="0.0 0 0"/>
      <geometry>
        <mesh filename="package://tiago_description/meshes/head/head_1_collision.dae" scale="1 1 1"/>
      </geometry>
      <material name="White"/>
    </collision>
  </link>
  <joint name="head_1_joint" type="fixed">
    <parent link="torso_lift_link"/>
    <child link="head_1_link"/>
    <origin rpy="0 0 0" xyz="0.182 0.0 0.0"/>
    <axis xyz="0 0 1"/>
    <limit effort="5.197" lower="-1.308996939" upper="1.308996939" velocity="3.0"/>
    <dynamics damping="0.5" friction="1.0"/>
    <safety_controller k_position="20" k_velocity="20" soft_lower_limit="-1.238996939" soft_upper_limit="1.238996939"/>
  </joint>
  <link name="head_2_link">
    <inertial>
      <origin rpy="0.00000 0.00000 0.00000" xyz="0.04700 0.05542 0.00022"/>
      <mass value="0.66123"/>
      <inertia ixx="0.00462000000" ixy="0.00068900000" ixz="0.00000600000" iyy="0.00486100000" iyz="0.00000600000" izz="0.00313200000"/>
    </inertial>
    <visual>
      <origin rpy="0 0 0" xyz="0 0 0"/>
      <geometry>
        <mesh filename="package://tiago_description/meshes/head/head_2.stl" scale="1 1 1"/>
      </geometry>
      <material name="White"/>
    </visual>
    <collision>
      <origin rpy="0 0 0" xyz="0 0 0"/>
      <geometry>
        <mesh filename="package://tiago_description/meshes/head/head_2_collision.dae" scale="1 1 1"/>
      </geometry>
    </collision>
  </link>
  <joint name="head_2_joint" type="fixed">
    <parent link="head_1_link"/>
    <child link="head_2_link"/>
    <origin rpy="1.57079632679 0 0" xyz="0.005 0.0 0.098"/>
    <axis xyz="0 0 1"/>
    <limit effort="2.77" lower="-1.0471975512" upper="0.785398163397" velocity="3.0"/>
    <dynamics damping="0.5" friction="1.0"/>
    <safety_controller k_position="20" k_velocity="20" soft_lower_limit="-0.977197551197" soft_upper_limit="0.785398163397"/>
  </joint>
  <!--************************-->
  <!--        SHOULDER        -->
  <!--************************-->
  <link name="arm_left_1_link">
    <inertial>
      <origin rpy="0.00000 0.00000 0.00000" xyz="0.061191 -0.022397 0.012835"/>
      <mass value="1.563428"/>
      <inertia ixx="0.002471" ixy="0.001809" ixz="-0.001202" iyy="0.006132" iyz="-0.000494" izz="0.006704"/>
    </inertial>
    <!-- M90 module -->
    <visual>
      <origin rpy="0 0 0" xyz="0 0 0"/>
      <geometry>
        <mesh filename="package://tiago_description/meshes/arm/arm_1.stl" scale="1 -1 -1"/>
      </geometry>
      <material name="White"/>
    </visual>
  </link>
  <joint name="arm_left_1_joint" type="fixed">
    <parent link="torso_lift_link"/>
    <child link="arm_left_1_link"/>
    <origin rpy="3.14159265359 0 2.9" xyz="0.02556 0.19 -0.171"/>
    <axis xyz="0 0 1"/>
    <limit effort="43.0" lower="-1.1780972451" upper="1.57079632679" velocity="1.95"/>
  </joint>
  <link name="arm_left_2_link">
    <inertial>
      <origin rpy="0.00000 0.00000 0.00000" xyz="0.030432 0.000229 0.005942"/>
      <mass value="1.800397"/>
      <inertia ixx="0.001809" ixy="-1.5e-05" ixz="-0.000254" iyy="0.004333" iyz="-1.4e-05" izz="0.004341"/>
    </inertial>
    <visual>
      <!-- <origin xyz="0 0 0" rpy="${180 * deg_to_rad} ${0 * deg_to_rad} ${-90 * deg_to_rad}" /> -->
      <origin rpy="0.0 0.0 0.0" xyz="0 0 0"/>
      <geometry>
        <mesh filename="package://tiago_description/meshes/arm/arm_2.stl" scale="1 1 -1"/>
      </geometry>
      <material name="DarkGrey"/>
    </visual>
  </link>
  <joint name="arm_left_2_joint" type="fixed">
    <parent link="arm_left_1_link"/>
    <child link="arm_left_2_link"/>
    <origin rpy="1.57079632679 -1.57079632679 0.0" xyz="0.125 -0.0195 0.031"/>
    <axis xyz="0 0 1"/>
    <limit effort="43.0" lower="-1.1780972451" upper="1.57079632679" velocity="1.95"/>
  </joint>
  <link name="arm_left_3_link">
    <inertial>
      <origin rpy="0.00000 0.00000 0.00000" xyz="0.007418 -0.004361 0.134194"/>
      <mass value="2.343502"/>
      <inertia ixx="0.019541" ixy="-0.000105" ixz="-0.001717" iyy="0.019936" iyz="-0.000852" izz="0.002864"/>
    </inertial>
    <visual>
      <origin rpy="0 0 0" xyz="0 0 0"/>
      <geometry>
        <mesh filename="package://tiago_description/meshes/arm/arm_3.stl" scale="1 1 -1"/>
      </geometry>
      <material name="DarkGrey"/>
    </visual>
  </link>
  <joint name="arm_left_3_joint" type="fixed">
    <parent link="arm_left_2_link"/>
    <child link="arm_left_3_link"/>
    <origin rpy="-1.57079632679 2.9 -1.57079632679" xyz="0.0895 0.0 -0.0015"/>
    <axis xyz="0 0 1"/>
    <limit effort="26" lower="-0.785398163397" upper="3.92699081699" velocity="2.35"/>
  </joint>
  <!--************************-->
  <!--        ELBOW           -->
  <!--************************-->
  <link name="arm_left_4_link">
    <inertial>
      <origin rpy="0.00000 0.00000 0.00000" xyz="0.095658 -0.014666 0.018133"/>
      <mass value="1.432697"/>
      <inertia ixx="0.002040" ixy="-0.000725" ixz="0.00115" iyy="0.008424" iyz="-0.000204" izz="0.008686"/>
    </inertial>
    <visual>
      <origin rpy="0 0 0" xyz="0 0 0"/>
      <geometry>
        <mesh filename="package://tiago_description/meshes/arm/arm_4.stl" scale="-1 -1 -1"/>
      </geometry>
      <material name="DarkGrey"/>
    </visual>
  </link>
  <joint name="arm_left_4_joint" type="fixed">
    <parent link="arm_left_3_link"/>
    <child link="arm_left_4_link"/>
    <origin rpy="1.57079632679 0.785 0.0" xyz="-0.02 -0.027 0.222"/>
    <axis xyz="0 0 1"/>
    <limit effort="26" lower="-0.392699081699" upper="2.35619449019" velocity="2.35"/>
  </joint>

  <!--************************-->
  <!--        WRIST           -->
  <!--************************-->
  <link name="arm_left_5_link">
    <inertial>
      <origin rpy="0.00000 0.00000 0.00000" xyz="0.001078 -0.000151 0.077173"/>
      <mass value="1.655819"/>
      <inertia ixx="0.00613800000" ixy="-0.00000400000" ixz="0.00015600000" iyy="0.00564000000" iyz="0.00002200000" izz="0.00179700000"/>
    </inertial>
    <visual>
      <origin rpy="0 0 0" xyz="0 0 0"/>
      <geometry>
        <mesh filename="package://tiago_description/meshes/arm/arm_5-wrist-2017.stl" scale="-1 -1 -1"/>
      </geometry>
      <material name="LightGrey"/>
    </visual>

  </link>
  <joint name="arm_left_5_joint" type="fixed">
    <parent link="arm_left_4_link"/>
    <child link="arm_left_5_link"/>
    <origin rpy="1.57079632679 -1.57079632679 -1.57079632679" xyz="0.162 -0.02 -0.027"/>
    <axis xyz="0 0 1"/>
    <limit effort="3" lower="-2.09439510239" upper="2.09439510239" velocity="1.95"/>
  </joint>
  <link name="arm_left_6_link">
    <inertial>
      <origin rpy="0.00000 0.00000 0.00000" xyz="-0.000153 -0.003122 0.000183"/>
      <mass value="0.370063"/>
      <inertia ixx="0.00021500000" ixy="0.00000000000" ixz="0.00000000000" iyy="0.00017000000" iyz="0.00000200000" izz="0.00017400000"/>
    </inertial>
    <visual>
      <origin rpy="0 0 0" xyz="0 0 0"/>
      <geometry>
        <mesh filename="package://tiago_description/meshes/arm/arm_6-wrist-2017.stl" scale="-1 1 1"/>
      </geometry>
      <material name="LightGrey"/>
    </visual>
  </link>
  <joint name="arm_left_6_joint" type="fixed">
    <parent link="arm_left_5_link"/>
    <child link="arm_left_6_link"/>
    <origin rpy="0.0 -1.57079632679 -1.57079632679" xyz="0 0 -0.15"/>
    <axis xyz="0 0 1"/>
    <limit effort="6.6" lower="-1.41371669412" upper="1.41371669412" velocity="1.76"/>
  </joint>
  <link name="arm_left_7_link">
    <inertial>
      <origin rpy="0.00000 0.00000 0.00000" xyz="0.000010 -0.000003 -0.007774"/>
      <mass value="0.234252"/>
      <inertia ixx="0.00014200000" ixy="0.00000000000" ixz="0.00000000000" iyy="0.00011300000" iyz="0.00000000000" izz="0.00005200000"/>
    </inertial>
  </link>
  <joint name="arm_left_7_joint" type="fixed">
    <parent link="arm_left_6_link"/>
    <child link="arm_left_7_link"/>
    <origin rpy="1.57079632679 0.0 1.57079632679" xyz="0 0 0"/>
    <axis xyz="0 0 1"/>
    <limit effort="6.6" lower="-2.09439510239" upper="2.09439510239" velocity="1.76"/>
  </joint>
  <!--***********************-->
  <!--        TOOL           -->
  <!--***********************-->
  <link name="arm_left_tool_link">
    <inertial>
      <mass value="0.1"/>
      <inertia ixx="0.0" ixy="0.0" ixz="0.0" iyy="0.0" iyz="0.0" izz="0.0"/>
    </inertial>
    <visual>
      <origin rpy="0 1.57079632679 0" xyz="0.001 0 0"/>
      <geometry>
        <cylinder length="0.005" radius="0.005"/>
      </geometry>
      <material name="LightGrey"/>
    </visual>
  </link>
  <joint name="arm_left_tool_joint" type="fixed">
    <parent link="arm_left_7_link"/>
    <child link="arm_left_tool_link"/>
    <origin rpy="1.57079632679 1.57079632679 3.14159265359" xyz="0 0 -0.046"/>
  </joint>
  <!--************************-->
  <!--        ft sensor       -->
  <!--************************-->
  <link name="wrist_left_ft_link">
    <inertial>
      <mass value="0.1"/>
      <inertia ixx="0.0" ixy="0.0" ixz="0.0" iyy="0.0" iyz="0.0" izz="0.0"/>
    </inertial>
    <visual>
      <origin rpy="0 0 0" xyz="0 0 0"/>
      <geometry>
        <cylinder length="0.0157" radius="0.0225"/>
      </geometry>
      <material name="LightGrey"/>
    </visual>
  </link>
  <joint name="wrist_left_ft_joint" type="fixed">
    <parent link="arm_left_tool_link"/>
    <child link="wrist_left_ft_link"/>
    <origin rpy="1.57079632679 0 1.57079632679" xyz="0.00785 0 0"/>
  </joint>
  <!--***********************-->
  <!--       FT TOOL         -->
  <!--***********************-->
  <link name="wrist_left_ft_tool_link">
    <inertial>
      <mass value="0.1"/>
      <inertia ixx="0.0" ixy="0.0" ixz="0.0" iyy="0.0" iyz="0.0" izz="0.0"/>
    </inertial>
    <visual>
      <origin rpy="0 1.57079632679 0" xyz="0.0 0 0"/>
      <geometry>
        <cylinder length="0.00975" radius="0.025"/>
      </geometry>
      <material name="FlatBlack"/>
    </visual>
  </link>
  <joint name="wrist_left_tool_joint" type="fixed">
    <parent link="wrist_left_ft_link"/>
    <child link="wrist_left_ft_tool_link"/>
    <origin rpy="-1.57079632679 -1.57079632679 0" xyz="0 0 0.012725"/>
  </joint>
  <link name="gripper_left_tool_link">
    <inertial>
      <origin rpy="0 0 0" xyz="0 0 0"/>
      <mass value="0.0001"/>
      <inertia ixx="0.00001" ixy="0.0" ixz="0.0" iyy="0.00001" iyz="0.0" izz="0.00001"/>
    </inertial>
  </link>
  <joint name="gripper_left_tool_joint" type="fixed">
    <origin rpy="1.57079632679 1.57079632679 -1.57079632679" xyz="0.01 0 0"/>
    <parent link="wrist_left_ft_tool_link"/>
    <child link="gripper_left_tool_link"/>
    <axis xyz="0 0 0"/>
  </joint>
  <link name="gripper_left_link">
    <inertial>
      <origin rpy="0.0 0.0 0.0" xyz="-0.000294 0.000291 -0.033086"/>
      <mass value="0.602660"/>
      <inertia ixx="0.000693" ixy="0.000045" ixz="-0.000000" iyy="0.001024" iyz="0.000000" izz="0.000672"/>
    </inertial>
    <visual>
      <origin rpy="0 0 0" xyz="0 0 0"/>
      <geometry>
        <mesh filename="package://pal_gripper_description/meshes/gripper_link.stl"/>
      </geometry>
      <material name="White"/>
    </visual>
  </link>
  <joint name="gripper_left_joint" type="fixed">
    <origin rpy="1.57079632679 1.57079632679 -1.57079632679" xyz="0.01 0 0"/>
    <parent link="wrist_left_ft_tool_link"/>
    <child link="gripper_left_link"/>
    <axis xyz="0 0 0"/>
  </joint>
  <link name="gripper_left_right_finger_link">
    <inertial>
      <origin rpy="0 0 0" xyz="-0.004470 0.010766 -0.121013"/>
      <mass value="0.109980"/>
      <inertia ixx="0.000232" ixy="-0.000005" ixz="-0.000032" iyy="0.000224" iyz="0.000036" izz="0.000029"/>
    </inertial>
    <visual>
      <origin rpy="0 0 3.1415" xyz="0 0 0"/>
      <geometry>
        <mesh filename="package://pal_gripper_description/meshes/gripper_finger_link.stl" scale="-1 -1 1"/>
      </geometry>
      <material name="Black"/>
    </visual>
  </link>
  <joint name="gripper_left_right_finger_joint" type="fixed">
    <origin rpy="0 0 0" xyz="0. 0 0"/>
    <parent link="gripper_left_link"/>
    <child link="gripper_left_right_finger_link"/>
    <axis xyz="1 0 0"/>
    <limit effort="16" lower="0.0" upper="0.045" velocity="0.05"/>
    <calibration rising="0.0"/>
    <dynamics damping="80"/>
    <safety_controller k_position="20" k_velocity="20" soft_lower_limit="0.001" soft_upper_limit="0.044"/>
  </joint>
  <link name="gripper_left_left_finger_link">
    <inertial>
      <origin rpy="0 0 0" xyz="-0.004470 0.010766 -0.121013"/>
      <mass value="0.109980"/>
      <inertia ixx="0.000232" ixy="-0.000005" ixz="-0.000032" iyy="0.000224" iyz="0.000036" izz="0.000029"/>
    </inertial>
    <visual>
      <origin rpy="0 0 3.1415" xyz="0 0 0"/>
      <geometry>
        <mesh filename="package://pal_gripper_description/meshes/gripper_finger_link.stl"/>
      </geometry>
      <material name="Black"/>
    </visual>
  </link>
  <joint name="gripper_left_left_finger_joint" type="fixed">
    <origin rpy="0 0 0" xyz="0. 0 0"/>
    <parent link="gripper_left_link"/>
    <child link="gripper_left_left_finger_link"/>
    <axis xyz="-1 0 0"/>
    <limit effort="16" lower="0" upper="0.045" velocity="0.05"/>
  </joint>
  <!--************************-->
  <!--        SHOULDER        -->
  <!--************************-->
  <link name="arm_right_1_link">
    <inertial>
      <!--<origin xyz="0.061191 ${reflect * -0.022397} -0.012835" rpy="0.00000 0.00000 0.00000"/>-->
      <origin rpy="0.00000 0.00000 0.00000" xyz="0.061191 -0.022397 -0.012835"/>
      <mass value="1.563428"/>
      <inertia ixx="0.002471" ixy="-0.001809" ixz="-0.001202" iyy="0.006132" iyz="0.000494" izz="0.006704"/>
    </inertial>
    <!-- M90 module -->
    <visual>
      <origin rpy="0 0 0" xyz="0 0 0"/>
      <geometry>
        <mesh filename="package://tiago_description/meshes/arm/arm_1.stl" scale="1 -1 1"/>
      </geometry>
      <material name="White"/>
    </visual>
  </link>
  <joint name="arm_right_1_rjoint" type="revolute">
    <parent link="torso_lift_link"/>
    <child link="arm_right_1_link"/>
    <origin rpy="0 0 -1.57079632679" xyz="0.02556 -0.19 -0.171"/>
    <axis xyz="0 0 1"/>
    <limit effort="43.0" lower="-1.1780972451" upper="1.57079632679" velocity="1.95"/>
  </joint>
  <link name="arm_right_2_link">
    <inertial>
      <origin rpy="0.00000 0.00000 0.00000" xyz="0.030432 0.000229 -0.005942"/>
      <mass value="1.800397"/>
      <inertia ixx="0.001809" ixy="1.5e-05" ixz="0.000254" iyy="0.004333" iyz="1.4e-05" izz="0.004341"/>
    </inertial>
    <visual>
      <!-- <origin xyz="0 0 0" rpy="${180 * deg_to_rad} ${0 * deg_to_rad} ${-90 * deg_to_rad}" /> -->
      <origin rpy="0.0 0.0 0.0" xyz="0 0 0"/>
      <geometry>
        <mesh filename="package://tiago_description/meshes/arm/arm_2.stl" scale="1 1 1"/>
      </geometry>
      <material name="DarkGrey"/>
    </visual>
    <collision>
      <!-- <origin xyz="0 0 0" rpy="${180 * deg_to_rad} ${0 * deg_to_rad} ${-90 * deg_to_rad}" /> -->
      <origin rpy="0.0 0.0 0.0" xyz="0 0 0"/>
      <geometry>
        <mesh filename="package://tiago_description/meshes/arm/arm_2_collision.dae" scale="1 1 1"/>
      </geometry>
    </collision>
  </link>
  <joint name="arm_right_2_rjoint" type="revolute">
    <parent link="arm_right_1_link"/>
    <child link="arm_right_2_link"/>
    <origin rpy="-1.57079632679 1.57 0.0" xyz="0.125 -0.0195 -0.031"/>
    <axis xyz="0 0 1"/>
    <limit effort="43.0" lower="-3.14" upper="0" velocity="1.95"/>
  </joint>
  <link name="arm_right_3_link">
    <inertial>
      <origin rpy="0.00000 0.00000 0.00000" xyz="0.007418 -0.004361 -0.134194"/>
      <mass value="2.343502"/>
      <inertia ixx="0.019541" ixy="-0.000105" ixz="-0.001717" iyy="0.019936" iyz="0.000852" izz="0.002864"/>
    </inertial>
    <visual>
      <origin rpy="0 0 0" xyz="0 0 0"/>
      <geometry>
        <mesh filename="package://tiago_description/meshes/arm/arm_3.stl" scale="1 1 1"/>
      </geometry>
      <material name="DarkGrey"/>
    </visual>
    <collision>
      <origin rpy="0 0 0" xyz="0 0 0"/>
      <geometry>
        <mesh filename="package://tiago_description/meshes/arm/arm_3_collision.dae" scale="1 1 1"/>
      </geometry>
    </collision>
  </link>
  <joint name="arm_right_3_rjoint" type="revolute">
    <parent link="arm_right_2_link"/>
    <child link="arm_right_3_link"/>
    <origin rpy="-1.57079632679 1.5707 1.57079632679" xyz="0.0895 0.0 -0.0015"/>
    <axis xyz="0 0 1"/>
    <limit effort="26" lower="-0.785398163397" upper="3.92699081699" velocity="2.35"/>
  </joint>
  <!--************************-->
  <!--        ELBOW           -->
  <!--************************-->
  <link name="arm_right_4_link">
    <inertial>
      <origin rpy="0.00000 0.00000 0.00000" xyz="-0.095658 0.014666 0.018133"/>
      <mass value="1.432697"/>
      <inertia ixx="0.002040" ixy="0.000725" ixz="-0.00115" iyy="0.008424" iyz="-0.000204" izz="0.008686"/>
    </inertial>
    <visual>
      <origin rpy="0 0 0" xyz="0 0 0"/>
      <geometry>
        <mesh filename="package://tiago_description/meshes/arm/arm_4.stl" scale="1 1 1"/>
      </geometry>
      <material name="DarkGrey"/>
    </visual>
    <collision>
      <origin rpy="0 0 0" xyz="0 0 0"/>
      <geometry>
        <mesh filename="package://tiago_description/meshes/arm/arm_4_collision.dae" scale="1 1 1"/>
      </geometry>
    </collision>
  </link>
  <joint name="arm_right_4_rjoint" type="revolute">
    <parent link="arm_right_3_link"/>
    <child link="arm_right_4_link"/>
    <origin rpy="-1.57079632679 0.78 0.0" xyz="-0.02 -0.027 -0.222"/>
    <axis xyz="0 0 1"/>
    <limit effort="26" lower="-1.57079632679" upper="0" velocity="2.35"/>
  </joint>
  <!--************************-->
  <!--        WRIST           -->
  <!--************************-->
  <!--************************-->
  <!--        WRIST           -->
  <!--************************-->
  <link name="arm_right_5_link">
    <inertial>
      <origin rpy="0.00000 0.00000 0.00000" xyz="0.001078 -0.000151 -0.077173"/>
      <mass value="1.655819"/>
      <inertia ixx="0.00613800000" ixy="-0.00000400000" ixz="0.00015600000" iyy="0.00564000000" iyz="0.00002200000" izz="0.00179700000"/>
    </inertial>
    <visual>
      <origin rpy="0 0 0" xyz="0 0 0"/>
      <geometry>
        <mesh filename="package://tiago_description/meshes/arm/arm_5-wrist-2017.stl" scale="1 1 1"/>
      </geometry>
      <material name="LightGrey"/>
    </visual>
    <collision>
      <origin rpy="0 0 0" xyz="0 0 0"/>
      <geometry>
        <mesh filename="package://tiago_description/meshes/arm/arm_5_collision-wrist-2017.dae" scale="1 1 1"/>
      </geometry>
    </collision>
  </link>
  <joint name="arm_right_5_rjoint" type="revolute">
    <parent link="arm_right_4_link"/>
    <child link="arm_right_5_link"/>
    <origin rpy="1.57079632679 -1.57079632679 -1.57079632679" xyz="-0.162 0.02 0.027"/>
    <axis xyz="0 0 1"/>
    <limit effort="3" lower="-2.09439510239" upper="2.09439510239" velocity="1.95"/>
  </joint>
  <link name="arm_right_6_link">
    <inertial>
      <origin rpy="0.00000 0.00000 0.00000" xyz="-0.000153 -0.003122 0.000183"/>
      <mass value="0.370063"/>
      <inertia ixx="0.00021500000" ixy="0.00000000000" ixz="0.00000000000" iyy="0.00017000000" iyz="0.00000200000" izz="0.00017400000"/>
    </inertial>
    <visual>
      <origin rpy="0 0 0" xyz="0 0 0"/>
      <geometry>
        <mesh filename="package://tiago_description/meshes/arm/arm_6-wrist-2017.stl" scale="1 1 1"/>
      </geometry>
      <material name="LightGrey"/>
    </visual>
    <collision>
      <origin rpy="0 0 0" xyz="0 0 0"/>
      <geometry>
        <mesh filename="package://tiago_description/meshes/arm/arm_6_collision-wrist-2017.dae" scale="1 1 1"/>
      </geometry>
    </collision>
  </link>
  <joint name="arm_right_6_rjoint" type="revolute">
    <parent link="arm_right_5_link"/>
    <child link="arm_right_6_link"/>
    <origin rpy="0.0 -1.57079632679 -1.57079632679" xyz="0 0 0.15"/>
    <axis xyz="0 0 1"/>
    <limit effort="6.6" lower="-1.41371669412" upper="1.41371669412" velocity="1.76"/>
  </joint>
  <link name="arm_right_7_link">
    <inertial>
      <origin rpy="0.00000 0.00000 0.00000" xyz="0.000010 -0.000003 -0.007774"/>
      <mass value="0.234252"/>
      <inertia ixx="0.00014200000" ixy="0.00000000000" ixz="0.00000000000" iyy="0.00011300000" iyz="0.00000000000" izz="0.00005200000"/>
    </inertial>
  </link>
  <joint name="arm_right_7_rjoint" type="revolute">
    <parent link="arm_right_6_link"/>
    <child link="arm_right_7_link"/>
    <origin rpy="1.57079632679 0.0 1.57079632679" xyz="0 0 0"/>
    <axis xyz="0 0 1"/>
    <limit effort="6.6" lower="-2.09439510239" upper="2.09439510239" velocity="1.76"/>
  </joint>
  <!--***********************-->
  <!--        TOOL           -->
  <!--***********************-->
  <link name="arm_right_tool_link">
    <inertial>
      <mass value="0.1"/>
      <inertia ixx="0.0" ixy="0.0" ixz="0.0" iyy="0.0" iyz="0.0" izz="0.0"/>
    </inertial>
    <visual>
      <origin rpy="0 1.57079632679 0" xyz="0.001 0 0"/>
      <geometry>
        <cylinder length="0.005" radius="0.005"/>
      </geometry>
      <material name="LightGrey"/>
    </visual>
    <collision>
      <origin rpy="0 1.57079632679 0" xyz="0.001 0 0"/>
      <geometry>
        <cylinder length="0.005" radius="0.005"/>
      </geometry>
    </collision>
  </link>
  <joint name="arm_right_tool_joint" type="fixed">
    <parent link="arm_right_7_link"/>
    <child link="arm_right_tool_link"/>
    <origin rpy="1.57079632679 -1.57079632679 3.14159265359" xyz="0 0 0.046"/>
  </joint>
  <!--************************-->
  <!--        ft sensor       -->
  <!--************************-->
  <link name="wrist_right_ft_link">
    <inertial>
      <mass value="0.1"/>
      <inertia ixx="0.0" ixy="0.0" ixz="0.0" iyy="0.0" iyz="0.0" izz="0.0"/>
    </inertial>
    <visual>
      <origin rpy="0 0 0" xyz="0 0 0"/>
      <geometry>
        <cylinder length="0.0157" radius="0.0225"/>
      </geometry>
      <material name="LightGrey"/>
    </visual>
    <collision>
      <origin rpy="0 0 0" xyz="0 0 0"/>
      <geometry>
        <cylinder length="0.0157" radius="0.0225"/>
      </geometry>
    </collision>
  </link>
  <joint name="wrist_right_ft_joint" type="fixed">
    <parent link="arm_right_tool_link"/>
    <child link="wrist_right_ft_link"/>
    <origin rpy="1.57079632679 0 1.57079632679" xyz="0.00785 0 0"/>
  </joint>
  <!--***********************-->
  <!--       FT TOOL         -->
  <!--***********************-->
  <link name="wrist_right_ft_tool_link">
    <inertial>
      <mass value="0.1"/>
      <inertia ixx="0.0" ixy="0.0" ixz="0.0" iyy="0.0" iyz="0.0" izz="0.0"/>
    </inertial>
    <visual>
      <origin rpy="0 1.57079632679 0" xyz="0.0 0 0"/>
      <geometry>
        <cylinder length="0.00975" radius="0.025"/>
      </geometry>
      <material name="FlatBlack"/>
    </visual>
    <collision>
      <origin rpy="0 1.57079632679 0" xyz="0.0 0 0"/>
      <geometry>
        <cylinder length="0.00975" radius="0.025"/>
      </geometry>
    </collision>
  </link>
  <joint name="wrist_right_tool_joint" type="fixed">
    <parent link="wrist_right_ft_link"/>
    <child link="wrist_right_ft_tool_link"/>
    <origin rpy="-1.57079632679 -1.57079632679 0" xyz="0 0 0.012725"/>
  </joint>
  <link name="gripper">
    <inertial>
      <origin rpy="0 0 0" xyz="0 0 0"/>
      <mass value="0.0001"/>
      <inertia ixx="0.00001" ixy="0.0" ixz="0.0" iyy="0.00001" iyz="0.0" izz="0.00001"/>
    </inertial>
  </link>
  <joint name="endeffector_gjoint" type="fixed">
    <parent link="gripper"/>
    <child link="endeffector"/>
    <origin rpy="0 0 0" xyz="0.0 0.0 -0.23"/>
  </joint>
  <link name="endeffector">
    <visual>
      <origin rpy="0 0 0" xyz="-0.0 0.0 0.0"/>
      <geometry>
        <sphere radius="0.01"/>
      </geometry>
      <material name="LightGrey"/>
    </visual>
  </link>
  <joint name="gripper_right_tool_joint" type="fixed">
    <origin rpy="1.57079632679 1.57079632679 -1.57079632679" xyz="0.01 0 0"/>
    <parent link="wrist_right_ft_tool_link"/>
    <child link="gripper"/>
    <axis xyz="0 0 0"/>
  </joint>
  <link name="gripper_right_link">
    <inertial>
      <origin rpy="0.0 0.0 0.0" xyz="-0.000294 0.000291 -0.033086"/>
      <mass value="0.602660"/>
      <inertia ixx="0.000693" ixy="0.000045" ixz="-0.000000" iyy="0.001024" iyz="0.000000" izz="0.000672"/>
    </inertial>
    <visual>
      <origin rpy="0 0 0" xyz="0 0 0"/>
      <geometry>
        <mesh filename="package://pal_gripper_description/meshes/gripper_link.stl"/>
      </geometry>
      <material name="White"/>
    </visual>
    <collision>
      <origin rpy="0 0 0" xyz="0 0 0"/>
      <geometry>
        <mesh filename="package://pal_gripper_description/meshes/gripper_link_collision.stl"/>
      </geometry>
    </collision>
  </link>
  <joint name="gripper_right_joint" type="fixed">
    <origin rpy="1.57079632679 1.57079632679 -1.57079632679" xyz="0.01 0 0"/>
    <parent link="wrist_right_ft_tool_link"/>
    <child link="gripper_right_link"/>
    <axis xyz="0 0 0"/>
  </joint>
  <link name="gripper_right_right_finger_link">
    <inertial>
      <origin rpy="0 0 0" xyz="-0.004470 0.010766 -0.121013"/>
      <mass value="0.109980"/>
      <inertia ixx="0.000232" ixy="-0.000005" ixz="-0.000032" iyy="0.000224" iyz="0.000036" izz="0.000029"/>
    </inertial>
    <visual>
      <origin rpy="0 0 3.1415" xyz="0 0 0"/>
      <geometry>
        <mesh filename="package://pal_gripper_description/meshes/gripper_finger_link.stl" scale="-1 -1 1"/>
      </geometry>
      <material name="Black"/>
    </visual>
  </link>
  <joint name="gripper_right_right_finger_gjoint" type="prismatic">
    <origin rpy="0 0 0" xyz="0. 0 0"/>
    <parent link="gripper_right_link"/>
    <child link="gripper_right_right_finger_link"/>
    <axis xyz="1 0 0"/>
    <limit effort="16" lower="0.044" upper="0.045" velocity="10"/>
  </joint>
  <link name="gripper_right_left_finger_link">
    <inertial>
      <origin rpy="0 0 0" xyz="-0.004470 0.010766 -0.121013"/>
      <mass value="0.109980"/>
      <inertia ixx="0.000232" ixy="-0.000005" ixz="-0.000032" iyy="0.000224" iyz="0.000036" izz="0.000029"/>
    </inertial>
    <visual>
      <origin rpy="0 0 3.1415" xyz="0 0 0"/>
      <geometry>
        <mesh filename="package://pal_gripper_description/meshes/gripper_finger_link.stl"/>
      </geometry>
      <material name="Black"/>
    </visual>
  </link>
  <joint name="gripper_right_left_finger_gjoint" type="prismatic">
    <origin rpy="0 0 0" xyz="0. 0 0"/>
    <parent link="gripper_right_link"/>
    <child link="gripper_right_left_finger_link"/>
    <axis xyz="-1 0 0"/>
    <limit effort="16" lower="0.044" upper="0.045" velocity="10"/>
  </joint>
</robot>
